Workbook
Name Capex_Pct: Assumptions!$B$31
Name DaysYear: Assumptions!$B$34
Name Debt_Amort: Assumptions!$B$33
Name DIO_Days: Assumptions!$B$29
Name DnA_Pct: Assumptions!$B$25
Name DPO_Days: Assumptions!$B$30
Name DSO_Days: Assumptions!$B$28
Name IntRate: Assumptions!$B$26
Name Payout_Pct: Assumptions!$B$32
Name TaxRate: Assumptions!$B$27

Sheet Assumptions
A1: MfgCo — 3-Statement Model (BM-3S-001) — Assumptions & Drivers
A2: Synthetic benchmark deal. USD millions; 365-day year. Blue = hard-coded input; all other cells are formulas.
A4: Historicals (USD m)
B5: FY0 | C5: FY1 | D5: FY2
A6: Revenue | B6: 540 | C6: 570 | D6: 600
A7: EBITDA | B7: 70.2 | C7: 76.95 | D7: 84
A9: Opening balance sheet (anchors t = 0)
A10: Cash | B10: 40
A11: Accounts receivable | B11: 90
A12: Inventory | B12: 75
A13: Net PP&E | B13: 250
A14: Accounts payable | B14: 55
A15: Debt | B15: 180
A16: Equity | B16: 220
A17: Check: opening assets - opening L&E | B17: =(B10+B11+B12+B13)-(B14+B15+B16) -> 0
A19: Projection drivers (t = 3..7)
B20: FY3 | C20: FY4 | D20: FY5 | E20: FY6 | F20: FY7
A21: Revenue growth | B21: 0.05 | C21: 0.045 | D21: 0.04 | E21: 0.035 | F21: 0.03
A22: EBITDA margin | B22: 0.14 | C22: 0.145 | D22: 0.15 | E22: 0.15 | F22: 0.15
A24: Constant drivers (apply to all columns t = 0..7)
A25: D&A (% of revenue) | B25: 0.055
A26: Interest rate on debt (on opening balance) | B26: 0.06
A27: Tax rate (on positive EBT only) | B27: 0.25
A28: Receivable days (DSO) | B28: 55
A29: Inventory days (on revenue — stated simplification) | B29: 60
A30: Payable days (on revenue — stated simplification) | B30: 40
A31: Capex (% of revenue) | B31: 0.06
A32: Dividend payout (% of positive net income) | B32: 0.3
A33: Debt amortization ($m per year, floored at 0) | B33: 20
A34: Days in year | B34: 365

Sheet Model
A1: MfgCo — Integrated 3-Statement Model (BM-3S-001)
A2: USD millions; 365-day year. Balance sheet anchored at t=0; working capital & PP&E driver-linked from t=1. CFS from t=1.
A4: USD millions | B4: FY0 | C4: FY1 | D4: FY2 | E4: FY3 | F4: FY4 | G4: FY5 | H4: FY6 | I4: FY7
B5: Hist. | C5: Hist. | D5: Hist. | E5: Proj. | F5: Proj. | G5: Proj. | H5: Proj. | I5: Proj.
A7: INCOME STATEMENT
A8: Revenue | B8: =Assumptions!B6 -> 540 | C8: =Assumptions!C6 -> 570 | D8: =Assumptions!D6 -> 600 | E8: =D8*(1+Assumptions!B21) -> 630 | F8: =E8*(1+Assumptions!C21) -> 658.35 | G8: =F8*(1+Assumptions!D21) -> 684.684 | H8: =G8*(1+Assumptions!E21) -> 708.64794 | I8: =H8*(1+Assumptions!F21) -> 729.90738
A9: Revenue growth (%) | B9: n.a. | C9: =C8/B8-1 -> 0.055555556 | D9: =D8/C8-1 -> 0.052631579 | E9: =E8/D8-1 -> 0.05 | F9: =F8/E8-1 -> 0.045 | G9: =G8/F8-1 -> 0.04 | H9: =H8/G8-1 -> 0.035 | I9: =I8/H8-1 -> 0.03
A10: EBITDA | B10: =Assumptions!B7 -> 70.2 | C10: =Assumptions!C7 -> 76.95 | D10: =Assumptions!D7 -> 84 | E10: =E8*Assumptions!B22 -> 88.2 | F10: =F8*Assumptions!C22 -> 95.46075 | G10: =G8*Assumptions!D22 -> 102.7026 | H10: =H8*Assumptions!E22 -> 106.29719 | I10: =I8*Assumptions!F22 -> 109.48611
A11: EBITDA margin (%) | B11: =B10/B8 -> 0.13 | C11: =C10/C8 -> 0.135 | D11: =D10/D8 -> 0.14 | E11: =E10/E8 -> 0.14 | F11: =F10/F8 -> 0.145 | G11: =G10/G8 -> 0.15 | H11: =H10/H8 -> 0.15 | I11: =I10/I8 -> 0.15
A12: Less: D&A (5.5% of revenue) | B12: =B8*DnA_Pct -> 29.7 | C12: =C8*DnA_Pct -> 31.35 | D12: =D8*DnA_Pct -> 33 | E12: =E8*DnA_Pct -> 34.65 | F12: =F8*DnA_Pct -> 36.20925 | G12: =G8*DnA_Pct -> 37.65762 | H12: =H8*DnA_Pct -> 38.975637 | I12: =I8*DnA_Pct -> 40.144906
A13: EBIT | B13: =B10-B12 -> 40.5 | C13: =C10-C12 -> 45.6 | D13: =D10-D12 -> 51 | E13: =E10-E12 -> 53.55 | F13: =F10-F12 -> 59.2515 | G13: =G10-G12 -> 65.04498 | H13: =H10-H12 -> 67.321554 | I13: =I10-I12 -> 69.341201
A14: Less: Interest expense (6.0% on opening debt) | B14: =IntRate*B52 -> 10.8 | C14: =IntRate*B52 -> 10.8 | D14: =IntRate*C52 -> 9.6 | E14: =IntRate*D52 -> 8.4 | F14: =IntRate*E52 -> 7.2 | G14: =IntRate*F52 -> 6 | H14: =IntRate*G52 -> 4.8 | I14: =IntRate*H52 -> 3.6
A15: EBT | B15: =B13-B14 -> 29.7 | C15: =C13-C14 -> 34.8 | D15: =D13-D14 -> 41.4 | E15: =E13-E14 -> 45.15 | F15: =F13-F14 -> 52.0515 | G15: =G13-G14 -> 59.04498 | H15: =H13-H14 -> 62.521554 | I15: =I13-I14 -> 65.741201
A16: Less: Taxes (25% of positive EBT) | B16: =MAX(B15,0)*TaxRate -> 7.425 | C16: =MAX(C15,0)*TaxRate -> 8.7 | D16: =MAX(D15,0)*TaxRate -> 10.35 | E16: =MAX(E15,0)*TaxRate -> 11.2875 | F16: =MAX(F15,0)*TaxRate -> 13.012875 | G16: =MAX(G15,0)*TaxRate -> 14.761245 | H16: =MAX(H15,0)*TaxRate -> 15.630389 | I16: =MAX(I15,0)*TaxRate -> 16.4353
A17: Net income | B17: =B15-B16 -> 22.275 | C17: =C15-C16 -> 26.1 | D17: =D15-D16 -> 31.05 | E17: =E15-E16 -> 33.8625 | F17: =F15-F16 -> 39.038625 | G17: =G15-G16 -> 44.283735 | H17: =H15-H16 -> 46.891166 | I17: =I15-I16 -> 49.305901
A19: BALANCE SHEET
A20: Cash | B20: =Assumptions!B10 -> 40 | C20: =C46 -> 28.296712 | D20: =D46 -> 20.867329 | E20: =E46 -> 15.256695 | F20: =F46 -> 13.46664 | G20: =G46 -> 15.630739 | H20: =H46 -> 19.987218 | I20: =I46 -> 26.483434
A21: Accounts receivable (DSO 55) | B21: =Assumptions!B11 -> 90 | C21: =C8*DSO_Days/DaysYear -> 85.890411 | D21: =D8*DSO_Days/DaysYear -> 90.410959 | E21: =E8*DSO_Days/DaysYear -> 94.931507 | F21: =F8*DSO_Days/DaysYear -> 99.203425 | G21: =G8*DSO_Days/DaysYear -> 103.17156 | H21: =H8*DSO_Days/DaysYear -> 106.78257 | I21: =I8*DSO_Days/DaysYear -> 109.98604
A22: Inventory (60 days on revenue) | B22: =Assumptions!B12 -> 75 | C22: =C8*DIO_Days/DaysYear -> 93.69863 | D22: =D8*DIO_Days/DaysYear -> 98.630137 | E22: =E8*DIO_Days/DaysYear -> 103.56164 | F22: =F8*DIO_Days/DaysYear -> 108.22192 | G22: =G8*DIO_Days/DaysYear -> 112.55079 | H22: =H8*DIO_Days/DaysYear -> 116.49007 | I22: =I8*DIO_Days/DaysYear -> 119.98477
A23: Net PP&E | B23: =B57 -> 250 | C23: =C57 -> 252.85 | D23: =D57 -> 255.85 | E23: =E57 -> 259 | F23: =F57 -> 262.29175 | G23: =G57 -> 265.71517 | H23: =H57 -> 269.25841 | I23: =I57 -> 272.90795
A24: Total assets | B24: =SUM(B20:B23) -> 455 | C24: =SUM(C20:C23) -> 460.73575 | D24: =SUM(D20:D23) -> 465.75842 | E24: =SUM(E20:E23) -> 472.74985 | F24: =SUM(F20:F23) -> 483.18373 | G24: =SUM(G20:G23) -> 497.06827 | H24: =SUM(H20:H23) -> 512.51827 | I24: =SUM(I20:I23) -> 529.3622
A25: Accounts payable (40 days on revenue) | B25: =Assumptions!B14 -> 55 | C25: =C8*DPO_Days/DaysYear -> 62.465753 | D25: =D8*DPO_Days/DaysYear -> 65.753425 | E25: =E8*DPO_Days/DaysYear -> 69.041096 | F25: =F8*DPO_Days/DaysYear -> 72.147945 | G25: =G8*DPO_Days/DaysYear -> 75.033863 | H25: =H8*DPO_Days/DaysYear -> 77.660048 | I25: =I8*DPO_Days/DaysYear -> 79.98985
A26: Debt | B26: =B52 -> 180 | C26: =C52 -> 160 | D26: =D52 -> 140 | E26: =E52 -> 120 | F26: =F52 -> 100 | G26: =G52 -> 80 | H26: =H52 -> 60 | I26: =I52 -> 40
A27: Total liabilities | B27: =B25+B26 -> 235 | C27: =C25+C26 -> 222.46575 | D27: =D25+D26 -> 205.75342 | E27: =E25+E26 -> 189.0411 | F27: =F25+F26 -> 172.14795 | G27: =G25+G26 -> 155.03386 | H27: =H25+H26 -> 137.66005 | I27: =I25+I26 -> 119.98985
A28: Equity | B28: =B62 -> 220 | C28: =C62 -> 238.27 | D28: =D62 -> 260.005 | E28: =E62 -> 283.70875 | F28: =F62 -> 311.03579 | G28: =G62 -> 342.0344 | H28: =H62 -> 374.85822 | I28: =I62 -> 409.37235
A29: Total liabilities & equity | B29: =B27+B28 -> 455 | C29: =C27+C28 -> 460.73575 | D29: =D27+D28 -> 465.75842 | E29: =E27+E28 -> 472.74985 | F29: =F27+F28 -> 483.18373 | G29: =G27+G28 -> 497.06827 | H29: =H27+H28 -> 512.51827 | I29: =I27+I28 -> 529.3622
A30: Balance check: assets - (liabilities + equity) | B30: =B24-B29 -> 0 | C30: =C24-C29 -> 0 | D30: =D24-D29 -> 0 | E30: =E24-E29 -> 0 | F30: =F24-F29 -> 0 | G30: =G24-G29 -> 0 | H30: =H24-H29 -> 0 | I30: =I24-I29 -> 0
A32: CASH FLOW STATEMENT (indirect; from t = 1)
A33: Net income | C33: =C17 -> 26.1 | D33: =D17 -> 31.05 | E33: =E17 -> 33.8625 | F33: =F17 -> 39.038625 | G33: =G17 -> 44.283735 | H33: =H17 -> 46.891166 | I33: =I17 -> 49.305901
A34: Plus: D&A | C34: =C12 -> 31.35 | D34: =D12 -> 33 | E34: =E12 -> 34.65 | F34: =F12 -> 36.20925 | G34: =G12 -> 37.65762 | H34: =H12 -> 38.975637 | I34: =I12 -> 40.144906
A35: (Increase) / decrease in accounts receivable | C35: =-(C21-B21) -> 4.109589 | D35: =-(D21-C21) -> -4.5205479 | E35: =-(E21-D21) -> -4.5205479 | F35: =-(F21-E21) -> -4.2719178 | G35: =-(G21-F21) -> -3.968137 | H35: =-(H21-G21) -> -3.6110047 | I35: =-(I21-H21) -> -3.203477
A36: (Increase) / decrease in inventory | C36: =-(C22-B22) -> -18.69863 | D36: =-(D22-C22) -> -4.9315068 | E36: =-(E22-D22) -> -4.9315068 | F36: =-(F22-E22) -> -4.660274 | G36: =-(G22-F22) -> -4.3288767 | H36: =-(H22-G22) -> -3.9392778 | I36: =-(I22-H22) -> -3.4947022
A37: Increase / (decrease) in accounts payable | C37: =C25-B25 -> 7.4657534 | D37: =D25-C25 -> 3.2876712 | E37: =E25-D25 -> 3.2876712 | F37: =F25-E25 -> 3.1068493 | G37: =G25-F25 -> 2.8859178 | H37: =H25-G25 -> 2.6261852 | I37: =I25-H25 -> 2.3298014
A38: Cash flow from operations | C38: =SUM(C33:C37) -> 50.326712 | D38: =SUM(D33:D37) -> 57.885616 | E38: =SUM(E33:E37) -> 62.348116 | F38: =SUM(F33:F37) -> 69.422533 | G38: =SUM(G33:G37) -> 76.530259 | H38: =SUM(H33:H37) -> 80.942705 | I38: =SUM(I33:I37) -> 85.082429
A39: Less: Capex | C39: =-C55 -> -34.2 | D39: =-D55 -> -36 | E39: =-E55 -> -37.8 | F39: =-F55 -> -39.501 | G39: =-G55 -> -41.08104 | H39: =-H55 -> -42.518876 | I39: =-I55 -> -43.794443
A40: Cash flow from investing | C40: =C39 -> -34.2 | D40: =D39 -> -36 | E40: =E39 -> -37.8 | F40: =F39 -> -39.501 | G40: =G39 -> -41.08104 | H40: =H39 -> -42.518876 | I40: =I39 -> -43.794443
A41: Less: Dividends paid | C41: =C61 -> -7.83 | D41: =D61 -> -9.315 | E41: =E61 -> -10.15875 | F41: =F61 -> -11.711587 | G41: =G61 -> -13.28512 | H41: =H61 -> -14.06735 | I41: =I61 -> -14.79177
A42: Less: Debt repayment | C42: =-C51 -> -20 | D42: =-D51 -> -20 | E42: =-E51 -> -20 | F42: =-F51 -> -20 | G42: =-G51 -> -20 | H42: =-H51 -> -20 | I42: =-I51 -> -20
A43: Cash flow from financing | C43: =C41+C42 -> -27.83 | D43: =D41+D42 -> -29.315 | E43: =E41+E42 -> -30.15875 | F43: =F41+F42 -> -31.711587 | G43: =G41+G42 -> -33.28512 | H43: =H41+H42 -> -34.06735 | I43: =I41+I42 -> -34.79177
A44: Net change in cash | C44: =C38+C40+C43 -> -11.703288 | D44: =D38+D40+D43 -> -7.4293836 | E44: =E38+E40+E43 -> -5.6106336 | F44: =F38+F40+F43 -> -1.790055 | G44: =G38+G40+G43 -> 2.1640986 | H44: =H38+H40+H43 -> 4.356479 | I44: =I38+I40+I43 -> 6.4962159
...
