Workbook

Sheet Assumptions
A1: IndustrialCo - Enterprise DCF - Assumptions
A2: Synthetic benchmark deal BM-DCF-001 - USD millions unless stated - Blue = input | Black = calculation | Green = link
A4: Target & Capitalization
A5: Last FY revenue (FY0) | B5: 1000
A6: Last FY EBITDA (FY0) | B6: 180
A7: Net debt | B7: 250
A8: Shares outstanding (m) | B8: 150
A9: Reference share price ($/sh) | B9: 8
A11: Operating Drivers (every projection year)
A12: D&A (% of revenue) | B12: 0.06
A13: Capex (% of revenue) | B13: 0.065
A14: Change in NWC (% of change in revenue) | B14: 0.1
A15: Cash tax rate (on EBIT) | B15: 0.25
A17: Forecast Path (5 explicit years, revenue fade) | C17: Year 1 | D17: Year 2 | E17: Year 3 | F17: Year 4 | G17: Year 5
A18: Revenue growth | C18: 0.04 | D18: 0.035 | E18: 0.03 | F18: 0.025 | G18: 0.02
A19: EBITDA margin | C19: 0.18 | D19: 0.18 | E19: 0.18 | F19: 0.18 | G19: 0.18
A21: WACC Inputs (plain CAPM - no extra premia)
A22: Risk-free rate (10Y UST) | B22: 0.0425
A23: Equity risk premium | B23: 0.05
A24: Beta (levered) | B24: 1.1
A25: Pre-tax cost of debt | B25: 0.0575
A26: Tax rate (for WACC) | B26: 0.25
A27: Target D/(D+E) | B27: 0.3
A29: Terminal Value
A30: Terminal growth g (Gordon) | B30: 0.02
A31: Note: capex = D&A in perpetuity; terminal NWC normalized at g

Sheet DCF
A1: IndustrialCo - Enterprise DCF (end-of-year discounting, Gordon terminal)
A2: Synthetic benchmark deal BM-DCF-001 - USD millions unless stated - Blue = input | Black = calculation | Green = link
A3: (USD m unless stated) | B3: FY0 | C3: Year 1 | D3: Year 2 | E3: Year 3 | F3: Year 4 | G3: Year 5
A5: 1. WACC Build (CAPM)
A6: Risk-free rate (10Y UST) | B6: =Assumptions!B22
A7: Equity risk premium | B7: =Assumptions!B23
A8: Beta (levered) | B8: =Assumptions!B24
A9: Cost of equity (Ke = rf + beta x ERP) | B9: =B6+B8*B7
A10: Pre-tax cost of debt | B10: =Assumptions!B25
A11: Tax rate | B11: =Assumptions!B26
A12: After-tax cost of debt (Kd x (1-t)) | B12: =B10*(1-B11)
A13: Target D/(D+E) | B13: =Assumptions!B27
A14: Target E/(D+E) | B14: =1-B13
A15: WACC = E% x Ke + D% x after-tax Kd | B15: =B14*B9+B13*B12
A17: 2. FCFF Forecast (revenue -> EBITDA -> EBIT -> NOPAT -> FCFF)
A18: Revenue growth | C18: =Assumptions!C18 | D18: =Assumptions!D18 | E18: =Assumptions!E18 | F18: =Assumptions!F18 | G18: =Assumptions!G18
A19: Revenue | B19: =Assumptions!B5 | C19: =B19*(1+C18) | D19: =C19*(1+D18) | E19: =D19*(1+E18) | F19: =E19*(1+F18) | G19: =F19*(1+G18)
A20: EBITDA margin | B20: =Assumptions!B6/Assumptions!B5 | C20: =Assumptions!C19 | D20: =Assumptions!D19 | E20: =Assumptions!E19 | F20: =Assumptions!F19 | G20: =Assumptions!G19
A21: EBITDA | B21: =Assumptions!B6 | C21: =C19*C20 | D21: =D19*D20 | E21: =E19*E20 | F21: =F19*F20 | G21: =G19*G20
A22: Less: D&A (6.0% of revenue) | C22: =-C19*Assumptions!$B$12 | D22: =-D19*Assumptions!$B$12 | E22: =-E19*Assumptions!$B$12 | F22: =-F19*Assumptions!$B$12 | G22: =-G19*Assumptions!$B$12
A23: EBIT | C23: =C21+C22 | D23: =D21+D22 | E23: =E21+E22 | F23: =F21+F22 | G23: =G21+G22
A24: Less: cash taxes (25% of EBIT) | C24: =-C23*Assumptions!$B$15 | D24: =-D23*Assumptions!$B$15 | E24: =-E23*Assumptions!$B$15 | F24: =-F23*Assumptions!$B$15 | G24: =-G23*Assumptions!$B$15
A25: NOPAT | C25: =C23+C24 | D25: =D23+D24 | E25: =E23+E24 | F25: =F23+F24 | G25: =G23+G24
A26: Plus: D&A | C26: =-C22 | D26: =-D22 | E26: =-E22 | F26: =-F22 | G26: =-G22
A27: Less: capex (6.5% of revenue) | C27: =-C19*Assumptions!$B$13 | D27: =-D19*Assumptions!$B$13 | E27: =-E19*Assumptions!$B$13 | F27: =-F19*Assumptions!$B$13 | G27: =-G19*Assumptions!$B$13
A28: Less: change in NWC (10% of change in revenue) | C28: =-(C19-B19)*Assumptions!$B$14 | D28: =-(D19-C19)*Assumptions!$B$14 | E28: =-(E19-D19)*Assumptions!$B$14 | F28: =-(F19-E19)*Assumptions!$B$14 | G28: =-(G19-F19)*Assumptions!$B$14
A29: FCFF (unlevered free cash flow) | C29: =SUM(C25:C28) | D29: =SUM(D25:D28) | E29: =SUM(E25:E28) | F29: =SUM(F25:F28) | G29: =SUM(G25:G28)
A31: Discount period (end-of-year) | C31: 1 | D31: =C31+1 | E31: =D31+1 | F31: =E31+1 | G31: =F31+1
A32: Discount factor @ WACC | C32: =1/(1+$B$15)^C31 | D32: =1/(1+$B$15)^D31 | E32: =1/(1+$B$15)^E31 | F32: =1/(1+$B$15)^F31 | G32: =1/(1+$B$15)^G31
A33: PV of FCFF | C33: =C29*C32 | D33: =D29*D32 | E33: =E29*E32 | F33: =F29*F32 | G33: =G29*G32
A35: 3. Terminal Value (Gordon growth on normalized FCF; capex = D&A in perpetuity)
A36: Terminal growth (g) | B36: =Assumptions!B30
A37: Year-5 NOPAT | B37: =G25
A38: Less: terminal change in NWC (Yr-5 dNWC x (1+g)) | B38: =-(G19-F19)*Assumptions!$B$14*(1+B36)
A39: Normalized terminal FCF | B39: =B37+B38
A40: Terminal value at end of Year 5 = norm FCF x (1+g)/(WACC-g) | B40: =B39*(1+B36)/($B$15-B36)
A41: PV of terminal value = TV/(1+WACC)^5 | B41: =B40/(1+$B$15)^G31
A43: 4. Enterprise & Equity Value
A44: PV of explicit FCFF (Years 1-5) | B44: =SUM(C33:G33)
A45: PV of terminal value | B45: =B41
...

Sheet Sensitivity
A1: IndustrialCo - DCF Sensitivities (live formulas, full model re-derived per cell)
A2: Synthetic benchmark deal BM-DCF-001 - USD millions unless stated - Blue = input | Black = calculation | Green = link
A3: Enterprise value ($m) - WACC vs terminal growth g
B4: WACC \ g | C4: =D4-0.005 | D4: =E4-0.005 | E4: =DCF!B36 | F4: =E4+0.005 | G4: =F4+0.005
B5: =B6-0.005 | C5: =DCF!$C$29/(1+$B5)^1+DCF!$D$29/(1+$B5)^2+DCF!$E$29/(1+$B5)^3+DCF!$F$29/(1+$B5)^4+DCF!$G$29/(1+$B5)^5+(DCF!$G$25-(DCF!$G$19-DCF!$F$19)*Assumptions!$B$14*(1+C$4))*(1+C$4)/($B5-C$4)/(1+$B5)^5 | D5: =DCF!$C$29/(1+$B5)^1+DCF!$D$29/(1+$B5)^2+DCF!$E$29/(1+$B5)^3+DCF!$F$29/(1+$B5)^4+DCF!$G$29/(1+$B5)^5+(DCF!$G$25-(DCF!$G$19-DCF!$F$19)*Assumptions!$B$14*(1+D$4))*(1+D$4)/($B5-D$4)/(1+$B5)^5 | E5: =DCF!$C$29/(1+$B5)^1+DCF!$D$29/(1+$B5)^2+DCF!$E$29/(1+$B5)^3+DCF!$F$29/(1+$B5)^4+DCF!$G$29/(1+$B5)^5+(DCF!$G$25-(DCF!$G$19-DCF!$F$19)*Assumptions!$B$14*(1+E$4))*(1+E$4)/($B5-E$4)/(1+$B5)^5 | F5: =DCF!$C$29/(1+$B5)^1+DCF!$D$29/(1+$B5)^2+DCF!$E$29/(1+$B5)^3+DCF!$F$29/(1+$B5)^4+DCF!$G$29/(1+$B5)^5+(DCF!$G$25-(DCF!$G$19-DCF!$F$19)*Assumptions!$B$14*(1+F$4))*(1+F$4)/($B5-F$4)/(1+$B5)^5 | G5: =DCF!$C$29/(1+$B5)^1+DCF!$D$29/(1+$B5)^2+DCF!$E$29/(1+$B5)^3+DCF!$F$29/(1+$B5)^4+DCF!$G$29/(1+$B5)^5+(DCF!$G$25-(DCF!$G$19-DCF!$F$19)*Assumptions!$B$14*(1+G$4))*(1+G$4)/($B5-G$4)/(1+$B5)^5
B6: =B7-0.005 | C6: =DCF!$C$29/(1+$B6)^1+DCF!$D$29/(1+$B6)^2+DCF!$E$29/(1+$B6)^3+DCF!$F$29/(1+$B6)^4+DCF!$G$29/(1+$B6)^5+(DCF!$G$25-(DCF!$G$19-DCF!$F$19)*Assumptions!$B$14*(1+C$4))*(1+C$4)/($B6-C$4)/(1+$B6)^5 | D6: =DCF!$C$29/(1+$B6)^1+DCF!$D$29/(1+$B6)^2+DCF!$E$29/(1+$B6)^3+DCF!$F$29/(1+$B6)^4+DCF!$G$29/(1+$B6)^5+(DCF!$G$25-(DCF!$G$19-DCF!$F$19)*Assumptions!$B$14*(1+D$4))*(1+D$4)/($B6-D$4)/(1+$B6)^5 | E6: =DCF!$C$29/(1+$B6)^1+DCF!$D$29/(1+$B6)^2+DCF!$E$29/(1+$B6)^3+DCF!$F$29/(1+$B6)^4+DCF!$G$29/(1+$B6)^5+(DCF!$G$25-(DCF!$G$19-DCF!$F$19)*Assumptions!$B$14*(1+E$4))*(1+E$4)/($B6-E$4)/(1+$B6)^5 | F6: =DCF!$C$29/(1+$B6)^1+DCF!$D$29/(1+$B6)^2+DCF!$E$29/(1+$B6)^3+DCF!$F$29/(1+$B6)^4+DCF!$G$29/(1+$B6)^5+(DCF!$G$25-(DCF!$G$19-DCF!$F$19)*Assumptions!$B$14*(1+F$4))*(1+F$4)/($B6-F$4)/(1+$B6)^5 | G6: =DCF!$C$29/(1+$B6)^1+DCF!$D$29/(1+$B6)^2+DCF!$E$29/(1+$B6)^3+DCF!$F$29/(1+$B6)^4+DCF!$G$29/(1+$B6)^5+(DCF!$G$25-(DCF!$G$19-DCF!$F$19)*Assumptions!$B$14*(1+G$4))*(1+G$4)/($B6-G$4)/(1+$B6)^5
B7: =DCF!B15 | C7: =DCF!$C$29/(1+$B7)^1+DCF!$D$29/(1+$B7)^2+DCF!$E$29/(1+$B7)^3+DCF!$F$29/(1+$B7)^4+DCF!$G$29/(1+$B7)^5+(DCF!$G$25-(DCF!$G$19-DCF!$F$19)*Assumptions!$B$14*(1+C$4))*(1+C$4)/($B7-C$4)/(1+$B7)^5 | D7: =DCF!$C$29/(1+$B7)^1+DCF!$D$29/(1+$B7)^2+DCF!$E$29/(1+$B7)^3+DCF!$F$29/(1+$B7)^4+DCF!$G$29/(1+$B7)^5+(DCF!$G$25-(DCF!$G$19-DCF!$F$19)*Assumptions!$B$14*(1+D$4))*(1+D$4)/($B7-D$4)/(1+$B7)^5 | E7: =DCF!$C$29/(1+$B7)^1+DCF!$D$29/(1+$B7)^2+DCF!$E$29/(1+$B7)^3+DCF!$F$29/(1+$B7)^4+DCF!$G$29/(1+$B7)^5+(DCF!$G$25-(DCF!$G$19-DCF!$F$19)*Assumptions!$B$14*(1+E$4))*(1+E$4)/($B7-E$4)/(1+$B7)^5 | F7: =DCF!$C$29/(1+$B7)^1+DCF!$D$29/(1+$B7)^2+DCF!$E$29/(1+$B7)^3+DCF!$F$29/(1+$B7)^4+DCF!$G$29/(1+$B7)^5+(DCF!$G$25-(DCF!$G$19-DCF!$F$19)*Assumptions!$B$14*(1+F$4))*(1+F$4)/($B7-F$4)/(1+$B7)^5 | G7: =DCF!$C$29/(1+$B7)^1+DCF!$D$29/(1+$B7)^2+DCF!$E$29/(1+$B7)^3+DCF!$F$29/(1+$B7)^4+DCF!$G$29/(1+$B7)^5+(DCF!$G$25-(DCF!$G$19-DCF!$F$19)*Assumptions!$B$14*(1+G$4))*(1+G$4)/($B7-G$4)/(1+$B7)^5
B8: =B7+0.005 | C8: =DCF!$C$29/(1+$B8)^1+DCF!$D$29/(1+$B8)^2+DCF!$E$29/(1+$B8)^3+DCF!$F$29/(1+$B8)^4+DCF!$G$29/(1+$B8)^5+(DCF!$G$25-(DCF!$G$19-DCF!$F$19)*Assumptions!$B$14*(1+C$4))*(1+C$4)/($B8-C$4)/(1+$B8)^5 | D8: =DCF!$C$29/(1+$B8)^1+DCF!$D$29/(1+$B8)^2+DCF!$E$29/(1+$B8)^3+DCF!$F$29/(1+$B8)^4+DCF!$G$29/(1+$B8)^5+(DCF!$G$25-(DCF!$G$19-DCF!$F$19)*Assumptions!$B$14*(1+D$4))*(1+D$4)/($B8-D$4)/(1+$B8)^5 | E8: =DCF!$C$29/(1+$B8)^1+DCF!$D$29/(1+$B8)^2+DCF!$E$29/(1+$B8)^3+DCF!$F$29/(1+$B8)^4+DCF!$G$29/(1+$B8)^5+(DCF!$G$25-(DCF!$G$19-DCF!$F$19)*Assumptions!$B$14*(1+E$4))*(1+E$4)/($B8-E$4)/(1+$B8)^5 | F8: =DCF!$C$29/(1+$B8)^1+DCF!$D$29/(1+$B8)^2+DCF!$E$29/(1+$B8)^3+DCF!$F$29/(1+$B8)^4+DCF!$G$29/(1+$B8)^5+(DCF!$G$25-(DCF!$G$19-DCF!$F$19)*Assumptions!$B$14*(1+F$4))*(1+F$4)/($B8-F$4)/(1+$B8)^5 | G8: =DCF!$C$29/(1+$B8)^1+DCF!$D$29/(1+$B8)^2+DCF!$E$29/(1+$B8)^3+DCF!$F$29/(1+$B8)^4+DCF!$G$29/(1+$B8)^5+(DCF!$G$25-(DCF!$G$19-DCF!$F$19)*Assumptions!$B$14*(1+G$4))*(1+G$4)/($B8-G$4)/(1+$B8)^5
B9: =B8+0.005 | C9: =DCF!$C$29/(1+$B9)^1+DCF!$D$29/(1+$B9)^2+DCF!$E$29/(1+$B9)^3+DCF!$F$29/(1+$B9)^4+DCF!$G$29/(1+$B9)^5+(DCF!$G$25-(DCF!$G$19-DCF!$F$19)*Assumptions!$B$14*(1+C$4))*(1+C$4)/($B9-C$4)/(1+$B9)^5 | D9: =DCF!$C$29/(1+$B9)^1+DCF!$D$29/(1+$B9)^2+DCF!$E$29/(1+$B9)^3+DCF!$F$29/(1+$B9)^4+DCF!$G$29/(1+$B9)^5+(DCF!$G$25-(DCF!$G$19-DCF!$F$19)*Assumptions!$B$14*(1+D$4))*(1+D$4)/($B9-D$4)/(1+$B9)^5 | E9: =DCF!$C$29/(1+$B9)^1+DCF!$D$29/(1+$B9)^2+DCF!$E$29/(1+$B9)^3+DCF!$F$29/(1+$B9)^4+DCF!$G$29/(1+$B9)^5+(DCF!$G$25-(DCF!$G$19-DCF!$F$19)*Assumptions!$B$14*(1+E$4))*(1+E$4)/($B9-E$4)/(1+$B9)^5 | F9: =DCF!$C$29/(1+$B9)^1+DCF!$D$29/(1+$B9)^2+DCF!$E$29/(1+$B9)^3+DCF!$F$29/(1+$B9)^4+DCF!$G$29/(1+$B9)^5+(DCF!$G$25-(DCF!$G$19-DCF!$F$19)*Assumptions!$B$14*(1+F$4))*(1+F$4)/($B9-F$4)/(1+$B9)^5 | G9: =DCF!$C$29/(1+$B9)^1+DCF!$D$29/(1+$B9)^2+DCF!$E$29/(1+$B9)^3+DCF!$F$29/(1+$B9)^4+DCF!$G$29/(1+$B9)^5+(DCF!$G$25-(DCF!$G$19-DCF!$F$19)*Assumptions!$B$14*(1+G$4))*(1+G$4)/($B9-G$4)/(1+$B9)^5
A12: Implied price per share ($) - WACC vs terminal growth g
B13: WACC \ g | C13: =C4 | D13: =D4 | E13: =E4 | F13: =F4 | G13: =G4
B14: =B5 | C14: =(C5-Assumptions!$B$7)/Assumptions!$B$8 | D14: =(D5-Assumptions!$B$7)/Assumptions!$B$8 | E14: =(E5-Assumptions!$B$7)/Assumptions!$B$8 | F14: =(F5-Assumptions!$B$7)/Assumptions!$B$8 | G14: =(G5-Assumptions!$B$7)/Assumptions!$B$8
B15: =B6 | C15: =(C6-Assumptions!$B$7)/Assumptions!$B$8 | D15: =(D6-Assumptions!$B$7)/Assumptions!$B$8 | E15: =(E6-Assumptions!$B$7)/Assumptions!$B$8 | F15: =(F6-Assumptions!$B$7)/Assumptions!$B$8 | G15: =(G6-Assumptions!$B$7)/Assumptions!$B$8
B16: =B7 | C16: =(C7-Assumptions!$B$7)/Assumptions!$B$8 | D16: =(D7-Assumptions!$B$7)/Assumptions!$B$8 | E16: =(E7-Assumptions!$B$7)/Assumptions!$B$8 | F16: =(F7-Assumptions!$B$7)/Assumptions!$B$8 | G16: =(G7-Assumptions!$B$7)/Assumptions!$B$8
B17: =B8 | C17: =(C8-Assumptions!$B$7)/Assumptions!$B$8 | D17: =(D8-Assumptions!$B$7)/Assumptions!$B$8 | E17: =(E8-Assumptions!$B$7)/Assumptions!$B$8 | F17: =(F8-Assumptions!$B$7)/Assumptions!$B$8 | G17: =(G8-Assumptions!$B$7)/Assumptions!$B$8
B18: =B9 | C18: =(C9-Assumptions!$B$7)/Assumptions!$B$8 | D18: =(D9-Assumptions!$B$7)/Assumptions!$B$8 | E18: =(E9-Assumptions!$B$7)/Assumptions!$B$8 | F18: =(F9-Assumptions!$B$7)/Assumptions!$B$8 | G18: =(G9-Assumptions!$B$7)/Assumptions!$B$8
A20: Center row/column are live links to the model WACC (8.119%) and g (2.0%); steps of +/- 50bp. Every cell is a full live re-derivation (no data table).
