Workbook
Name Rev_FY0: Assumptions!$B$7
Name Entry_EBITDA: Assumptions!$B$11
Name Net_Debt_Entry: Assumptions!$B$12
Name Share_Price: Assumptions!$B$15
Name Offer_Premium: Assumptions!$B$16
Name FD_Shares: Assumptions!$B$17
Name Option_Buyout: Assumptions!$B$18
Name Advisory_Fees: Assumptions!$B$21
Name Financing_Fees: Assumptions!$B$22
Name Min_Cash: Assumptions!$B$23
Name TL_Mult: Assumptions!$B$24
Name Mezz_Mult: Assumptions!$B$25
Name SOFR_Rate: Assumptions!$B$26
Name TL_Spread: Assumptions!$B$27
Name Mezz_Spread: Assumptions!$B$28
Name Sched_Amort: Assumptions!$B$31
Name Dist_PerYear: Assumptions!$B$33
Name Growth_Y1: Assumptions!$B$37
Name Growth_Y2: Assumptions!$C$37
Name Growth_Y3: Assumptions!$D$37
Name Growth_Y4: Assumptions!$E$37
Name Growth_Y5: Assumptions!$F$37
Name Margin_Y1: Assumptions!$B$38
Name Margin_Y2: Assumptions!$C$38
Name Margin_Y3: Assumptions!$D$38
Name Margin_Y4: Assumptions!$E$38
Name Margin_Y5: Assumptions!$F$38
Name DA_Pct: Assumptions!$B$39
Name MaintCapex_Pct: Assumptions!$B$40
Name GrowthCapex_Pct: Assumptions!$B$41
Name NWC_Pct: Assumptions!$B$42
Name Tax_Rate: Assumptions!$B$43
Name Hold_Years: Assumptions!$B$46
Name Exit_Multiple: Assumptions!$B$47
Name Sens_MultStep: Assumptions!$B$52
Name Sens_GrowthStep: Assumptions!$B$53
Name Total_Uses: 'Sources and Uses'!$B$17
Name TL_Amount: 'Sources and Uses'!$B$20
Name Mezz_Amount: 'Sources and Uses'!$B$21
Name Sponsor_Equity: 'Sources and Uses'!$B$22
Name EBITDA_Y5: 'Operating Model'!$I$8
Name Debt_AtExit: 'Debt Schedule'!$B$23
Name Exit_Equity: Returns!$B$9

Sheet Assumptions
A1: SaaSCo — SPONSOR LBO MODEL — ASSUMPTIONS & SOURCES (BM-LBO-001, arm B run 2)
A2: Synthetic benchmark. Every input below is sourced verbatim from benchmarks/briefs/lbo_us_saas.md. USD millions unless noted.
A3: Color code: blue = hardcoded input, black = calculation, green = cross-sheet link.
A4: 1. TARGET — HISTORICAL FINANCIALS
A5: Revenue — FY-2 | B5: 81 | C5: $m | D5: Brief §1
A6: Revenue — FY-1 | B6: 90 | C6: $m | D6: Brief §1
A7: Revenue — FY0 (last historical) | B7: 100 | C7: $m | D7: Brief §1
A8: EBITDA — FY-2 | B8: 26.7 | C8: $m | D8: Brief §1
A9: EBITDA — FY-1 | B9: 30.6 | C9: $m | D9: Brief §1
A10: EBITDA — FY0 | B10: 35 | C10: $m | D10: Brief §1
A11: Entry (LTM) EBITDA (= FY0 EBITDA) | B11: =B10 | C11: $m | D11: Brief §1
A12: Target net debt at close (refinanced) | B12: 20 | C12: $m | D12: Brief §1
A14: 2. PURCHASE PRICE
A15: Current share price | B15: 4.4 | C15: $ / share | D15: Brief §2
A16: Offer premium | B16: 0.25 | C16: % over current price | D16: Brief §2
A17: Fully diluted shares | B17: 60 | C17: m shares | D17: Brief §2
A18: Option / RSU buyout | B18: 0 | C18: $m | D18: Brief §2
A20: 3. FINANCING & TRANSACTION COSTS
A21: M&A advisory fees | B21: 7 | C21: $m, funded at close | D21: Brief §3
A22: Financing fees | B22: 5 | C22: $m, funded at close | D22: Brief §3
A23: Minimum cash funded to balance sheet | B23: 5 | C23: $m, funded at close | D23: Brief §3
A24: Senior Term Loan sizing | B24: 4.5 | C24: x entry LTM EBITDA | D24: Brief §3
A25: Mezzanine Notes sizing | B25: 1 | C25: x entry LTM EBITDA | D25: Brief §3
A26: SOFR (base rate) | B26: 0.04 | C26: flat, no floor | D26: Brief §3
A27: Senior Term Loan spread | B27: 0.035 | C27: +350 bps | D27: Brief §3
A28: Mezzanine Notes spread | B28: 0.07 | C28: +700 bps | D28: Brief §3
A29: Senior Term Loan tenor | B29: 7 | C29: years; bullet, no OID, no floor | D29: Brief §3
A30: Mezzanine Notes tenor | B30: 8 | C30: years; bullet, no OID, no floor | D30: Brief §3
A31: Scheduled amortization — both tranches (bullet) | B31: 0 | C31: $m / year | D31: Brief §3
A32: Cash sweep | B32: 0 | C32: % of FCF — none per brief | D32: Brief §3
A33: Interim distributions to sponsor | B33: 0 | C33: $m / year — none per brief | D33: Brief §5
A35: 4. OPERATING PLAN (PROJECTION YEARS 1–5)
B36: Year 1 | C36: Year 2 | D36: Year 3 | E36: Year 4 | F36: Year 5
A37: Revenue growth | B37: 0.12 | C37: 0.11 | D37: 0.1 | E37: 0.09 | F37: 0.08 | G37: Brief §4
A38: EBITDA margin | B38: 0.35 | C38: 0.36 | D38: 0.36 | E38: 0.37 | F38: 0.38 | G38: Brief §4
A39: D&A (% of revenue) | B39: 0.04 | D39: Brief §4
A40: Maintenance capex (% of revenue) | B40: 0.03 | D40: Brief §4
A41: Growth capex (% of revenue) | B41: 0.01 | D41: Brief §4
A42: Change in NWC (% of Δ revenue) | B42: 0.05 | D42: Brief §4
A43: Cash tax rate | B43: 0.25 | D43: Brief §4
...

Sheet Sources and Uses
A1: SOURCES & USES OF FUNDS — AT CLOSE
A2: USD millions. All lines are live formulas driven by the Assumptions sheet.
A4: ENTRY VALUATION
A5: Offer price per share | B5: =Share_Price*(1+Offer_Premium) | C5: i.e. $4.40 × (1 + 25%) = $5.50 (Brief §2)
A6: Equity purchase price | B6: =B5*FD_Shares+Option_Buyout | C6: i.e. offer price × 60.0m fully diluted shares
A7: Plus: target net debt at close | B7: =Net_Debt_Entry
A8: Entry enterprise value | B8: =B6+B7
A9: Implied entry EV / LTM EBITDA | B9: =B8/Entry_EBITDA
A11: USES OF FUNDS
A12: Equity purchase price | B12: =B6
A13: Refinance target net debt | B13: =Net_Debt_Entry
A14: M&A advisory fees | B14: =Advisory_Fees
A15: Financing fees | B15: =Financing_Fees
A16: Minimum cash funded to balance sheet | B16: =Min_Cash
A17: Total uses of funds | B17: =SUM(B12:B16)
A19: SOURCES OF FUNDS
A20: Senior Term Loan | B20: =TL_Mult*Entry_EBITDA | C20: 4.5× EBITDA; SOFR 4.00% + 350 bps = 7.50% all-in; bullet, 7-year (Brief §3)
A21: Mezzanine Notes | B21: =Mezz_Mult*Entry_EBITDA | C21: 1.0× EBITDA; SOFR 4.00% + 700 bps = 11.00% all-in; bullet, 8-year (Brief §3)
A22: Sponsor equity (balancing plug, new money) | B22: =B17-B20-B21 | C22: i.e. total uses − total debt; no management rollover (Brief §3)
A23: Total sources of funds | B23: =SUM(B20:B22)
A25: CHECKS & PRO-FORMA CAPITALIZATION
A26: Check: total sources − total uses (must be 0) | B26: =B23-B17
A27: Entry leverage — total debt / LTM EBITDA | B27: =(B20+B21)/Entry_EBITDA
A28: Senior leverage — Term Loan / LTM EBITDA | B28: =B20/Entry_EBITDA
A29: Equity % of total capitalization | B29: =B22/B23

Sheet Operating Model
A1: OPERATING MODEL — P&L, FREE CASH FLOW, CASH ROLL-FORWARD
A2: USD millions. Historicals per Brief §1; projection drivers per Brief §4. Interest links from the Debt Schedule.
B4: FY-2 | C4: FY-1 | D4: FY0 (Entry) | E4: Year 1 | F4: Year 2 | G4: Year 3 | H4: Year 4 | I4: Year 5 (Exit)
A5: Revenue | B5: =Assumptions!$B$5 | C5: =Assumptions!$B$6 | D5: =Rev_FY0 | E5: =D5*(1+E6) | F5: =E5*(1+F6) | G5: =F5*(1+G6) | H5: =G5*(1+H6) | I5: =H5*(1+I6)
A6: Revenue growth % | C6: =C5/B5-1 | D6: =D5/C5-1 | E6: =Growth_Y1 | F6: =Growth_Y2 | G6: =Growth_Y3 | H6: =Growth_Y4 | I6: =Growth_Y5
A7: EBITDA margin % | B7: =B8/B5 | C7: =C8/C5 | D7: =D8/D5 | E7: =Margin_Y1 | F7: =Margin_Y2 | G7: =Margin_Y3 | H7: =Margin_Y4 | I7: =Margin_Y5
A8: EBITDA | B8: =Assumptions!$B$8 | C8: =Assumptions!$B$9 | D8: =Assumptions!$B$10 | E8: =E5*E7 | F8: =F5*F7 | G8: =G5*G7 | H8: =H5*H7 | I8: =I5*I7
A9: Less: D&A (4.0% of revenue) | E9: =-DA_Pct*E5 | F9: =-DA_Pct*F5 | G9: =-DA_Pct*G5 | H9: =-DA_Pct*H5 | I9: =-DA_Pct*I5
A10: EBIT | E10: =E8+E9 | F10: =F8+F9 | G10: =G8+G9 | H10: =H8+H9 | I10: =I8+I9
A11: Less: cash interest expense | E11: =-'Debt Schedule'!B21 | F11: =-'Debt Schedule'!C21 | G11: =-'Debt Schedule'!D21 | H11: =-'Debt Schedule'!E21 | I11: =-'Debt Schedule'!F21
A12: Pre-tax income (EBT) | E12: =E10+E11 | F12: =F10+F11 | G12: =G10+G11 | H12: =H10+H11 | I12: =I10+I11
A13: Less: cash taxes (25% of positive EBT) | E13: =-MAX(0,E12)*Tax_Rate | F13: =-MAX(0,F12)*Tax_Rate | G13: =-MAX(0,G12)*Tax_Rate | H13: =-MAX(0,H12)*Tax_Rate | I13: =-MAX(0,I12)*Tax_Rate
A14: Net income | E14: =E12+E13 | F14: =F12+F13 | G14: =G12+G13 | H14: =H12+H13 | I14: =I12+I13
A16: LEVERED FREE CASH FLOW
A17: Net income | E17: =E14 | F17: =F14 | G17: =G14 | H17: =H14 | I17: =I14
A18: Plus: D&A | E18: =-E9 | F18: =-F9 | G18: =-G9 | H18: =-H9 | I18: =-I9
A19: Less: maintenance capex (3.0% of revenue) | E19: =-MaintCapex_Pct*E5 | F19: =-MaintCapex_Pct*F5 | G19: =-MaintCapex_Pct*G5 | H19: =-MaintCapex_Pct*H5 | I19: =-MaintCapex_Pct*I5
A20: Less: growth capex (1.0% of revenue) | E20: =-GrowthCapex_Pct*E5 | F20: =-GrowthCapex_Pct*F5 | G20: =-GrowthCapex_Pct*G5 | H20: =-GrowthCapex_Pct*H5 | I20: =-GrowthCapex_Pct*I5
A21: Less: increase in net working capital (5% of Δ revenue) | E21: =-NWC_Pct*(E5-D5) | F21: =-NWC_Pct*(F5-E5) | G21: =-NWC_Pct*(G5-F5) | H21: =-NWC_Pct*(H5-G5) | I21: =-NWC_Pct*(I5-H5)
A22: Levered free cash flow (no scheduled amortization) | E22: =SUM(E17:E21) | F22: =SUM(F17:F21) | G22: =SUM(G17:G21) | H22: =SUM(H17:H21) | I22: =SUM(I17:I21)
A24: CASH ROLL-FORWARD (no cash sweep — FCF accumulates on the balance sheet)
A25: Beginning cash | E25: ='Sources and Uses'!$B$16 | F25: =E27 | G25: =F27 | H25: =G27 | I25: =H27
A26: Plus: levered free cash flow | E26: =E22 | F26: =F22 | G26: =G22 | H26: =H22 | I26: =I22
A27: Ending cash | E27: =E25+E26 | F27: =F25+F26 | G27: =G25+G26 | H27: =H25+H26 | I27: =I25+I26
A28: Memo: ending cash is EXCLUDED from the equity bridge at exit (stated conservative convention, Brief §3 / §5).
A30: CREDIT STATISTICS
A31: Total debt — end of period | E31: ='Debt Schedule'!B20 | F31: ='Debt Schedule'!C20 | G31: ='Debt Schedule'!D20 | H31: ='Debt Schedule'!E20 | I31: ='Debt Schedule'!F20
A32: Gross leverage — total debt / EBITDA | E32: =E31/E8 | F32: =F31/F8 | G32: =G31/G8 | H32: =H31/H8 | I32: =I31/I8
A33: Net leverage — (total debt − cash) / EBITDA | E33: =(E31-E27)/E8 | F33: =(F31-F27)/F8 | G33: =(G31-G27)/G8 | H33: =(H31-H27)/H8 | I33: =(I31-I27)/I8
A34: Interest coverage — EBITDA / cash interest | E34: =E8/-E11 | F34: =F8/-F11 | G34: =G8/-G11 | H34: =H8/-H11 | I34: =I8/-I11

Sheet Debt Schedule
A1: DEBT SCHEDULE — PER-TRANCHE ROLL-FORWARD
A2: USD millions. Interest accrues on the opening balance of each year (Brief §3). Both tranches are bullet with no cash sweep, so balances are flat through exit.
B4: Year 1 | C4: Year 2 | D4: Year 3 | E4: Year 4 | F4: Year 5
A5: SENIOR TERM LOAN — SOFR + 350 bps, bullet, 7-year tenor
A6: All-in interest rate (SOFR 4.00% + 3.50%) | B6: =SOFR_Rate+TL_Spread
A7: Opening balance | B7: =TL_Amount | C7: =B9 | D7: =C9 | E7: =D9 | F7: =E9
A8: Less: scheduled repayment (bullet — none) | B8: =-Sched_Amort | C8: =-Sched_Amort | D8: =-Sched_Amort | E8: =-Sched_Amort | F8: =-Sched_Amort
A9: Closing balance | B9: =B7+B8 | C9: =C7+C8 | D9: =D7+D8 | E9: =E7+E8 | F9: =F7+F8
A10: Interest expense (opening balance × all-in rate) | B10: =B7*$B$6 | C10: =C7*$B$6 | D10: =D7*$B$6 | E10: =E7*$B$6 | F10: =F7*$B$6
A12: MEZZANINE NOTES — SOFR + 700 bps, bullet, 8-year tenor
A13: All-in interest rate (SOFR 4.00% + 7.00%) | B13: =SOFR_Rate+Mezz_Spread
A14: Opening balance | B14: =Mezz_Amount | C14: =B16 | D14: =C16 | E14: =D16 | F14: =E16
A15: Less: scheduled repayment (bullet — none) | B15: =-Sched_Amort | C15: =-Sched_Amort | D15: =-Sched_Amort | E15: =-Sched_Amort | F15: =-Sched_Amort
A16: Closing balance | B16: =B14+B15 | C16: =C14+C15 | D16: =D14+D15 | E16: =E14+E15 | F16: =F14+F15
A17: Interest expense (opening balance × all-in rate) | B17: =B14*$B$13 | C17: =C14*$B$13 | D17: =D14*$B$13 | E17: =E14*$B$13 | F17: =F14*$B$13
A19: TOTAL DEBT
A20: Total debt — closing balance | B20: =B9+B16 | C20: =C9+C16 | D20: =D9+D16 | E20: =E9+E16 | F20: =F9+F16
A21: Total cash interest expense | B21: =B10+B17 | C21: =C10+C17 | D21: =D10+D17 | E21: =E10+E17 | F21: =F10+F17
A23: Debt outstanding at exit (face value, end of Year 5) | B23: =F20
A24: Check: exit debt − (Term Loan + Mezzanine at close) (must be 0) | B24: =B23-(TL_Amount+Mezz_Amount)

Sheet Returns
A1: RETURNS ANALYSIS — EXIT BRIDGE, CASH FLOWS & HEADLINE OUTPUTS
A2: USD millions. Exit at end of Year 5 via strategic sale at 9.0× projected Year-5 EBITDA (Brief §5). No interim distributions.
A4: EQUITY BRIDGE AT EXIT (END OF YEAR 5)
A5: Projected Year-5 EBITDA (exit basis — NOT entry LTM) | B5: =EBITDA_Y5
A6: Exit EV / EBITDA multiple (strategic sale) | B6: =Exit_Multiple
A7: Exit enterprise value | B7: =B5*B6
A8: Less: debt outstanding at exit (face value) | B8: =-Debt_AtExit
A9: Exit equity proceeds | B9: =B7+B8
A10: Memo: accumulated cash at exit — EXCLUDED from the bridge per brief convention | B10: ='Operating Model'!I27
A12: SPONSOR CASH FLOWS (ANNUAL)
B13: Year 0 (Close) | C13: Year 1 | D13: Year 2 | E13: Year 3 | F13: Year 4 | G13: Year 5 (Exit)
A14: Sponsor cash flow | B14: =-Sponsor_Equity | C14: =Dist_PerYear | D14: =Dist_PerYear | E14: =Dist_PerYear | F14: =Dist_PerYear | G14: =Dist_PerYear+$B$9
A16: RETURN CALCULATIONS
A17: IRR — internal rate of return on sponsor cash flows (annual) | B17: =IRR(B14:G14)
A18: MoIC — multiple of invested capital (total inflows / equity invested) | B18: =SUM(C14:G14)/-B14
A20: HEADLINE OUTPUTS (BENCHMARK LABELS)
A21: Sponsor IRR (sponsor_irr) — annual, decimal | B21: =B17 | C21: shown as decimal; equals 15.46% annualized
A22: Sponsor MoIC (sponsor_moic) — x invested capital | B22: =B18
A23: Exit equity proceeds (exit_equity_proceeds) — $m | B23: =B9
A24: Sponsor equity cheque (sponsor_equity_cheque) — $m | B24: =Sponsor_Equity
A26: CHECKS
A27: Check: power-law cross-check of annual return (single-inflow profile; must be ~0) | B27: =ABS((SUM(C14:G14)/-B14)^(1/Hold_Years)-1-B17)
A28: Check: sources and uses balanced (must be 0) | B28: ='Sources and Uses'!B26
A29: Check: exit debt equals face value of tranches (must be 0) | B29: ='Debt Schedule'!B24

Sheet Sensitivity
A1: SENSITIVITY ANALYSIS — EXIT MULTIPLE × REVENUE GROWTH DELTA
A2: Closed-form grids (live formulas): annual return = ((M × Year-5 EBITDA(Δg) − exit debt) / invested equity)^(1/5) − 1, where Δg shifts every projection-year growth rate uniformly. Center cell = base case (9.0×, Δg = 0).
A4: GRID 1 — ANNUALIZED SPONSOR RETURN
B5: EV/EBITDA ↓ Δ growth → | C5: =-2*Sens_GrowthStep | D5: =C5+Sens_GrowthStep | E5: =D5+Sens_GrowthStep | F5: =E5+Sens_GrowthStep | G5: =F5+Sens_GrowthStep
B6: =Exit_Multiple-2*Sens_MultStep | C6: =(($B6*(Rev_FY0*(1+Growth_Y1+C$5)*(1+Growth_Y2+C$5)*(1+Growth_Y3+C$5)*(1+Growth_Y4+C$5)*(1+Growth_Y5+C$5)*Margin_Y5)-Debt_AtExit)/Sponsor_Equity)^(1/Hold_Years)-1 | D6: =(($B6*(Rev_FY0*(1+Growth_Y1+D$5)*(1+Growth_Y2+D$5)*(1+Growth_Y3+D$5)*(1+Growth_Y4+D$5)*(1+Growth_Y5+D$5)*Margin_Y5)-Debt_AtExit)/Sponsor_Equity)^(1/Hold_Years)-1 | E6: =(($B6*(Rev_FY0*(1+Growth_Y1+E$5)*(1+Growth_Y2+E$5)*(1+Growth_Y3+E$5)*(1+Growth_Y4+E$5)*(1+Growth_Y5+E$5)*Margin_Y5)-Debt_AtExit)/Sponsor_Equity)^(1/Hold_Years)-1 | F6: =(($B6*(Rev_FY0*(1+Growth_Y1+F$5)*(1+Growth_Y2+F$5)*(1+Growth_Y3+F$5)*(1+Growth_Y4+F$5)*(1+Growth_Y5+F$5)*Margin_Y5)-Debt_AtExit)/Sponsor_Equity)^(1/Hold_Years)-1 | G6: =(($B6*(Rev_FY0*(1+Growth_Y1+G$5)*(1+Growth_Y2+G$5)*(1+Growth_Y3+G$5)*(1+Growth_Y4+G$5)*(1+Growth_Y5+G$5)*Margin_Y5)-Debt_AtExit)/Sponsor_Equity)^(1/Hold_Years)-1
B7: =B6+Sens_MultStep | C7: =(($B7*(Rev_FY0*(1+Growth_Y1+C$5)*(1+Growth_Y2+C$5)*(1+Growth_Y3+C$5)*(1+Growth_Y4+C$5)*(1+Growth_Y5+C$5)*Margin_Y5)-Debt_AtExit)/Sponsor_Equity)^(1/Hold_Years)-1 | D7: =(($B7*(Rev_FY0*(1+Growth_Y1+D$5)*(1+Growth_Y2+D$5)*(1+Growth_Y3+D$5)*(1+Growth_Y4+D$5)*(1+Growth_Y5+D$5)*Margin_Y5)-Debt_AtExit)/Sponsor_Equity)^(1/Hold_Years)-1 | E7: =(($B7*(Rev_FY0*(1+Growth_Y1+E$5)*(1+Growth_Y2+E$5)*(1+Growth_Y3+E$5)*(1+Growth_Y4+E$5)*(1+Growth_Y5+E$5)*Margin_Y5)-Debt_AtExit)/Sponsor_Equity)^(1/Hold_Years)-1 | F7: =(($B7*(Rev_FY0*(1+Growth_Y1+F$5)*(1+Growth_Y2+F$5)*(1+Growth_Y3+F$5)*(1+Growth_Y4+F$5)*(1+Growth_Y5+F$5)*Margin_Y5)-Debt_AtExit)/Sponsor_Equity)^(1/Hold_Years)-1 | G7: =(($B7*(Rev_FY0*(1+Growth_Y1+G$5)*(1+Growth_Y2+G$5)*(1+Growth_Y3+G$5)*(1+Growth_Y4+G$5)*(1+Growth_Y5+G$5)*Margin_Y5)-Debt_AtExit)/Sponsor_Equity)^(1/Hold_Years)-1
B8: =B7+Sens_MultStep | C8: =(($B8*(Rev_FY0*(1+Growth_Y1+C$5)*(1+Growth_Y2+C$5)*(1+Growth_Y3+C$5)*(1+Growth_Y4+C$5)*(1+Growth_Y5+C$5)*Margin_Y5)-Debt_AtExit)/Sponsor_Equity)^(1/Hold_Years)-1 | D8: =(($B8*(Rev_FY0*(1+Growth_Y1+D$5)*(1+Growth_Y2+D$5)*(1+Growth_Y3+D$5)*(1+Growth_Y4+D$5)*(1+Growth_Y5+D$5)*Margin_Y5)-Debt_AtExit)/Sponsor_Equity)^(1/Hold_Years)-1 | E8: =(($B8*(Rev_FY0*(1+Growth_Y1+E$5)*(1+Growth_Y2+E$5)*(1+Growth_Y3+E$5)*(1+Growth_Y4+E$5)*(1+Growth_Y5+E$5)*Margin_Y5)-Debt_AtExit)/Sponsor_Equity)^(1/Hold_Years)-1 | F8: =(($B8*(Rev_FY0*(1+Growth_Y1+F$5)*(1+Growth_Y2+F$5)*(1+Growth_Y3+F$5)*(1+Growth_Y4+F$5)*(1+Growth_Y5+F$5)*Margin_Y5)-Debt_AtExit)/Sponsor_Equity)^(1/Hold_Years)-1 | G8: =(($B8*(Rev_FY0*(1+Growth_Y1+G$5)*(1+Growth_Y2+G$5)*(1+Growth_Y3+G$5)*(1+Growth_Y4+G$5)*(1+Growth_Y5+G$5)*Margin_Y5)-Debt_AtExit)/Sponsor_Equity)^(1/Hold_Years)-1
B9: =B8+Sens_MultStep | C9: =(($B9*(Rev_FY0*(1+Growth_Y1+C$5)*(1+Growth_Y2+C$5)*(1+Growth_Y3+C$5)*(1+Growth_Y4+C$5)*(1+Growth_Y5+C$5)*Margin_Y5)-Debt_AtExit)/Sponsor_Equity)^(1/Hold_Years)-1 | D9: =(($B9*(Rev_FY0*(1+Growth_Y1+D$5)*(1+Growth_Y2+D$5)*(1+Growth_Y3+D$5)*(1+Growth_Y4+D$5)*(1+Growth_Y5+D$5)*Margin_Y5)-Debt_AtExit)/Sponsor_Equity)^(1/Hold_Years)-1 | E9: =(($B9*(Rev_FY0*(1+Growth_Y1+E$5)*(1+Growth_Y2+E$5)*(1+Growth_Y3+E$5)*(1+Growth_Y4+E$5)*(1+Growth_Y5+E$5)*Margin_Y5)-Debt_AtExit)/Sponsor_Equity)^(1/Hold_Years)-1 | F9: =(($B9*(Rev_FY0*(1+Growth_Y1+F$5)*(1+Growth_Y2+F$5)*(1+Growth_Y3+F$5)*(1+Growth_Y4+F$5)*(1+Growth_Y5+F$5)*Margin_Y5)-Debt_AtExit)/Sponsor_Equity)^(1/Hold_Years)-1 | G9: =(($B9*(Rev_FY0*(1+Growth_Y1+G$5)*(1+Growth_Y2+G$5)*(1+Growth_Y3+G$5)*(1+Growth_Y4+G$5)*(1+Growth_Y5+G$5)*Margin_Y5)-Debt_AtExit)/Sponsor_Equity)^(1/Hold_Years)-1
B10: =B9+Sens_MultStep | C10: =(($B10*(Rev_FY0*(1+Growth_Y1+C$5)*(1+Growth_Y2+C$5)*(1+Growth_Y3+C$5)*(1+Growth_Y4+C$5)*(1+Growth_Y5+C$5)*Margin_Y5)-Debt_AtExit)/Sponsor_Equity)^(1/Hold_Years)-1 | D10: =(($B10*(Rev_FY0*(1+Growth_Y1+D$5)*(1+Growth_Y2+D$5)*(1+Growth_Y3+D$5)*(1+Growth_Y4+D$5)*(1+Growth_Y5+D$5)*Margin_Y5)-Debt_AtExit)/Sponsor_Equity)^(1/Hold_Years)-1 | E10: =(($B10*(Rev_FY0*(1+Growth_Y1+E$5)*(1+Growth_Y2+E$5)*(1+Growth_Y3+E$5)*(1+Growth_Y4+E$5)*(1+Growth_Y5+E$5)*Margin_Y5)-Debt_AtExit)/Sponsor_Equity)^(1/Hold_Years)-1 | F10: =(($B10*(Rev_FY0*(1+Growth_Y1+F$5)*(1+Growth_Y2+F$5)*(1+Growth_Y3+F$5)*(1+Growth_Y4+F$5)*(1+Growth_Y5+F$5)*Margin_Y5)-Debt_AtExit)/Sponsor_Equity)^(1/Hold_Years)-1 | G10: =(($B10*(Rev_FY0*(1+Growth_Y1+G$5)*(1+Growth_Y2+G$5)*(1+Growth_Y3+G$5)*(1+Growth_Y4+G$5)*(1+Growth_Y5+G$5)*Margin_Y5)-Debt_AtExit)/Sponsor_Equity)^(1/Hold_Years)-1
A12: GRID 2 — EXIT PROCEEDS ÷ EQUITY INVESTED (×)
B13: EV/EBITDA ↓ Δ growth → | C13: =-2*Sens_GrowthStep | D13: =C13+Sens_GrowthStep | E13: =D13+Sens_GrowthStep | F13: =E13+Sens_GrowthStep | G13: =F13+Sens_GrowthStep
B14: =Exit_Multiple-2*Sens_MultStep | C14: =($B14*(Rev_FY0*(1+Growth_Y1+C$13)*(1+Growth_Y2+C$13)*(1+Growth_Y3+C$13)*(1+Growth_Y4+C$13)*(1+Growth_Y5+C$13)*Margin_Y5)-Debt_AtExit)/Sponsor_Equity | D14: =($B14*(Rev_FY0*(1+Growth_Y1+D$13)*(1+Growth_Y2+D$13)*(1+Growth_Y3+D$13)*(1+Growth_Y4+D$13)*(1+Growth_Y5+D$13)*Margin_Y5)-Debt_AtExit)/Sponsor_Equity | E14: =($B14*(Rev_FY0*(1+Growth_Y1+E$13)*(1+Growth_Y2+E$13)*(1+Growth_Y3+E$13)*(1+Growth_Y4+E$13)*(1+Growth_Y5+E$13)*Margin_Y5)-Debt_AtExit)/Sponsor_Equity | F14: =($B14*(Rev_FY0*(1+Growth_Y1+F$13)*(1+Growth_Y2+F$13)*(1+Growth_Y3+F$13)*(1+Growth_Y4+F$13)*(1+Growth_Y5+F$13)*Margin_Y5)-Debt_AtExit)/Sponsor_Equity | G14: =($B14*(Rev_FY0*(1+Growth_Y1+G$13)*(1+Growth_Y2+G$13)*(1+Growth_Y3+G$13)*(1+Growth_Y4+G$13)*(1+Growth_Y5+G$13)*Margin_Y5)-Debt_AtExit)/Sponsor_Equity
B15: =B14+Sens_MultStep | C15: =($B15*(Rev_FY0*(1+Growth_Y1+C$13)*(1+Growth_Y2+C$13)*(1+Growth_Y3+C$13)*(1+Growth_Y4+C$13)*(1+Growth_Y5+C$13)*Margin_Y5)-Debt_AtExit)/Sponsor_Equity | D15: =($B15*(Rev_FY0*(1+Growth_Y1+D$13)*(1+Growth_Y2+D$13)*(1+Growth_Y3+D$13)*(1+Growth_Y4+D$13)*(1+Growth_Y5+D$13)*Margin_Y5)-Debt_AtExit)/Sponsor_Equity | E15: =($B15*(Rev_FY0*(1+Growth_Y1+E$13)*(1+Growth_Y2+E$13)*(1+Growth_Y3+E$13)*(1+Growth_Y4+E$13)*(1+Growth_Y5+E$13)*Margin_Y5)-Debt_AtExit)/Sponsor_Equity | F15: =($B15*(Rev_FY0*(1+Growth_Y1+F$13)*(1+Growth_Y2+F$13)*(1+Growth_Y3+F$13)*(1+Growth_Y4+F$13)*(1+Growth_Y5+F$13)*Margin_Y5)-Debt_AtExit)/Sponsor_Equity | G15: =($B15*(Rev_FY0*(1+Growth_Y1+G$13)*(1+Growth_Y2+G$13)*(1+Growth_Y3+G$13)*(1+Growth_Y4+G$13)*(1+Growth_Y5+G$13)*Margin_Y5)-Debt_AtExit)/Sponsor_Equity
B16: =B15+Sens_MultStep | C16: =($B16*(Rev_FY0*(1+Growth_Y1+C$13)*(1+Growth_Y2+C$13)*(1+Growth_Y3+C$13)*(1+Growth_Y4+C$13)*(1+Growth_Y5+C$13)*Margin_Y5)-Debt_AtExit)/Sponsor_Equity | D16: =($B16*(Rev_FY0*(1+Growth_Y1+D$13)*(1+Growth_Y2+D$13)*(1+Growth_Y3+D$13)*(1+Growth_Y4+D$13)*(1+Growth_Y5+D$13)*Margin_Y5)-Debt_AtExit)/Sponsor_Equity | E16: =($B16*(Rev_FY0*(1+Growth_Y1+E$13)*(1+Growth_Y2+E$13)*(1+Growth_Y3+E$13)*(1+Growth_Y4+E$13)*(1+Growth_Y5+E$13)*Margin_Y5)-Debt_AtExit)/Sponsor_Equity | F16: =($B16*(Rev_FY0*(1+Growth_Y1+F$13)*(1+Growth_Y2+F$13)*(1+Growth_Y3+F$13)*(1+Growth_Y4+F$13)*(1+Growth_Y5+F$13)*Margin_Y5)-Debt_AtExit)/Sponsor_Equity | G16: =($B16*(Rev_FY0*(1+Growth_Y1+G$13)*(1+Growth_Y2+G$13)*(1+Growth_Y3+G$13)*(1+Growth_Y4+G$13)*(1+Growth_Y5+G$13)*Margin_Y5)-Debt_AtExit)/Sponsor_Equity
B17: =B16+Sens_MultStep | C17: =($B17*(Rev_FY0*(1+Growth_Y1+C$13)*(1+Growth_Y2+C$13)*(1+Growth_Y3+C$13)*(1+Growth_Y4+C$13)*(1+Growth_Y5+C$13)*Margin_Y5)-Debt_AtExit)/Sponsor_Equity | D17: =($B17*(Rev_FY0*(1+Growth_Y1+D$13)*(1+Growth_Y2+D$13)*(1+Growth_Y3+D$13)*(1+Growth_Y4+D$13)*(1+Growth_Y5+D$13)*Margin_Y5)-Debt_AtExit)/Sponsor_Equity | E17: =($B17*(Rev_FY0*(1+Growth_Y1+E$13)*(1+Growth_Y2+E$13)*(1+Growth_Y3+E$13)*(1+Growth_Y4+E$13)*(1+Growth_Y5+E$13)*Margin_Y5)-Debt_AtExit)/Sponsor_Equity | F17: =($B17*(Rev_FY0*(1+Growth_Y1+F$13)*(1+Growth_Y2+F$13)*(1+Growth_Y3+F$13)*(1+Growth_Y4+F$13)*(1+Growth_Y5+F$13)*Margin_Y5)-Debt_AtExit)/Sponsor_Equity | G17: =($B17*(Rev_FY0*(1+Growth_Y1+G$13)*(1+Growth_Y2+G$13)*(1+Growth_Y3+G$13)*(1+Growth_Y4+G$13)*(1+Growth_Y5+G$13)*Margin_Y5)-Debt_AtExit)/Sponsor_Equity
B18: =B17+Sens_MultStep | C18: =($B18*(Rev_FY0*(1+Growth_Y1+C$13)*(1+Growth_Y2+C$13)*(1+Growth_Y3+C$13)*(1+Growth_Y4+C$13)*(1+Growth_Y5+C$13)*Margin_Y5)-Debt_AtExit)/Sponsor_Equity | D18: =($B18*(Rev_FY0*(1+Growth_Y1+D$13)*(1+Growth_Y2+D$13)*(1+Growth_Y3+D$13)*(1+Growth_Y4+D$13)*(1+Growth_Y5+D$13)*Margin_Y5)-Debt_AtExit)/Sponsor_Equity | E18: =($B18*(Rev_FY0*(1+Growth_Y1+E$13)*(1+Growth_Y2+E$13)*(1+Growth_Y3+E$13)*(1+Growth_Y4+E$13)*(1+Growth_Y5+E$13)*Margin_Y5)-Debt_AtExit)/Sponsor_Equity | F18: =($B18*(Rev_FY0*(1+Growth_Y1+F$13)*(1+Growth_Y2+F$13)*(1+Growth_Y3+F$13)*(1+Growth_Y4+F$13)*(1+Growth_Y5+F$13)*Margin_Y5)-Debt_AtExit)/Sponsor_Equity | G18: =($B18*(Rev_FY0*(1+Growth_Y1+G$13)*(1+Growth_Y2+G$13)*(1+Growth_Y3+G$13)*(1+Growth_Y4+G$13)*(1+Growth_Y5+G$13)*Margin_Y5)-Debt_AtExit)/Sponsor_Equity
A20: Check: grid 1 center − base annual return (must be 0) | B20: =ABS(E8-Returns!$B$17)
A21: Check: grid 2 center − base capital multiple (must be 0) | B21: =ABS(E16-Returns!$B$18)
