Workbook

Sheet Cover
B1: PROJECT SAASCO — SPONSOR LBO MODEL
B2: BM-LBO-001 - synthetic benchmark deal - all figures fictional - USD millions unless stated - built 2026-06-12
B4: TRANSACTION SNAPSHOT
B5: Entry enterprise value ($m) | C5: =Assumptions!$C$20
B6: Implied entry EV / LTM EBITDA | C6: =Assumptions!$C$21
B7: Total debt at close ($m) | C7: ='Sources & Uses'!$C$17
B8: Opening leverage (debt / LTM EBITDA) | C8: ='Sources & Uses'!$C$17/Assumptions!$C$10
B9: Sponsor equity cheque ($m) | C9: ='Sources & Uses'!$C$18
B10: Hold period (years) | C10: =Assumptions!$C$46
B12: HEADLINE OUTPUTS
B13: Sponsor IRR (annual) | C13: =Returns!$C$18
B14: Sponsor MoIC | C14: =Returns!$C$19
B15: Exit equity proceeds ($m) | C15: =Returns!$C$20
B16: Sponsor equity cheque ($m) | C16: =Returns!$C$21
B18: CONTENTS
B19: Assumptions
B20: Sources & Uses
B21: Operating Model
B22: Debt Schedule
B23: Returns
B24: Sensitivity
B26: Convention: bullet debt, no cash sweep, no revolver, no dividends; interest on opening balances; FCF accumulates as cash and is EXCLUDED from the exit equity bridge (deal brief, section 5).

Sheet Assumptions
B1: ASSUMPTIONS — ALL MODEL INPUTS
B2: Blue = hardcoded input - black = calculation - USD millions unless stated
B4: TARGET & HISTORICAL FINANCIALS
C5: FY-2 | D5: FY-1 | E5: FY0 (LTM)
B6: Revenue | C6: 81 | D6: 90 | E6: 100
B7: EBITDA | C7: 26.7 | D7: 30.6 | E7: 35
B8: EBITDA margin | C8: =C7/C6 | D8: =D7/D6 | E8: =E7/E6
B9: Revenue growth | D9: =D6/C6-1 | E9: =E6/D6-1
B10: Entry (LTM) EBITDA | C10: =E7
B11: Target net debt at close (refinanced) | C11: 20
B13: OFFER & ENTRY VALUATION
B14: Current share price ($/share) | C14: 4.4
B15: Offer premium | C15: 0.25
B16: Offer price per share ($/share) | C16: =C14*(1+C15)
B17: Fully diluted shares (m) | C17: 60
B18: Option / RSU buyout | C18: 0
B19: Equity purchase price | C19: =C16*C17+C18
B20: Entry enterprise value | C20: =C19+C11
B21: Implied entry EV / EBITDA | C21: =C20/C10
B23: TRANSACTION COSTS & MINIMUM CASH
B24: M&A advisory fees | C24: 7
B25: Financing fees | C25: 5
B26: Minimum cash funded to balance sheet | C26: 5
B28: DEBT FINANCING
B29: SOFR (base rate) | C29: 0.04
C30: Leverage (x LTM) | D30: Spread | E30: All-in rate | F30: Tenor (yrs) | G30: Amortisation
B31: Senior Term Loan | C31: 4.5 | D31: 0.035 | E31: =$C$29+D31 | F31: 7 | G31: Bullet
B32: Mezzanine Notes | C32: 1 | D32: 0.07 | E32: =$C$29+D32 | F32: 8 | G32: Bullet
B33: Conventions: no cash sweep - no revolver - no dividend recap - no PIK - no OID/floors - interest accrues on opening balance of each year.
B35: OPERATING PLAN (PROJECTION YEARS 1-5)
C36: Year 1 | D36: Year 2 | E36: Year 3 | F36: Year 4 | G36: Year 5
B37: Revenue growth | C37: 0.12 | D37: 0.11 | E37: 0.1 | F37: 0.09 | G37: 0.08
B38: EBITDA margin | C38: 0.35 | D38: 0.36 | E38: 0.36 | F38: 0.37 | G38: 0.38
B39: D&A (% of revenue) | C39: 0.04
B40: Maintenance capex (% of revenue) | C40: 0.03
B41: Growth capex (% of revenue) | C41: 0.01
B42: Change in NWC (% of change in revenue) | C42: 0.05
B43: Cash tax rate | C43: 0.25
B45: EXIT ASSUMPTIONS
B46: Hold period (years) | C46: 5
...

Sheet Sources & Uses
B1: SOURCES & USES OF FUNDS (AT CLOSE)
B2: USD millions - all funded at close
B4: USES OF FUNDS
C5: $m | D5: % of total
B6: Equity purchase price | C6: =Assumptions!$C$19 | D6: =C6/$C$11
B7: Refinance target net debt | C7: =Assumptions!$C$11 | D7: =C7/$C$11
B8: M&A advisory fees | C8: =Assumptions!$C$24 | D8: =C8/$C$11
B9: Financing fees | C9: =Assumptions!$C$25 | D9: =C9/$C$11
B10: Minimum cash funded to balance sheet | C10: =Assumptions!$C$26 | D10: =C10/$C$11
B11: Total uses | C11: =SUM(C6:C10) | D11: =SUM(D6:D10)
B13: SOURCES OF FUNDS
C14: $m | D14: % of total | E14: x LTM EBITDA
B15: Senior Term Loan (SOFR+350, bullet, 7y) | C15: =Assumptions!$C$31*Assumptions!$C$10 | D15: =C15/$C$19 | E15: =C15/Assumptions!$C$10
B16: Mezzanine Notes (SOFR+700, bullet, 8y) | C16: =Assumptions!$C$32*Assumptions!$C$10 | D16: =C16/$C$19 | E16: =C16/Assumptions!$C$10
B17: Total debt | C17: =SUM(C15:C16) | D17: =C17/$C$19 | E17: =C17/Assumptions!$C$10
B18: Sponsor equity (balancing plug; new money, no rollover) | C18: =C11-C17 | D18: =C18/$C$19
B19: Total sources | C19: =C17+C18 | D19: =SUM(D17:D18)
B21: CHECKS & ENTRY VALUATION
B22: Balance check: sources - uses (must be 0) | C22: =C19-C11 | D22: =IF(ABS(C22)<0.000001,"OK","ERROR")
B23: Entry enterprise value | C23: =Assumptions!$C$20
B24: Implied entry EV / LTM EBITDA | C24: =C23/Assumptions!$C$10
B25: Opening leverage: total debt / LTM EBITDA | C25: =C17/Assumptions!$C$10
B26: Equity contribution (% of total capitalization) | C26: =C18/C19

Sheet Operating Model
B1: OPERATING MODEL & FREE CASH FLOW
B2: USD millions - projection years 1-5 (hold period)
C4: FY0A | D4: FY1E | E4: FY2E | F4: FY3E | G4: FY4E | H4: FY5E
B5: REVENUE & PROFITABILITY
B6: Revenue growth | D6: =Assumptions!C37 | E6: =Assumptions!D37 | F6: =Assumptions!E37 | G6: =Assumptions!F37 | H6: =Assumptions!G37
B7: Revenue | C7: =Assumptions!$E$6 | D7: =C7*(1+D6) | E7: =D7*(1+E6) | F7: =E7*(1+F6) | G7: =F7*(1+G6) | H7: =G7*(1+H6)
B8: EBITDA margin | C8: =C9/C7 | D8: =Assumptions!C38 | E8: =Assumptions!D38 | F8: =Assumptions!E38 | G8: =Assumptions!F38 | H8: =Assumptions!G38
B9: EBITDA | C9: =Assumptions!$E$7 | D9: =D7*D8 | E9: =E7*E8 | F9: =F7*F8 | G9: =G7*G8 | H9: =H7*H8
B10: D&A (4.0% of revenue) | D10: =Assumptions!$C$39*D7 | E10: =Assumptions!$C$39*E7 | F10: =Assumptions!$C$39*F7 | G10: =Assumptions!$C$39*G7 | H10: =Assumptions!$C$39*H7
B11: EBIT | D11: =D9-D10 | E11: =E9-E10 | F11: =F9-F10 | G11: =G9-G10 | H11: =H9-H10
B13: FREE CASH FLOW BUILD
B14: EBITDA | D14: =D9 | E14: =E9 | F14: =F9 | G14: =G9 | H14: =H9
B15: Less: cash interest (opening balances) | D15: =-'Debt Schedule'!D21 | E15: =-'Debt Schedule'!E21 | F15: =-'Debt Schedule'!F21 | G15: =-'Debt Schedule'!G21 | H15: =-'Debt Schedule'!H21
B16: Less: cash taxes (25% x EBT) | D16: =-Assumptions!$C$43*(D11+D15) | E16: =-Assumptions!$C$43*(E11+E15) | F16: =-Assumptions!$C$43*(F11+F15) | G16: =-Assumptions!$C$43*(G11+G15) | H16: =-Assumptions!$C$43*(H11+H15)
B17: Less: maintenance capex (3.0% of revenue) | D17: =-Assumptions!$C$40*D7 | E17: =-Assumptions!$C$40*E7 | F17: =-Assumptions!$C$40*F7 | G17: =-Assumptions!$C$40*G7 | H17: =-Assumptions!$C$40*H7
B18: Less: growth capex (1.0% of revenue) | D18: =-Assumptions!$C$41*D7 | E18: =-Assumptions!$C$41*E7 | F18: =-Assumptions!$C$41*F7 | G18: =-Assumptions!$C$41*G7 | H18: =-Assumptions!$C$41*H7
B19: Less: change in net working capital (5% x chg revenue) | D19: =-Assumptions!$C$42*(D7-C7) | E19: =-Assumptions!$C$42*(E7-D7) | F19: =-Assumptions!$C$42*(F7-E7) | G19: =-Assumptions!$C$42*(G7-F7) | H19: =-Assumptions!$C$42*(H7-G7)
B20: Free cash flow (no sweep - builds as cash) | D20: =SUM(D14:D19) | E20: =SUM(E14:E19) | F20: =SUM(F14:F19) | G20: =SUM(G14:G19) | H20: =SUM(H14:H19)
B22: CASH ROLL-FORWARD (NO CASH SWEEP)
B23: Opening cash | D23: ='Sources & Uses'!$C$10 | E23: =D25 | F23: =E25 | G23: =F25 | H23: =G25
B24: Plus: free cash flow | D24: =D20 | E24: =E20 | F24: =F20 | G24: =G20 | H24: =H20
B25: Closing cash | D25: =D23+D24 | E25: =E23+E24 | F25: =F23+F24 | G25: =G23+G24 | H25: =H23+H24
B27: Memo: pre-tax income (EBT) | D27: =D11+D15 | E27: =E11+E15 | F27: =F11+F15 | G27: =G11+G15 | H27: =H11+H15
B28: Cash accumulates on the balance sheet and is EXCLUDED from the exit equity bridge (deal convention, brief section 5). It does not affect headline IRR / MoIC.

Sheet Debt Schedule
B1: DEBT SCHEDULE — PER-TRANCHE ROLL-FORWARD
B2: USD millions - both tranches bullet, no cash sweep - interest on opening balance
C4: At close | D4: FY1E | E4: FY2E | F4: FY3E | G4: FY4E | H4: FY5E
B5: SENIOR TERM LOAN (SOFR + 350bps - BULLET - 7-YEAR TENOR)
B6: Opening balance | D6: =C8 | E6: =D8 | F6: =E8 | G6: =F8 | H6: =G8
B7: Less: amortisation / cash sweep (bullet, none) | D7: 0 | E7: 0 | F7: 0 | G7: 0 | H7: 0
B8: Closing balance | C8: ='Sources & Uses'!$C$15 | D8: =D6-D7 | E8: =E6-E7 | F8: =F6-F7 | G8: =G6-G7 | H8: =H6-H7
B9: All-in interest rate | D9: =Assumptions!$E$31 | E9: =Assumptions!$E$31 | F9: =Assumptions!$E$31 | G9: =Assumptions!$E$31 | H9: =Assumptions!$E$31
B10: Interest expense (rate x opening balance) | D10: =D9*D6 | E10: =E9*E6 | F10: =F9*F6 | G10: =G9*G6 | H10: =H9*H6
B12: MEZZANINE NOTES (SOFR + 700bps - BULLET - 8-YEAR TENOR)
B13: Opening balance | D13: =C15 | E13: =D15 | F13: =E15 | G13: =F15 | H13: =G15
B14: Less: amortisation / cash sweep (bullet, none) | D14: 0 | E14: 0 | F14: 0 | G14: 0 | H14: 0
B15: Closing balance | C15: ='Sources & Uses'!$C$16 | D15: =D13-D14 | E15: =E13-E14 | F15: =F13-F14 | G15: =G13-G14 | H15: =H13-H14
B16: All-in interest rate | D16: =Assumptions!$E$32 | E16: =Assumptions!$E$32 | F16: =Assumptions!$E$32 | G16: =Assumptions!$E$32 | H16: =Assumptions!$E$32
B17: Interest expense (rate x opening balance) | D17: =D16*D13 | E17: =E16*E13 | F17: =F16*F13 | G17: =G16*G13 | H17: =H16*H13
B19: TOTALS & CREDIT STATISTICS
B20: Total debt - closing balance | C20: =C8+C15 | D20: =D8+D15 | E20: =E8+E15 | F20: =F8+F15 | G20: =G8+G15 | H20: =H8+H15
B21: Total cash interest expense | D21: =D10+D17 | E21: =E10+E17 | F21: =F10+F17 | G21: =G10+G17 | H21: =H10+H17
B22: Memo: closing cash (from operating model) | D22: ='Operating Model'!D25 | E22: ='Operating Model'!E25 | F22: ='Operating Model'!F25 | G22: ='Operating Model'!G25 | H22: ='Operating Model'!H25
B23: Net debt (total debt - cash) | D23: =D20-D22 | E23: =E20-E22 | F23: =F20-F22 | G23: =G20-G22 | H23: =H20-H22
B24: Gross leverage: total debt / EBITDA | D24: =D20/'Operating Model'!D9 | E24: =E20/'Operating Model'!E9 | F24: =F20/'Operating Model'!F9 | G24: =G20/'Operating Model'!G9 | H24: =H20/'Operating Model'!H9
B25: Net leverage: net debt / EBITDA | D25: =D23/'Operating Model'!D9 | E25: =E23/'Operating Model'!E9 | F25: =F23/'Operating Model'!F9 | G25: =G23/'Operating Model'!G9 | H25: =H23/'Operating Model'!H9
B26: Interest coverage: EBITDA / cash interest | D26: ='Operating Model'!D9/D21 | E26: ='Operating Model'!E9/E21 | F26: ='Operating Model'!F9/F21 | G26: ='Operating Model'!G9/G21 | H26: ='Operating Model'!H9/H21
B28: Check: debt outstanding at exit = face value at close | C28: =H20-'Sources & Uses'!$C$17 | D28: =IF(ABS(C28)<0.000001,"OK","ERROR")

Sheet Returns
B1: SPONSOR RETURNS — IRR & MoIC
B2: USD millions - exit at end of projection year 5
B4: EXIT VALUATION (END OF YEAR 5)
B5: Exit year (end of projection year) | C5: =Assumptions!$C$46
B6: Exit EBITDA - projected Year-5 (NOT entry LTM) | C6: ='Operating Model'!$H$9
B7: Exit EV / EBITDA multiple (strategic sale) | C7: =Assumptions!$C$47
B8: Exit enterprise value | C8: =C6*C7
B9: Less: debt outstanding at exit (face, bullet) | C9: =-'Debt Schedule'!$H$20
B10: Exit equity proceeds | C10: =C8+C9
B11: Memo: surplus cash at exit (EXCLUDED from bridge per convention) | C11: ='Operating Model'!$H$25
B13: SPONSOR CASH FLOW SERIES (NO INTERIM DISTRIBUTIONS)
B14: Year | C14: 0 | D14: 1 | E14: 2 | F14: 3 | G14: 4 | H14: 5
B15: Sponsor cash flow | C15: =-'Sources & Uses'!$C$18 | D15: 0 | E15: 0 | F15: 0 | G15: 0 | H15: =C10
B17: HEADLINE OUTPUTS
B18: sponsor_irr | C18: =IRR(C15:H15) | D18: Sponsor IRR (annual, decimal)
B19: sponsor_moic | C19: =C10/'Sources & Uses'!$C$18 | D19: Exit equity proceeds / sponsor equity cheque
B20: exit_equity_proceeds | C20: =C10 | D20: Exit EV less debt outstanding at exit ($m)
B21: sponsor_equity_cheque | C21: ='Sources & Uses'!$C$18 | D21: Sources & uses balancing plug ($m)
B23: CHECKS
B24: IRR cross-check: MoIC^(1/5)-1 minus IRR (must be 0) | C24: =(C19^(1/Assumptions!$C$46)-1)-C18 | D24: =IF(ABS(C24)<0.000001,"OK","ERROR")
B25: Sources & uses balance (must be 0) | C25: ='Sources & Uses'!$C$19-'Sources & Uses'!$C$11 | D25: =IF(ABS(C25)<0.000001,"OK","ERROR")
B26: Exit debt equals face value at close (must be 0) | C26: ='Debt Schedule'!$H$20-'Sources & Uses'!$C$17 | D26: =IF(ABS(C26)<0.000001,"OK","ERROR")

Sheet Sensitivity
B1: SENSITIVITY — EXIT MULTIPLE x REVENUE GROWTH SHIFT
B2: Live formulas - growth shift applied uniformly to all five projection years - base case highlighted
B4: HELPER: YEAR-5 EBITDA AT UNIFORM GROWTH SHIFT ($m)
B5: Uniform shift to annual revenue growth | C5: -0.02 | D5: -0.01 | E5: 0 | F5: 0.01 | G5: 0.02
B6: Year-5 EBITDA (Year-5 margin held at plan) | C6: =Assumptions!$E$6*(1+Assumptions!$C$37+C$5)*(1+Assumptions!$D$37+C$5)*(1+Assumptions!$E$37+C$5)*(1+Assumptions!$F$37+C$5)*(1+Assumptions!$G$37+C$5)*Assumptions!$G$38 | D6: =Assumptions!$E$6*(1+Assumptions!$C$37+D$5)*(1+Assumptions!$D$37+D$5)*(1+Assumptions!$E$37+D$5)*(1+Assumptions!$F$37+D$5)*(1+Assumptions!$G$37+D$5)*Assumptions!$G$38 | E6: =Assumptions!$E$6*(1+Assumptions!$C$37+E$5)*(1+Assumptions!$D$37+E$5)*(1+Assumptions!$E$37+E$5)*(1+Assumptions!$F$37+E$5)*(1+Assumptions!$G$37+E$5)*Assumptions!$G$38 | F6: =Assumptions!$E$6*(1+Assumptions!$C$37+F$5)*(1+Assumptions!$D$37+F$5)*(1+Assumptions!$E$37+F$5)*(1+Assumptions!$F$37+F$5)*(1+Assumptions!$G$37+F$5)*Assumptions!$G$38 | G6: =Assumptions!$E$6*(1+Assumptions!$C$37+G$5)*(1+Assumptions!$D$37+G$5)*(1+Assumptions!$E$37+G$5)*(1+Assumptions!$F$37+G$5)*(1+Assumptions!$G$37+G$5)*Assumptions!$G$38
B8: SPONSOR MoIC (x)
B9: Exit EV/EBITDA (rows) vs growth shift (cols) | C9: =C$5 | D9: =D$5 | E9: =E$5 | F9: =F$5 | G9: =G$5
B10: 7 | C10: =($B10*C$6-'Debt Schedule'!$H$20)/'Sources & Uses'!$C$18 | D10: =($B10*D$6-'Debt Schedule'!$H$20)/'Sources & Uses'!$C$18 | E10: =($B10*E$6-'Debt Schedule'!$H$20)/'Sources & Uses'!$C$18 | F10: =($B10*F$6-'Debt Schedule'!$H$20)/'Sources & Uses'!$C$18 | G10: =($B10*G$6-'Debt Schedule'!$H$20)/'Sources & Uses'!$C$18
B11: 7.5 | C11: =($B11*C$6-'Debt Schedule'!$H$20)/'Sources & Uses'!$C$18 | D11: =($B11*D$6-'Debt Schedule'!$H$20)/'Sources & Uses'!$C$18 | E11: =($B11*E$6-'Debt Schedule'!$H$20)/'Sources & Uses'!$C$18 | F11: =($B11*F$6-'Debt Schedule'!$H$20)/'Sources & Uses'!$C$18 | G11: =($B11*G$6-'Debt Schedule'!$H$20)/'Sources & Uses'!$C$18
B12: 8 | C12: =($B12*C$6-'Debt Schedule'!$H$20)/'Sources & Uses'!$C$18 | D12: =($B12*D$6-'Debt Schedule'!$H$20)/'Sources & Uses'!$C$18 | E12: =($B12*E$6-'Debt Schedule'!$H$20)/'Sources & Uses'!$C$18 | F12: =($B12*F$6-'Debt Schedule'!$H$20)/'Sources & Uses'!$C$18 | G12: =($B12*G$6-'Debt Schedule'!$H$20)/'Sources & Uses'!$C$18
B13: 8.5 | C13: =($B13*C$6-'Debt Schedule'!$H$20)/'Sources & Uses'!$C$18 | D13: =($B13*D$6-'Debt Schedule'!$H$20)/'Sources & Uses'!$C$18 | E13: =($B13*E$6-'Debt Schedule'!$H$20)/'Sources & Uses'!$C$18 | F13: =($B13*F$6-'Debt Schedule'!$H$20)/'Sources & Uses'!$C$18 | G13: =($B13*G$6-'Debt Schedule'!$H$20)/'Sources & Uses'!$C$18
B14: 9 | C14: =($B14*C$6-'Debt Schedule'!$H$20)/'Sources & Uses'!$C$18 | D14: =($B14*D$6-'Debt Schedule'!$H$20)/'Sources & Uses'!$C$18 | E14: =($B14*E$6-'Debt Schedule'!$H$20)/'Sources & Uses'!$C$18 | F14: =($B14*F$6-'Debt Schedule'!$H$20)/'Sources & Uses'!$C$18 | G14: =($B14*G$6-'Debt Schedule'!$H$20)/'Sources & Uses'!$C$18
B15: 9.5 | C15: =($B15*C$6-'Debt Schedule'!$H$20)/'Sources & Uses'!$C$18 | D15: =($B15*D$6-'Debt Schedule'!$H$20)/'Sources & Uses'!$C$18 | E15: =($B15*E$6-'Debt Schedule'!$H$20)/'Sources & Uses'!$C$18 | F15: =($B15*F$6-'Debt Schedule'!$H$20)/'Sources & Uses'!$C$18 | G15: =($B15*G$6-'Debt Schedule'!$H$20)/'Sources & Uses'!$C$18
B16: 10 | C16: =($B16*C$6-'Debt Schedule'!$H$20)/'Sources & Uses'!$C$18 | D16: =($B16*D$6-'Debt Schedule'!$H$20)/'Sources & Uses'!$C$18 | E16: =($B16*E$6-'Debt Schedule'!$H$20)/'Sources & Uses'!$C$18 | F16: =($B16*F$6-'Debt Schedule'!$H$20)/'Sources & Uses'!$C$18 | G16: =($B16*G$6-'Debt Schedule'!$H$20)/'Sources & Uses'!$C$18
B17: 10.5 | C17: =($B17*C$6-'Debt Schedule'!$H$20)/'Sources & Uses'!$C$18 | D17: =($B17*D$6-'Debt Schedule'!$H$20)/'Sources & Uses'!$C$18 | E17: =($B17*E$6-'Debt Schedule'!$H$20)/'Sources & Uses'!$C$18 | F17: =($B17*F$6-'Debt Schedule'!$H$20)/'Sources & Uses'!$C$18 | G17: =($B17*G$6-'Debt Schedule'!$H$20)/'Sources & Uses'!$C$18
B18: 11 | C18: =($B18*C$6-'Debt Schedule'!$H$20)/'Sources & Uses'!$C$18 | D18: =($B18*D$6-'Debt Schedule'!$H$20)/'Sources & Uses'!$C$18 | E18: =($B18*E$6-'Debt Schedule'!$H$20)/'Sources & Uses'!$C$18 | F18: =($B18*F$6-'Debt Schedule'!$H$20)/'Sources & Uses'!$C$18 | G18: =($B18*G$6-'Debt Schedule'!$H$20)/'Sources & Uses'!$C$18
B20: SPONSOR IRR (%)
B21: Exit EV/EBITDA (rows) vs growth shift (cols) | C21: =C$5 | D21: =D$5 | E21: =E$5 | F21: =F$5 | G21: =G$5
B22: =$B10 | C22: =C10^(1/Assumptions!$C$46)-1 | D22: =D10^(1/Assumptions!$C$46)-1 | E22: =E10^(1/Assumptions!$C$46)-1 | F22: =F10^(1/Assumptions!$C$46)-1 | G22: =G10^(1/Assumptions!$C$46)-1
B23: =$B11 | C23: =C11^(1/Assumptions!$C$46)-1 | D23: =D11^(1/Assumptions!$C$46)-1 | E23: =E11^(1/Assumptions!$C$46)-1 | F23: =F11^(1/Assumptions!$C$46)-1 | G23: =G11^(1/Assumptions!$C$46)-1
B24: =$B12 | C24: =C12^(1/Assumptions!$C$46)-1 | D24: =D12^(1/Assumptions!$C$46)-1 | E24: =E12^(1/Assumptions!$C$46)-1 | F24: =F12^(1/Assumptions!$C$46)-1 | G24: =G12^(1/Assumptions!$C$46)-1
B25: =$B13 | C25: =C13^(1/Assumptions!$C$46)-1 | D25: =D13^(1/Assumptions!$C$46)-1 | E25: =E13^(1/Assumptions!$C$46)-1 | F25: =F13^(1/Assumptions!$C$46)-1 | G25: =G13^(1/Assumptions!$C$46)-1
B26: =$B14 | C26: =C14^(1/Assumptions!$C$46)-1 | D26: =D14^(1/Assumptions!$C$46)-1 | E26: =E14^(1/Assumptions!$C$46)-1 | F26: =F14^(1/Assumptions!$C$46)-1 | G26: =G14^(1/Assumptions!$C$46)-1
B27: =$B15 | C27: =C15^(1/Assumptions!$C$46)-1 | D27: =D15^(1/Assumptions!$C$46)-1 | E27: =E15^(1/Assumptions!$C$46)-1 | F27: =F15^(1/Assumptions!$C$46)-1 | G27: =G15^(1/Assumptions!$C$46)-1
B28: =$B16 | C28: =C16^(1/Assumptions!$C$46)-1 | D28: =D16^(1/Assumptions!$C$46)-1 | E28: =E16^(1/Assumptions!$C$46)-1 | F28: =F16^(1/Assumptions!$C$46)-1 | G28: =G16^(1/Assumptions!$C$46)-1
B29: =$B17 | C29: =C17^(1/Assumptions!$C$46)-1 | D29: =D17^(1/Assumptions!$C$46)-1 | E29: =E17^(1/Assumptions!$C$46)-1 | F29: =F17^(1/Assumptions!$C$46)-1 | G29: =G17^(1/Assumptions!$C$46)-1
B30: =$B18 | C30: =C18^(1/Assumptions!$C$46)-1 | D30: =D18^(1/Assumptions!$C$46)-1 | E30: =E18^(1/Assumptions!$C$46)-1 | F30: =F18^(1/Assumptions!$C$46)-1 | G30: =G18^(1/Assumptions!$C$46)-1
B33: CHECKS
B34: Base-case MoIC ties to Returns sheet (must be 0) | C34: =E14-Returns!$C$19 | D34: =IF(ABS(C34)<0.000001,"OK","ERROR")
B35: Base-case IRR ties to Returns sheet (must be 0) | C35: =E26-Returns!$C$18 | D35: =IF(ABS(C35)<0.000001,"OK","ERROR")
B36: IRR = MoIC^(1/5)-1 in closed form because the sponsor receives no interim distributions (single outflow at close, single inflow at exit).
