Workbook
Name scenario_index: 'Cover'!$C$17
Name revenue_growth_y1: 'Assumptions'!$I$6
Name revenue_growth_y2: 'Assumptions'!$I$7
Name revenue_growth_y3: 'Assumptions'!$I$8
Name revenue_growth_y4: 'Assumptions'!$I$9
Name revenue_growth_y5: 'Assumptions'!$I$10
Name ebitda_margin_y1: 'Assumptions'!$I$11
Name ebitda_margin_y2: 'Assumptions'!$I$12
Name ebitda_margin_y3: 'Assumptions'!$I$13
Name ebitda_margin_y4: 'Assumptions'!$I$14
Name ebitda_margin_y5: 'Assumptions'!$I$15
Name da_pct_revenue: 'Assumptions'!$I$16
Name capex_pct_revenue: 'Assumptions'!$I$17
Name nwc_pct_revenue_delta: 'Assumptions'!$I$18
Name risk_free_rate: 'Assumptions'!$I$19
Name equity_risk_premium: 'Assumptions'!$I$20
Name beta_levered: 'Assumptions'!$I$21
Name pretax_cost_of_debt: 'Assumptions'!$I$22
Name target_debt_weight: 'Assumptions'!$I$23
Name effective_tax_rate: 'Assumptions'!$I$24
Name terminal_growth_pct: 'Assumptions'!$I$25
Name exit_ev_ebitda_x: 'Assumptions'!$I$26
Name net_debt_assum: 'Assumptions'!$I$27
Name shares_outstanding_assum: 'Assumptions'!$I$28
Name current_price_assum: 'Assumptions'!$I$29
Name wacc_rate: 'WACCBuild'!$D$14
Name terminal_method_choice: 'Valuation'!$D$28
Name aif_leverage_cap_open: 'ComplianceCheck'!$D$7
Name aif_leverage_cap_closed: 'ComplianceCheck'!$D$8
Name aif_actual_leverage: 'ComplianceCheck'!$D$10
Name aif_largest_single_borrower_pct_nav: 'ComplianceCheck'!$D$13
Name aif_single_borrower_cap: 'ComplianceCheck'!$D$14
Name tax_ires_rate: 'ComplianceCheck'!$D$51
Name tax_irap_rate: 'ComplianceCheck'!$D$52
Name primary_output: 'Valuation'!$D$23
Name mc_vol: 'MonteCarlo'!$B$9
Name mf_spec_sha256: 'Reproducibility'!$B$5
Name mf_version: 'Reproducibility'!$B$6
Name mf_python_version: 'Reproducibility'!$B$7
Name mf_build_timestamp: 'Reproducibility'!$B$8
Name mf_spec_source: 'Reproducibility'!$B$9

Sheet RedFlags
A1: ModelForge Trust Layer — Red Flags
A2: Workbook: dcf_industrial.xlsx
A3: Template: dcf
A4: Rules run: 7 • FAIL: 0 WARN: 0 INFO: 0
A7: # | B7: Severity | C7: Rule | D7: Cell / Anchor | E7: Actual | F7: Expected | G7: Message | H7: Recommendation
B8: ALL CLEAR | C8: No plausibility violations triggered

Sheet Cover
A1: IndustrialCo (synthetic benchmark) — Benchmark DCF — Generic US Industrial (synthetic) | B1: DCF benchmark — industriale USA generico (sintetico)
A2: Strictly Private & Confidential · FINAL · v1.0
A4: Project code | B4: Codice progetto | C4: BM-DCF-001
A5: Analyst | B5: Analista | C5: Benchmark
A6: Valuation date | B6: Data valutazione | C6: 2026-01-01
A7: Version | B7: Versione | C7: v1.0
A8: Status | B8: Stato | C8: final
A9: Currency | B9: Valuta | C9: USD
A10: Units | B10: Unità | C10: millions
A11: Sign convention | B11: Convenzione di segno | C11: costs_negative
A12: Target | B12: Target | C12: IndustrialCo (synthetic benchmark)
A13: Sector | B13: Settore | C13: Diversified Industrials
A14: Country | B14: Paese | C14: US
A16: Scenario control | B16: Controllo scenari
A17: Active scenario | B17: Scenario attivo | C17: 2
A18: Scenario (resolved) | B18: Scenario (attivo) | C18: =CHOOSE(scenario_index,"Worst","Base","Best")
A20: Revision log | B20: Registro revisioni
A21: Version | B21: Date | C21: Analyst | D21: Note
A22: v1.0 | B22: 2026-01-01 | C22: Benchmark | D22: Frozen benchmark input — must match briefs/dcf_industrial.md exactly.
A25: Sheet index | B25: Indice fogli
A26: Sources
A27: Assumptions
A28: OperatingModel
A29: DebtSchedule
A30: Covenants
A31: Returns
A32: QC

Sheet Sources
A1: Sources
A2: Fonti
A3: Every hardcoded number in this model traces back to a row below. Comment on the cell shows the ID; look it up here.
A4: ID fonte | B4: Documento | C4: Pagina | D4: Editore | E4: Data | F4: URL | G4: Verificato | H4: Note
A5: Source ID | B5: Document | C5: Page | D5: Publisher | E5: Date | F5: URL | G5: Verified | H5: Note
A6: S-001 | B6: benchmarks/briefs/dcf_industrial.md | C6: 1 | D6: ModelForge public benchmark (synthetic deal brief) | E6: 2026-01-01 | G6: ✔ | H6: All operating, WACC and bridge inputs are defined in the frozen benchmark brief.

Sheet Assumptions
A1: Assumptions
A2: Ipotesi e driver
A3: Single source of truth. Every formula in the workbook reads the 'Active' column via named range. Change numbers here — nowhere else.
A5: ID | B5: Driver | C5: Description | D5: Descrizione | E5: Unit | F5: Worst | G5: Base | H5: Best | I5: Active | J5: Rationale | K5: Conf. | L5: Source
A6: A-101 | B6: revenue_growth_y1 | C6: Revenue growth Y1 | D6: Crescita ricavi A1 | E6: pct | F6: 0.04 | G6: 0.04 | H6: 0.04 | I6: =CHOOSE(scenario_index,F6,G6,H6) | J6: Frozen benchmark fade path per brief BM-DCF-001. | K6: H | L6: S-001
A7: A-102 | B7: revenue_growth_y2 | C7: Revenue growth Y2 | D7: Crescita ricavi A2 | E7: pct | F7: 0.035 | G7: 0.035 | H7: 0.035 | I7: =CHOOSE(scenario_index,F7,G7,H7) | J7: Frozen benchmark fade path per brief BM-DCF-001. | K7: H | L7: S-001
A8: A-103 | B8: revenue_growth_y3 | C8: Revenue growth Y3 | D8: Crescita ricavi A3 | E8: pct | F8: 0.03 | G8: 0.03 | H8: 0.03 | I8: =CHOOSE(scenario_index,F8,G8,H8) | J8: Frozen benchmark fade path per brief BM-DCF-001. | K8: H | L8: S-001
A9: A-104 | B9: revenue_growth_y4 | C9: Revenue growth Y4 | D9: Crescita ricavi A4 | E9: pct | F9: 0.025 | G9: 0.025 | H9: 0.025 | I9: =CHOOSE(scenario_index,F9,G9,H9) | J9: Frozen benchmark fade path per brief BM-DCF-001. | K9: H | L9: S-001
A10: A-105 | B10: revenue_growth_y5 | C10: Revenue growth Y5 | D10: Crescita ricavi A5 | E10: pct | F10: 0.02 | G10: 0.02 | H10: 0.02 | I10: =CHOOSE(scenario_index,F10,G10,H10) | J10: Frozen benchmark fade path per brief BM-DCF-001. | K10: H | L10: S-001
A11: A-201 | B11: ebitda_margin_y1 | C11: EBITDA margin Y1 | D11: Margine EBITDA A1 | E11: pct | F11: 0.18 | G11: 0.18 | H11: 0.18 | I11: =CHOOSE(scenario_index,F11,G11,H11) | J11: Frozen benchmark input per brief BM-DCF-001. | K11: H | L11: S-001
A12: A-202 | B12: ebitda_margin_y2 | C12: EBITDA margin Y2 | D12: Margine EBITDA A2 | E12: pct | F12: 0.18 | G12: 0.18 | H12: 0.18 | I12: =CHOOSE(scenario_index,F12,G12,H12) | J12: Frozen benchmark input per brief BM-DCF-001. | K12: H | L12: S-001
A13: A-203 | B13: ebitda_margin_y3 | C13: EBITDA margin Y3 | D13: Margine EBITDA A3 | E13: pct | F13: 0.18 | G13: 0.18 | H13: 0.18 | I13: =CHOOSE(scenario_index,F13,G13,H13) | J13: Frozen benchmark input per brief BM-DCF-001. | K13: H | L13: S-001
A14: A-204 | B14: ebitda_margin_y4 | C14: EBITDA margin Y4 | D14: Margine EBITDA A4 | E14: pct | F14: 0.18 | G14: 0.18 | H14: 0.18 | I14: =CHOOSE(scenario_index,F14,G14,H14) | J14: Frozen benchmark input per brief BM-DCF-001. | K14: H | L14: S-001
A15: A-205 | B15: ebitda_margin_y5 | C15: EBITDA margin Y5 | D15: Margine EBITDA A5 | E15: pct | F15: 0.18 | G15: 0.18 | H15: 0.18 | I15: =CHOOSE(scenario_index,F15,G15,H15) | J15: Frozen benchmark input per brief BM-DCF-001. | K15: H | L15: S-001
A16: A-301 | B16: da_pct_revenue | C16: D&A % revenue | D16: Ammortamenti % ricavi | E16: pct | F16: 0.06 | G16: 0.06 | H16: 0.06 | I16: =CHOOSE(scenario_index,F16,G16,H16) | J16: Frozen benchmark input per brief BM-DCF-001 (EBIT margin = 18% - 6% = 12%). | K16: H | L16: S-001
A17: A-302 | B17: capex_pct_revenue | C17: Capex % revenue | D17: Capex % ricavi | E17: pct | F17: 0.065 | G17: 0.065 | H17: 0.065 | I17: =CHOOSE(scenario_index,F17,G17,H17) | J17: Frozen benchmark input per brief BM-DCF-001. | K17: H | L17: S-001
... A29: A-503 | B29: current_price_assum | C29: Reference share price ($) | D29: Prezzo di riferimento ($) | E29: eur | F29: 8 | G29: 8 | H29: 8 | I29: =CHOOSE(scenario_index,F29,G29,H29) | J29: Frozen benchmark input per brief BM-DCF-001. | K29: H | L29: S-001

Sheet ComparableBetas
A1: Comparable Betas (none provided)
A2: Add wacc.comparable_betas to spec to enable Hamada unlever/relever

Sheet WACCBuild
A1: WACC Build | B1: Calcolo WACC
A2: Damodaran CRP methodology + Hamada beta (when comps present)
A5: Risk-free rate (10Y BTP) | B5: Tasso risk-free | D5: =risk_free_rate
A6: Equity risk premium (country) | B6: ERP paese | D6: =equity_risk_premium
A7: Beta (levered — input) | B7: Beta | D7: =beta_levered
A8: Cost of equity | B8: Costo del capitale | D8: =risk_free_rate+beta_levered*(equity_risk_premium)
A9: Pre-tax cost of debt | B9: Costo del debito pre-tax | D9: =pretax_cost_of_debt
A10: Effective tax rate | B10: Aliquota effettiva | D10: =effective_tax_rate
A11: After-tax cost of debt | B11: Costo del debito post-tax | D11: =pretax_cost_of_debt*(1-effective_tax_rate)
A12: Target D / (D+E) | B12: Target D / (D+E) | D12: =target_debt_weight
A13: Target E / (D+E) | B13: Target E / (D+E) | D13: =1-target_debt_weight
A14: WACC | B14: WACC | D14: =((risk_free_rate+beta_levered*(equity_risk_premium))*(1-target_debt_weight))+(pretax_cost_of_debt*(1-effective_tax_rate)*target_debt_weight)

Sheet FCFForecast
A1: FCF Forecast | B1: Previsione FCF
A2: Unlevered free cash flow to the firm
A3: ACTIVE SCENARIO → | B3: SCENARIO ATTIVO → | C3: =CHOOSE(scenario_index,"WORST","BASE","BEST")
D5: HY1 | E5: HY2 | F5: HY3 | G5: FY1 | H5: FY2 | I5: FY3 | J5: FY4 | K5: FY5
A6: Stub period: 365 days (full year) | Single-stage explicit (no fade)
A7: Revenue | B7: Ricavi | D7: 810 | E7: 900 | F7: 1000 | G7: =F7*(1+revenue_growth_y1) | H7: =G7*(1+revenue_growth_y2) | I7: =H7*(1+revenue_growth_y3) | J7: =I7*(1+revenue_growth_y4) | K7: =J7*(1+revenue_growth_y5)
A8: EBITDA | B8: EBITDA | D8: 180 | E8: 180 | F8: 180 | G8: =G7*ebitda_margin_y1 | H8: =H7*ebitda_margin_y2 | I8: =I7*ebitda_margin_y3 | J8: =J7*ebitda_margin_y4 | K8: =K7*ebitda_margin_y5
A9: D&A | B9: A&A | D9: =-D7*da_pct_revenue | E9: =-E7*da_pct_revenue | F9: =-F7*da_pct_revenue | G9: =-G7*da_pct_revenue | H9: =-H7*da_pct_revenue | I9: =-I7*da_pct_revenue | J9: =-J7*da_pct_revenue | K9: =-K7*da_pct_revenue
A10: EBIT | B10: EBIT | D10: =D8+D9 | E10: =E8+E9 | F10: =F8+F9 | G10: =G8+G9 | H10: =H8+H9 | I10: =I8+I9 | J10: =J8+J9 | K10: =K8+K9
A11: Tax on EBIT | B11: Imposte su EBIT | D11: =-MAX(D10*effective_tax_rate,0) | E11: =-MAX(E10*effective_tax_rate,0) | F11: =-MAX(F10*effective_tax_rate,0) | G11: =-MAX(G10*effective_tax_rate,0) | H11: =-MAX(H10*effective_tax_rate,0) | I11: =-MAX(I10*effective_tax_rate,0) | J11: =-MAX(J10*effective_tax_rate,0) | K11: =-MAX(K10*effective_tax_rate,0)
A12: NOPAT | B12: NOPAT | D12: =D10+D11 | E12: =E10+E11 | F12: =F10+F11 | G12: =G10+G11 | H12: =H10+H11 | I12: =I10+I11 | J12: =J10+J11 | K12: =K10+K11
A13: + D&A addback | B13: + A&A | D13: =-D9 | E13: =-E9 | F13: =-F9 | G13: =-G9 | H13: =-H9 | I13: =-I9 | J13: =-J9 | K13: =-K9
A14: Capex | B14: Capex | D14: =-D7*capex_pct_revenue | E14: =-E7*capex_pct_revenue | F14: =-F7*capex_pct_revenue | G14: =-G7*capex_pct_revenue | H14: =-H7*capex_pct_revenue | I14: =-I7*capex_pct_revenue | J14: =-J7*capex_pct_revenue | K14: =-K7*capex_pct_revenue
A15: Δ Working capital | B15: Δ Capitale circolante | D15: 0 | E15: =-(E7-D7)*nwc_pct_revenue_delta | F15: =-(F7-E7)*nwc_pct_revenue_delta | G15: =-(G7-F7)*nwc_pct_revenue_delta | H15: =-(H7-G7)*nwc_pct_revenue_delta | I15: =-(I7-H7)*nwc_pct_revenue_delta | J15: =-(J7-I7)*nwc_pct_revenue_delta | K15: =-(K7-J7)*nwc_pct_revenue_delta
A16: Unlevered FCF | B16: FCF unlevered | D16: =D12+D13+D14+D15 | E16: =E12+E13+E14+E15 | F16: =F12+F13+F14+F15 | G16: =G12+G13+G14+G15 | H16: =H12+H13+H14+H15 | I16: =I12+I13+I14+I15 | J16: =J12+J13+J14+J15 | K16: =K12+K13+K14+K15

Sheet Valuation
A1: Valuation | B1: Valutazione
A2: DCF Gordon / Exit Multiple — pick one via terminal_method_choice
A5: Explicit-period PV of FCF | B5: VAN FCF esplicito | D5: ='FCFForecast'!G16/(1+wacc_rate)^1.0+'FCFForecast'!H16/(1+wacc_rate)^2.0+'FCFForecast'!I16/(1+wacc_rate)^3.0+'FCFForecast'!J16/(1+wacc_rate)^4.0+'FCFForecast'!K16/(1+wacc_rate)^5.0
A6: Terminal year NOPAT (from explicit) | B6: NOPAT terminale | D6: ='FCFForecast'!K12
A7: Normalized terminal Δ NWC (grown at g) | B7: Δ CCN terminale normalizzato | D7: ='FCFForecast'!K15*(1+terminal_growth_pct)
A8: Normalized terminal FCF (capex = D&A steady state) | B8: FCF terminale normalizzato (capex = A&A) | D8: =D6+D7
A9: Terminal value — Gordon growth (normalized) | B9: Terminal value — Gordon (norm.) | D9: =D8*(1+terminal_growth_pct)/(wacc_rate-terminal_growth_pct)
A10: Terminal value — exit EV/EBITDA | B10: Terminal value — EV/EBITDA uscita | D10: ='FCFForecast'!K8*exit_ev_ebitda_x
A11: Implied g (closed-form) — terminal (from exit multiple) | B11: Implied g (forma chiusa) — terminale (da multiplo uscita) | D11: =(wacc_rate*D10-D8)/(D10+D8)
A12: Terminal value — chosen | B12: Terminal value — scelto | D12: =IF(terminal_method_choice=2,D10,D9)
A13: PV of terminal value | B13: VAN del terminal value | D13: =D12/(1+wacc_rate)^5.0
A14: Enterprise Value | B14: Enterprise Value | D14: =D5+D13
A15: (−) Net debt | B15: (−) Posizione finanziaria netta | D15: =-net_debt_assum
A16: (−) Minority interest | B16: (−) Interessenze di minoranza | D16: =-0
A17: (−) Pension deficit (unfunded) | B17: (−) Deficit pensionistico | D17: =-0
A18: (−) Preferred equity | B18: (−) Azioni privilegiate | D18: =-0
A19: (−) IFRS 16 lease liability | B19: (−) Passività leasing IFRS 16 | D19: =-0
A20: (+) Cross-holdings / investments at FV | B20: (+) Partecipazioni / investimenti | D20: =0
A21: Equity Value | B21: Valore equity | D21: =D14+D15+D16+D17+D18+D19+D20
A22: Implied EV / EBITDA (Y1 proj) | B22: EV/EBITDA implicito Y1 | D22: =D14/'FCFForecast'!G8
A23: Implied EV | B23: EV implicito | D23: =D14
A24: Implied price per share | B24: Prezzo implicito per azione | D24: =D21/shares_outstanding_assum
A25: Current price | B25: Prezzo attuale | D25: =current_price_assum
A26: Premium / (discount) % | B26: Premio / (sconto) % | D26: =D24/D25-1
A28: Terminal method choice (1=Gordon, 2=Exit) | B28: Metodo TV (1=Gordon, 2=Exit) | D28: 1

Sheet QC
A1: QC Checks
A2: Controlli
A4: ALL CHECKS PASS | C4: =IF(AND(C5=1,C6=1,C7=1),1,0)
A5: WACC positive | C5: =IF(wacc_rate>0,1,0)
A6: EV positive | C6: =IF('Valuation'!D14>0,1,0)
A7: Terminal g < WACC | C7: =IF(terminal_growth_pct<wacc_rate,1,0)

Sheet MOAT
A1: ModelForge MOAT — Live-Formula Verification
A2: Workbook: dcf_industrial.xlsx
A3: Core-output formula density: 93.0%
A4: Overall: PASS (4/4 gates)
A6: Gate | B6: Verdict | C6: Metric | D6: Threshold | E6: Detail
A7: formula_density | B7: PASS | C7: 0.9298 | D7: 0.9000 | E7: All core output sheets meet density threshold
A8: reference_graph | B8: PASS | C8: 0.00 | D8: 0.00 | E8: No magic-number literals in output formulas
A9: no_orphan_inputs | B9: PASS | C9: 0.00 | D9: 5.00 | E9: All defined names reachable from formulas (≤5 allowed)
A10: recalculation | B10: PASS | C10: 0.00 | D10: 0 | E10: All formula values reconcile (tol=1e-04)
A12: Per-sheet formula density
A13: Sheet | B13: Class | C13: Numeric cells | D13: Formula cells | E13: Formula % | F13: Magic-number cells
A14: RedFlags | B14: audit | C14: 0 | D14: 0 | E14: n/a | F14: 0
A15: Cover | B15: input | C15: 2 | D15: 1 | E15: 50.0% | F15: 0
A16: Sources | B16: input | C16: 1 | D16: 0 | E16: 0.0% | F16: 0
A17: Assumptions | B17: input | C17: 96 | D17: 24 | E17: 25.0% | F17: 0
A18: ComparableBetas | B18: reference | C18: 0 | D18: 0 | E18: n/a | F18: 0
A19: WACCBuild | B19: core_output | C19: 10 | D19: 10 | E19: 100.0% | F19: 0
A20: FCFForecast | B20: core_output | C20: 81 | D20: 74 | E20: 91.4% | F20: 0
A21: Valuation | B21: core_output | C21: 23 | D21: 22 | E21: 95.7% | F21: 0
A22: QC | B22: audit | C22: 4 | D22: 4 | E22: 100.0% | F22: 0
A23: ComplianceCheck | B23: audit | C23: 13 | D23: 5 | E23: 38.5% | F23: 0
A24: SensitivityAnalysis | B24: audit | C24: 129 | D24: 107 | E24: 82.9% | F24: 0
A25: MonteCarlo | B25: simulation | C25: 115 | D25: 15 | E25: 13.0% | F25: 0
A26: Reproducibility | B26: audit | C26: 1 | D26: 1 | E26: 100.0% | F26: 0

Sheet ComplianceCheck
A1: Compliance Check | B1: Controllo di conformità
A2: AIFMD II / IFRS 9 / Basel III-IV / GACS — Italian & EU regulatory plumbing
A5: AIFMD II leverage & concentration | B5: AIFMD II leva & concentrazione
A6: AIF type (open/closed) | B6: Tipo AIF | D6: closed
A7: AIFMD II leverage cap — open-ended | B7: Limite leva AIFMD II — aperto | D7: 1.75
A8: AIFMD II leverage cap — closed-ended | B8: Limite leva AIFMD II — chiuso | D8: 3
A9: AIFMD II leverage cap (applied) | B9: Limite AIFMD II (applicato) | D9: =IF($D$6="open",aif_leverage_cap_open,aif_leverage_cap_closed)
A10: Actual portfolio leverage | B10: Leva effettiva | D10: 1.5
A11: AIFMD II leverage compliance | D11: =IF(aif_actual_leverage<=$D$9,"PASS","FAIL")
A13: Largest single borrower % NAV | B13: Maggior debitore % NAV | D13: 0.15
A14: AIFMD II single-borrower cap | B14: Limite singolo debitore | D14: 0.2
A15: Single-borrower compliance | D15: =IF(aif_largest_single_borrower_pct_nav<=aif_single_borrower_cap,"PASS","FAIL")
A17: Loan-originating AIF status | B17: Classificazione AIF con origination
A18: Originated loans % NAV | B18: Prestiti originati % NAV | D18: 0.55
A19: Loan-originating AIF flag | D19: =IF($D$18>=0.50,"YES — closed-ended required if >60%","NO")
A21: IFRS 9 three-stage ECL | B21: IFRS 9 modello a tre stadi
A22: ECL formula (canonical): ECL = PD × LGD × EAD × DF | B22: Formula ECL: PD × LGD × EAD × Fattore sconto
A23: where PD = probability of default, LGD = loss given default, EAD = exposure at default, DF = discount factor
A25: Stage 1 (12-month ECL — no SICR) | B25: Stadio 1 (ECL 12m — no SICR) | D25: 12m PD × LGD × EAD × DF
A26: Stage 2 (Lifetime ECL — SICR triggered) | B26: Stadio 2 (ECL lifetime — SICR) | D26: Lifetime PD × LGD × EAD × DF | 30+DPD backstop
A27: Stage 3 (Lifetime ECL — credit-impaired) | B27: Stadio 3 (ECL lifetime — impaired) | D27: PD 100% × LGD × EAD × DF | interest on NET
A29: SICR triggers (document bank policy)
A30: • Absolute PD threshold breach
A31: • Relative PD doubling vs origination
A32: • Rating downgrade by ≥2 notches
A33: • Watchlist flag
A34: • Forbearance granted
A35: • 30+ days past due (DPD) presumption
A37: Basel NPL calendar provisioning | B37: Calendar provisioning NPL
A38: Regulation (EU) 2019/630 — NPL minimum coverage
A39: • Unsecured NPEs | B39: NPE non garantite | D39: 0% / 35% / 100% (Y1-2 / Y3 / Y3+)
A40: • NPEs secured by real estate | B40: NPE garantite da immobili | D40: 0% / 25% / 70% / 100% (Y1-4 / Y5 / Y7 / Y9+)
A41: • NPEs secured by other collateral | B41: NPE garantite altro | D41: 0% / 35% / 70% / 100% (Y1-2 / Y3 / Y4 / Y7+)
A44: GACS (Garanzia Cartolarizzazione Sofferenze) | B44: GACS — Garanzia stato su senior NPL
A45: • Senior tranche rating ≥ BBB- | B45: Rating senior ≥ investment grade | D45: BBB
A46: • Legge 130/1999 SPV (bankruptcy-remote) | B46: SPV legge 130/1999 | D46: YES (required)
A47: • Guarantee fee priced on IT financial CDS | B47: Fee garanzia su CDS finanziari italiani | D47: IT Italian financial-sector CDS basket (5Y)
A48: • Servicer fit-and-proper (Banca d'Italia) | B48: Servicer requisiti | D48: Required
A50: Italian tax — IRES + IRAP split | B50: Tassazione italiana — IRES + IRAP
A51: IRES rate | B51: Aliquota IRES | D51: 0.24
...

Sheet SensitivityAnalysis
A1: Sensitivity Analysis
A2: Analisi di sensibilità
A3: ACTIVE SCENARIO → | B3: SCENARIO ATTIVO → | C3: =CHOOSE(scenario_index,"WORST","BASE","BEST")
A4: LIVE — linear-elasticity approximation off primary_output. Recomputes when you change scenario_index or edit a driver/shock. Exact non-linear recompute via the `modelforge` CLI / dossier. | LIVE — approssimazione a elasticità lineare su primary_output. Si ricalcola quando cambi scenario_index o modifichi un driver/shock. Ricalcolo esatto non lineare tramite la CLI `modelforge` / dossier.
A5: Primary output | B5: Implied EV | D5: =primary_output
A6: Factors analyzed | D6: 7
J8: Method: LIVE elasticity formula (exact non-linear Δ via CLI/dossier)
A9: ID | B9: Factor | C9: Driver | D9: Base | E9: Low shk | F9: High shk | G9: Elast. | H9: Low value | I9: High value | J9: Low Δ | K9: High Δ
A10: F-001 | B10: Revenue growth Y1 ±20% | C10: revenue_growth_y1 | D10: =revenue_growth_y1 | E10: -0.2 | F10: 0.2 | G10: 0.8 | H10: =D10*(1+E10) | I10: =D10*(1+F10) | J10: =primary_output*E10*G10 | K10: =primary_output*F10*G10
A11: F-002 | B11: EBITDA margin Y1 ±25% | C11: ebitda_margin_y1 | D11: =ebitda_margin_y1 | E11: -0.25 | F11: 0.25 | G11: 0.9 | H11: =D11*(1+E11) | I11: =D11*(1+F11) | J11: =primary_output*E11*G11 | K11: =primary_output*F11*G11
A12: F-003 | B12: Capex % revenue ±20% | C12: capex_pct_revenue | D12: =capex_pct_revenue | E12: -0.2 | F12: 0.2 | G12: -0.4 | H12: =D12*(1+E12) | I12: =D12*(1+F12) | J12: =primary_output*E12*G12 | K12: =primary_output*F12*G12
A13: F-004 | B13: Terminal growth ±50bps | C13: terminal_growth_pct | D13: =terminal_growth_pct | E13: -0.5 | F13: 0.5 | G13: 0.45 | H13: =D13*(1+E13) | I13: =D13*(1+F13) | J13: =primary_output*E13*G13 | K13: =primary_output*F13*G13
A14: F-005 | B14: Exit EV/EBITDA ±1x | C14: exit_ev_ebitda_x | D14: =exit_ev_ebitda_x | E14: -0.15 | F14: 0.15 | G14: 0.7 | H14: =D14*(1+E14) | I14: =D14*(1+F14) | J14: =primary_output*E14*G14 | K14: =primary_output*F14*G14
A15: F-006 | B15: Beta ±0.10 | C15: beta_levered | D15: =beta_levered | E15: -0.15 | F15: 0.15 | G15: -0.25 | H15: =D15*(1+E15) | I15: =D15*(1+F15) | J15: =primary_output*E15*G15 | K15: =primary_output*F15*G15
A16: F-007 | B16: ERP ±100bps | C16: equity_risk_premium | D16: =equity_risk_premium | E16: -0.15 | F16: 0.15 | G16: -0.3 | H16: =D16*(1+E16) | I16: =D16*(1+F16) | J16: =primary_output*E16*G16 | K16: =primary_output*F16*G16
A19: 2D Data Table: WACC × Terminal g =TABLE(wacc_rate, terminal_growth_pct) (Gordon TV)
B21: WACC ↓ / g → | C21: =terminal_growth_pct+(-0.01) | D21: =terminal_growth_pct+(-0.005) | E21: =terminal_growth_pct+(0.0) | F21: =terminal_growth_pct+(0.005) | G21: =terminal_growth_pct+(0.01)
B22: =wacc_rate+(-0.02) | C22: ='FCFForecast'!G16/(1+(wacc_rate+(-0.02)))^1.0+'FCFForecast'!H16/(1+(wacc_rate+(-0.02)))^2.0+'FCFForecast'!I16/(1+(wacc_rate+(-0.02)))^3.0+'FCFForecast'!J16/(1+(wacc_rate+(-0.02)))^4.0+'FCFForecast'!K16/(1+(wacc_rate+(-0.02)))^5.0+'Valuation'!$D$8*(1+(terminal_growth_pct+(-0.01)))/((wacc_rate+(-0.02))-(terminal_growth_pct+(-0.01)))/(1+(wacc_rate+(-0.02)))^5.0 | D22: ='FCFForecast'!G16/(1+(wacc_rate+(-0.02)))^1.0+'FCFForecast'!H16/(1+(wacc_rate+(-0.02)))^2.0+'FCFForecast'!I16/(1+(wacc_rate+(-0.02)))^3.0+'FCFForecast'!J16/(1+(wacc_rate+(-0.02)))^4.0+'FCFForecast'!K16/(1+(wacc_rate+(-0.02)))^5.0+'Valuation'!$D$8*(1+(terminal_growth_pct+(-0.005)))/((wacc_rate+(-0.02))-(terminal_growth_pct+(-0.005)))/(1+(wacc_rate+(-0.02)))^5.0 | E22: ='FCFForecast'!G16/(1+(wacc_rate+(-0.02)))^1.0+'FCFForecast'!H16/(1+(wacc_rate+(-0.02)))^2.0+'FCFForecast'!I16/(1+(wacc_rate+(-0.02)))^3.0+'FCFForecast'!J16/(1+(wacc_rate+(-0.02)))^4.0+'FCFForecast'!K16/(1+(wacc_rate+(-0.02)))^5.0+'Valuation'!$D$8*(1+(terminal_growth_pct+(0.0)))/((wacc_rate+(-0.02))-(terminal_growth_pct+(0.0)))/(1+(wacc_rate+(-0.02)))^5.0 | F22: ='FCFForecast'!G16/(1+(wacc_rate+(-0.02)))^1.0+'FCFForecast'!H16/(1+(wacc_rate+(-0.02)))^2.0+'FCFForecast'!I16/(1+(wacc_rate+(-0.02)))^3.0+'FCFForecast'!J16/(1+(wacc_rate+(-0.02)))^4.0+'FCFForecast'!K16/(1+(wacc_rate+(-0.02)))^5.0+'Valuation'!$D$8*(1+(terminal_growth_pct+(0.005)))/((wacc_rate+(-0.02))-(terminal_growth_pct+(0.005)))/(1+(wacc_rate+(-0.02)))^5.0 | G22: ='FCFForecast'!G16/(1+(wacc_rate+(-0.02)))^1.0+'FCFForecast'!H16/(1+(wacc_rate+(-0.02)))^2.0+'FCFForecast'!I16/(1+(wacc_rate+(-0.02)))^3.0+'FCFForecast'!J16/(1+(wacc_rate+(-0.02)))^4.0+'FCFForecast'!K16/(1+(wacc_rate+(-0.02)))^5.0+'Valuation'!$D$8*(1+(terminal_growth_pct+(0.01)))/((wacc_rate+(-0.02))-(terminal_growth_pct+(0.01)))/(1+(wacc_rate+(-0.02)))^5.0
B23: =wacc_rate+(-0.01) | C23: ='FCFForecast'!G16/(1+(wacc_rate+(-0.01)))^1.0+'FCFForecast'!H16/(1+(wacc_rate+(-0.01)))^2.0+'FCFForecast'!I16/(1+(wacc_rate+(-0.01)))^3.0+'FCFForecast'!J16/(1+(wacc_rate+(-0.01)))^4.0+'FCFForecast'!K16/(1+(wacc_rate+(-0.01)))^5.0+'Valuation'!$D$8*(1+(terminal_growth_pct+(-0.01)))/((wacc_rate+(-0.01))-(terminal_growth_pct+(-0.01)))/(1+(wacc_rate+(-0.01)))^5.0 | D23: ='FCFForecast'!G16/(1+(wacc_rate+(-0.01)))^1.0+'FCFForecast'!H16/(1+(wacc_rate+(-0.01)))^2.0+'FCFForecast'!I16/(1+(wacc_rate+(-0.01)))^3.0+'FCFForecast'!J16/(1+(wacc_rate+(-0.01)))^4.0+'FCFForecast'!K16/(1+(wacc_rate+(-0.01)))^5.0+'Valuation'!$D$8*(1+(terminal_growth_pct+(-0.005)))/((wacc_rate+(-0.01))-(terminal_growth_pct+(-0.005)))/(1+(wacc_rate+(-0.01)))^5.0 | E23: ='FCFForecast'!G16/(1+(wacc_rate+(-0.01)))^1.0+'FCFForecast'!H16/(1+(wacc_rate+(-0.01)))^2.0+'FCFForecast'!I16/(1+(wacc_rate+(-0.01)))^3.0+'FCFForecast'!J16/(1+(wacc_rate+(-0.01)))^4.0+'FCFForecast'!K16/(1+(wacc_rate+(-0.01)))^5.0+'Valuation'!$D$8*(1+(terminal_growth_pct+(0.0)))/((wacc_rate+(-0.01))-(terminal_growth_pct+(0.0)))/(1+(wacc_rate+(-0.01)))^5.0 | F23: ='FCFForecast'!G16/(1+(wacc_rate+(-0.01)))^1.0+'FCFForecast'!H16/(1+(wacc_rate+(-0.01)))^2.0+'FCFForecast'!I16/(1+(wacc_rate+(-0.01)))^3.0+'FCFForecast'!J16/(1+(wacc_rate+(-0.01)))^4.0+'FCFForecast'!K16/(1+(wacc_rate+(-0.01)))^5.0+'Valuation'!$D$8*(1+(terminal_growth_pct+(0.005)))/((wacc_rate+(-0.01))-(terminal_growth_pct+(0.005)))/(1+(wacc_rate+(-0.01)))^5.0 | G23: ='FCFForecast'!G16/(1+(wacc_rate+(-0.01)))^1.0+'FCFForecast'!H16/(1+(wacc_rate+(-0.01)))^2.0+'FCFForecast'!I16/(1+(wacc_rate+(-0.01)))^3.0+'FCFForecast'!J16/(1+(wacc_rate+(-0.01)))^4.0+'FCFForecast'!K16/(1+(wacc_rate+(-0.01)))^5.0+'Valuation'!$D$8*(1+(terminal_growth_pct+(0.01)))/((wacc_rate+(-0.01))-(terminal_growth_pct+(0.01)))/(1+(wacc_rate+(-0.01)))^5.0
B24: =wacc_rate+(0.0) | C24: ='FCFForecast'!G16/(1+(wacc_rate+(0.0)))^1.0+'FCFForecast'!H16/(1+(wacc_rate+(0.0)))^2.0+'FCFForecast'!I16/(1+(wacc_rate+(0.0)))^3.0+'FCFForecast'!J16/(1+(wacc_rate+(0.0)))^4.0+'FCFForecast'!K16/(1+(wacc_rate+(0.0)))^5.0+'Valuation'!$D$8*(1+(terminal_growth_pct+(-0.01)))/((wacc_rate+(0.0))-(terminal_growth_pct+(-0.01)))/(1+(wacc_rate+(0.0)))^5.0 | D24: ='FCFForecast'!G16/(1+(wacc_rate+(0.0)))^1.0+'FCFForecast'!H16/(1+(wacc_rate+(0.0)))^2.0+'FCFForecast'!I16/(1+(wacc_rate+(0.0)))^3.0+'FCFForecast'!J16/(1+(wacc_rate+(0.0)))^4.0+'FCFForecast'!K16/(1+(wacc_rate+(0.0)))^5.0+'Valuation'!$D$8*(1+(terminal_growth_pct+(-0.005)))/((wacc_rate+(0.0))-(terminal_growth_pct+(-0.005)))/(1+(wacc_rate+(0.0)))^5.0 | E24: ='FCFForecast'!G16/(1+(wacc_rate+(0.0)))^1.0+'FCFForecast'!H16/(1+(wacc_rate+(0.0)))^2.0+'FCFForecast'!I16/(1+(wacc_rate+(0.0)))^3.0+'FCFForecast'!J16/(1+(wacc_rate+(0.0)))^4.0+'FCFForecast'!K16/(1+(wacc_rate+(0.0)))^5.0+'Valuation'!$D$8*(1+(terminal_growth_pct+(0.0)))/((wacc_rate+(0.0))-(terminal_growth_pct+(0.0)))/(1+(wacc_rate+(0.0)))^5.0 | F24: ='FCFForecast'!G16/(1+(wacc_rate+(0.0)))^1.0+'FCFForecast'!H16/(1+(wacc_rate+(0.0)))^2.0+'FCFForecast'!I16/(1+(wacc_rate+(0.0)))^3.0+'FCFForecast'!J16/(1+(wacc_rate+(0.0)))^4.0+'FCFForecast'!K16/(1+(wacc_rate+(0.0)))^5.0+'Valuation'!$D$8*(1+(terminal_growth_pct+(0.005)))/((wacc_rate+(0.0))-(terminal_growth_pct+(0.005)))/(1+(wacc_rate+(0.0)))^5.0 | G24: ='FCFForecast'!G16/(1+(wacc_rate+(0.0)))^1.0+'FCFForecast'!H16/(1+(wacc_rate+(0.0)))^2.0+'FCFForecast'!I16/(1+(wacc_rate+(0.0)))^3.0+'FCFForecast'!J16/(1+(wacc_rate+(0.0)))^4.0+'FCFForecast'!K16/(1+(wacc_rate+(0.0)))^5.0+'Valuation'!$D$8*(1+(terminal_growth_pct+(0.01)))/((wacc_rate+(0.0))-(terminal_growth_pct+(0.01)))/(1+(wacc_rate+(0.0)))^5.0
B25: =wacc_rate+(0.01) | C25: ='FCFForecast'!G16/(1+(wacc_rate+(0.01)))^1.0+'FCFForecast'!H16/(1+(wacc_rate+(0.01)))^2.0+'FCFForecast'!I16/(1+(wacc_rate+(0.01)))^3.0+'FCFForecast'!J16/(1+(wacc_rate+(0.01)))^4.0+'FCFForecast'!K16/(1+(wacc_rate+(0.01)))^5.0+'Valuation'!$D$8*(1+(terminal_growth_pct+(-0.01)))/((wacc_rate+(0.01))-(terminal_growth_pct+(-0.01)))/(1+(wacc_rate+(0.01)))^5.0 | D25: ='FCFForecast'!G16/(1+(wacc_rate+(0.01)))^1.0+'FCFForecast'!H16/(1+(wacc_rate+(0.01)))^2.0+'FCFForecast'!I16/(1+(wacc_rate+(0.01)))^3.0+'FCFForecast'!J16/(1+(wacc_rate+(0.01)))^4.0+'FCFForecast'!K16/(1+(wacc_rate+(0.01)))^5.0+'Valuation'!$D$8*(1+(terminal_growth_pct+(-0.005)))/((wacc_rate+(0.01))-(terminal_growth_pct+(-0.005)))/(1+(wacc_rate+(0.01)))^5.0 | E25: ='FCFForecast'!G16/(1+(wacc_rate+(0.01)))^1.0+'FCFForecast'!H16/(1+(wacc_rate+(0.01)))^2.0+'FCFForecast'!I16/(1+(wacc_rate+(0.01)))^3.0+'FCFForecast'!J16/(1+(wacc_rate+(0.01)))^4.0+'FCFForecast'!K16/(1+(wacc_rate+(0.01)))^5.0+'Valuation'!$D$8*(1+(terminal_growth_pct+(0.0)))/((wacc_rate+(0.01))-(terminal_growth_pct+(0.0)))/(1+(wacc_rate+(0.01)))^5.0 | F25: ='FCFForecast'!G16/(1+(wacc_rate+(0.01)))^1.0+'FCFForecast'!H16/(1+(wacc_rate+(0.01)))^2.0+'FCFForecast'!I16/(1+(wacc_rate+(0.01)))^3.0+'FCFForecast'!J16/(1+(wacc_rate+(0.01)))^4.0+'FCFForecast'!K16/(1+(wacc_rate+(0.01)))^5.0+'Valuation'!$D$8*(1+(terminal_growth_pct+(0.005)))/((wacc_rate+(0.01))-(terminal_growth_pct+(0.005)))/(1+(wacc_rate+(0.01)))^5.0 | G25: ='FCFForecast'!G16/(1+(wacc_rate+(0.01)))^1.0+'FCFForecast'!H16/(1+(wacc_rate+(0.01)))^2.0+'FCFForecast'!I16/(1+(wacc_rate+(0.01)))^3.0+'FCFForecast'!J16/(1+(wacc_rate+(0.01)))^4.0+'FCFForecast'!K16/(1+(wacc_rate+(0.01)))^5.0+'Valuation'!$D$8*(1+(terminal_growth_pct+(0.01)))/((wacc_rate+(0.01))-(terminal_growth_pct+(0.01)))/(1+(wacc_rate+(0.01)))^5.0
B26: =wacc_rate+(0.02) | C26: ='FCFForecast'!G16/(1+(wacc_rate+(0.02)))^1.0+'FCFForecast'!H16/(1+(wacc_rate+(0.02)))^2.0+'FCFForecast'!I16/(1+(wacc_rate+(0.02)))^3.0+'FCFForecast'!J16/(1+(wacc_rate+(0.02)))^4.0+'FCFForecast'!K16/(1+(wacc_rate+(0.02)))^5.0+'Valuation'!$D$8*(1+(terminal_growth_pct+(-0.01)))/((wacc_rate+(0.02))-(terminal_growth_pct+(-0.01)))/(1+(wacc_rate+(0.02)))^5.0 | D26: ='FCFForecast'!G16/(1+(wacc_rate+(0.02)))^1.0+'FCFForecast'!H16/(1+(wacc_rate+(0.02)))^2.0+'FCFForecast'!I16/(1+(wacc_rate+(0.02)))^3.0+'FCFForecast'!J16/(1+(wacc_rate+(0.02)))^4.0+'FCFForecast'!K16/(1+(wacc_rate+(0.02)))^5.0+'Valuation'!$D$8*(1+(terminal_growth_pct+(-0.005)))/((wacc_rate+(0.02))-(terminal_growth_pct+(-0.005)))/(1+(wacc_rate+(0.02)))^5.0 | E26: ='FCFForecast'!G16/(1+(wacc_rate+(0.02)))^1.0+'FCFForecast'!H16/(1+(wacc_rate+(0.02)))^2.0+'FCFForecast'!I16/(1+(wacc_rate+(0.02)))^3.0+'FCFForecast'!J16/(1+(wacc_rate+(0.02)))^4.0+'FCFForecast'!K16/(1+(wacc_rate+(0.02)))^5.0+'Valuation'!$D$8*(1+(terminal_growth_pct+(0.0)))/((wacc_rate+(0.02))-(terminal_growth_pct+(0.0)))/(1+(wacc_rate+(0.02)))^5.0 | F26: ='FCFForecast'!G16/(1+(wacc_rate+(0.02)))^1.0+'FCFForecast'!H16/(1+(wacc_rate+(0.02)))^2.0+'FCFForecast'!I16/(1+(wacc_rate+(0.02)))^3.0+'FCFForecast'!J16/(1+(wacc_rate+(0.02)))^4.0+'FCFForecast'!K16/(1+(wacc_rate+(0.02)))^5.0+'Valuation'!$D$8*(1+(terminal_growth_pct+(0.005)))/((wacc_rate+(0.02))-(terminal_growth_pct+(0.005)))/(1+(wacc_rate+(0.02)))^5.0 | G26: ='FCFForecast'!G16/(1+(wacc_rate+(0.02)))^1.0+'FCFForecast'!H16/(1+(wacc_rate+(0.02)))^2.0+'FCFForecast'!I16/(1+(wacc_rate+(0.02)))^3.0+'FCFForecast'!J16/(1+(wacc_rate+(0.02)))^4.0+'FCFForecast'!K16/(1+(wacc_rate+(0.02)))^5.0+'Valuation'!$D$8*(1+(terminal_growth_pct+(0.01)))/((wacc_rate+(0.02))-(terminal_growth_pct+(0.01)))/(1+(wacc_rate+(0.02)))^5.0
A30: 2D Data Table: WACC × Exit EV/EBITDA =TABLE(wacc_rate, exit_ev_ebitda_x) (Exit-multiple TV)
B32: WACC ↓ / exit × | C32: =exit_ev_ebitda_x+(-2.0) | D32: =exit_ev_ebitda_x+(-1.0) | E32: =exit_ev_ebitda_x+(0.0) | F32: =exit_ev_ebitda_x+(1.0) | G32: =exit_ev_ebitda_x+(2.0)
B33: =wacc_rate+(-0.02) | C33: ='FCFForecast'!G16/(1+(wacc_rate+(-0.02)))^1.0+'FCFForecast'!H16/(1+(wacc_rate+(-0.02)))^2.0+'FCFForecast'!I16/(1+(wacc_rate+(-0.02)))^3.0+'FCFForecast'!J16/(1+(wacc_rate+(-0.02)))^4.0+'FCFForecast'!K16/(1+(wacc_rate+(-0.02)))^5.0+'FCFForecast'!K8*(exit_ev_ebitda_x+(-2.0))/(1+(wacc_rate+(-0.02)))^5.0 | D33: ='FCFForecast'!G16/(1+(wacc_rate+(-0.02)))^1.0+'FCFForecast'!H16/(1+(wacc_rate+(-0.02)))^2.0+'FCFForecast'!I16/(1+(wacc_rate+(-0.02)))^3.0+'FCFForecast'!J16/(1+(wacc_rate+(-0.02)))^4.0+'FCFForecast'!K16/(1+(wacc_rate+(-0.02)))^5.0+'FCFForecast'!K8*(exit_ev_ebitda_x+(-1.0))/(1+(wacc_rate+(-0.02)))^5.0 | E33: ='FCFForecast'!G16/(1+(wacc_rate+(-0.02)))^1.0+'FCFForecast'!H16/(1+(wacc_rate+(-0.02)))^2.0+'FCFForecast'!I16/(1+(wacc_rate+(-0.02)))^3.0+'FCFForecast'!J16/(1+(wacc_rate+(-0.02)))^4.0+'FCFForecast'!K16/(1+(wacc_rate+(-0.02)))^5.0+'FCFForecast'!K8*(exit_ev_ebitda_x+(0.0))/(1+(wacc_rate+(-0.02)))^5.0 | F33: ='FCFForecast'!G16/(1+(wacc_rate+(-0.02)))^1.0+'FCFForecast'!H16/(1+(wacc_rate+(-0.02)))^2.0+'FCFForecast'!I16/(1+(wacc_rate+(-0.02)))^3.0+'FCFForecast'!J16/(1+(wacc_rate+(-0.02)))^4.0+'FCFForecast'!K16/(1+(wacc_rate+(-0.02)))^5.0+'FCFForecast'!K8*(exit_ev_ebitda_x+(1.0))/(1+(wacc_rate+(-0.02)))^5.0 | G33: ='FCFForecast'!G16/(1+(wacc_rate+(-0.02)))^1.0+'FCFForecast'!H16/(1+(wacc_rate+(-0.02)))^2.0+'FCFForecast'!I16/(1+(wacc_rate+(-0.02)))^3.0+'FCFForecast'!J16/(1+(wacc_rate+(-0.02)))^4.0+'FCFForecast'!K16/(1+(wacc_rate+(-0.02)))^5.0+'FCFForecast'!K8*(exit_ev_ebitda_x+(2.0))/(1+(wacc_rate+(-0.02)))^5.0
B34: =wacc_rate+(-0.01) | C34: ='FCFForecast'!G16/(1+(wacc_rate+(-0.01)))^1.0+'FCFForecast'!H16/(1+(wacc_rate+(-0.01)))^2.0+'FCFForecast'!I16/(1+(wacc_rate+(-0.01)))^3.0+'FCFForecast'!J16/(1+(wacc_rate+(-0.01)))^4.0+'FCFForecast'!K16/(1+(wacc_rate+(-0.01)))^5.0+'FCFForecast'!K8*(exit_ev_ebitda_x+(-2.0))/(1+(wacc_rate+(-0.01)))^5.0 | D34: ='FCFForecast'!G16/(1+(wacc_rate+(-0.01)))^1.0+'FCFForecast'!H16/(1+(wacc_rate+(-0.01)))^2.0+'FCFForecast'!I16/(1+(wacc_rate+(-0.01)))^3.0+'FCFForecast'!J16/(1+(wacc_rate+(-0.01)))^4.0+'FCFForecast'!K16/(1+(wacc_rate+(-0.01)))^5.0+'FCFForecast'!K8*(exit_ev_ebitda_x+(-1.0))/(1+(wacc_rate+(-0.01)))^5.0 | E34: ='FCFForecast'!G16/(1+(wacc_rate+(-0.01)))^1.0+'FCFForecast'!H16/(1+(wacc_rate+(-0.01)))^2.0+'FCFForecast'!I16/(1+(wacc_rate+(-0.01)))^3.0+'FCFForecast'!J16/(1+(wacc_rate+(-0.01)))^4.0+'FCFForecast'!K16/(1+(wacc_rate+(-0.01)))^5.0+'FCFForecast'!K8*(exit_ev_ebitda_x+(0.0))/(1+(wacc_rate+(-0.01)))^5.0 | F34: ='FCFForecast'!G16/(1+(wacc_rate+(-0.01)))^1.0+'FCFForecast'!H16/(1+(wacc_rate+(-0.01)))^2.0+'FCFForecast'!I16/(1+(wacc_rate+(-0.01)))^3.0+'FCFForecast'!J16/(1+(wacc_rate+(-0.01)))^4.0+'FCFForecast'!K16/(1+(wacc_rate+(-0.01)))^5.0+'FCFForecast'!K8*(exit_ev_ebitda_x+(1.0))/(1+(wacc_rate+(-0.01)))^5.0 | G34: ='FCFForecast'!G16/(1+(wacc_rate+(-0.01)))^1.0+'FCFForecast'!H16/(1+(wacc_rate+(-0.01)))^2.0+'FCFForecast'!I16/(1+(wacc_rate+(-0.01)))^3.0+'FCFForecast'!J16/(1+(wacc_rate+(-0.01)))^4.0+'FCFForecast'!K16/(1+(wacc_rate+(-0.01)))^5.0+'FCFForecast'!K8*(exit_ev_ebitda_x+(2.0))/(1+(wacc_rate+(-0.01)))^5.0
B35: =wacc_rate+(0.0) | C35: ='FCFForecast'!G16/(1+(wacc_rate+(0.0)))^1.0+'FCFForecast'!H16/(1+(wacc_rate+(0.0)))^2.0+'FCFForecast'!I16/(1+(wacc_rate+(0.0)))^3.0+'FCFForecast'!J16/(1+(wacc_rate+(0.0)))^4.0+'FCFForecast'!K16/(1+(wacc_rate+(0.0)))^5.0+'FCFForecast'!K8*(exit_ev_ebitda_x+(-2.0))/(1+(wacc_rate+(0.0)))^5.0 | D35: ='FCFForecast'!G16/(1+(wacc_rate+(0.0)))^1.0+'FCFForecast'!H16/(1+(wacc_rate+(0.0)))^2.0+'FCFForecast'!I16/(1+(wacc_rate+(0.0)))^3.0+'FCFForecast'!J16/(1+(wacc_rate+(0.0)))^4.0+'FCFForecast'!K16/(1+(wacc_rate+(0.0)))^5.0+'FCFForecast'!K8*(exit_ev_ebitda_x+(-1.0))/(1+(wacc_rate+(0.0)))^5.0 | E35: ='FCFForecast'!G16/(1+(wacc_rate+(0.0)))^1.0+'FCFForecast'!H16/(1+(wacc_rate+(0.0)))^2.0+'FCFForecast'!I16/(1+(wacc_rate+(0.0)))^3.0+'FCFForecast'!J16/(1+(wacc_rate+(0.0)))^4.0+'FCFForecast'!K16/(1+(wacc_rate+(0.0)))^5.0+'FCFForecast'!K8*(exit_ev_ebitda_x+(0.0))/(1+(wacc_rate+(0.0)))^5.0 | F35: ='FCFForecast'!G16/(1+(wacc_rate+(0.0)))^1.0+'FCFForecast'!H16/(1+(wacc_rate+(0.0)))^2.0+'FCFForecast'!I16/(1+(wacc_rate+(0.0)))^3.0+'FCFForecast'!J16/(1+(wacc_rate+(0.0)))^4.0+'FCFForecast'!K16/(1+(wacc_rate+(0.0)))^5.0+'FCFForecast'!K8*(exit_ev_ebitda_x+(1.0))/(1+(wacc_rate+(0.0)))^5.0 | G35: ='FCFForecast'!G16/(1+(wacc_rate+(0.0)))^1.0+'FCFForecast'!H16/(1+(wacc_rate+(0.0)))^2.0+'FCFForecast'!I16/(1+(wacc_rate+(0.0)))^3.0+'FCFForecast'!J16/(1+(wacc_rate+(0.0)))^4.0+'FCFForecast'!K16/(1+(wacc_rate+(0.0)))^5.0+'FCFForecast'!K8*(exit_ev_ebitda_x+(2.0))/(1+(wacc_rate+(0.0)))^5.0
B36: =wacc_rate+(0.01) | C36: ='FCFForecast'!G16/(1+(wacc_rate+(0.01)))^1.0+'FCFForecast'!H16/(1+(wacc_rate+(0.01)))^2.0+'FCFForecast'!I16/(1+(wacc_rate+(0.01)))^3.0+'FCFForecast'!J16/(1+(wacc_rate+(0.01)))^4.0+'FCFForecast'!K16/(1+(wacc_rate+(0.01)))^5.0+'FCFForecast'!K8*(exit_ev_ebitda_x+(-2.0))/(1+(wacc_rate+(0.01)))^5.0 | D36: ='FCFForecast'!G16/(1+(wacc_rate+(0.01)))^1.0+'FCFForecast'!H16/(1+(wacc_rate+(0.01)))^2.0+'FCFForecast'!I16/(1+(wacc_rate+(0.01)))^3.0+'FCFForecast'!J16/(1+(wacc_rate+(0.01)))^4.0+'FCFForecast'!K16/(1+(wacc_rate+(0.01)))^5.0+'FCFForecast'!K8*(exit_ev_ebitda_x+(-1.0))/(1+(wacc_rate+(0.01)))^5.0 | E36: ='FCFForecast'!G16/(1+(wacc_rate+(0.01)))^1.0+'FCFForecast'!H16/(1+(wacc_rate+(0.01)))^2.0+'FCFForecast'!I16/(1+(wacc_rate+(0.01)))^3.0+'FCFForecast'!J16/(1+(wacc_rate+(0.01)))^4.0+'FCFForecast'!K16/(1+(wacc_rate+(0.01)))^5.0+'FCFForecast'!K8*(exit_ev_ebitda_x+(0.0))/(1+(wacc_rate+(0.01)))^5.0 | F36: ='FCFForecast'!G16/(1+(wacc_rate+(0.01)))^1.0+'FCFForecast'!H16/(1+(wacc_rate+(0.01)))^2.0+'FCFForecast'!I16/(1+(wacc_rate+(0.01)))^3.0+'FCFForecast'!J16/(1+(wacc_rate+(0.01)))^4.0+'FCFForecast'!K16/(1+(wacc_rate+(0.01)))^5.0+'FCFForecast'!K8*(exit_ev_ebitda_x+(1.0))/(1+(wacc_rate+(0.01)))^5.0 | G36: ='FCFForecast'!G16/(1+(wacc_rate+(0.01)))^1.0+'FCFForecast'!H16/(1+(wacc_rate+(0.01)))^2.0+'FCFForecast'!I16/(1+(wacc_rate+(0.01)))^3.0+'FCFForecast'!J16/(1+(wacc_rate+(0.01)))^4.0+'FCFForecast'!K16/(1+(wacc_rate+(0.01)))^5.0+'FCFForecast'!K8*(exit_ev_ebitda_x+(2.0))/(1+(wacc_rate+(0.01)))^5.0
B37: =wacc_rate+(0.02) | C37: ='FCFForecast'!G16/(1+(wacc_rate+(0.02)))^1.0+'FCFForecast'!H16/(1+(wacc_rate+(0.02)))^2.0+'FCFForecast'!I16/(1+(wacc_rate+(0.02)))^3.0+'FCFForecast'!J16/(1+(wacc_rate+(0.02)))^4.0+'FCFForecast'!K16/(1+(wacc_rate+(0.02)))^5.0+'FCFForecast'!K8*(exit_ev_ebitda_x+(-2.0))/(1+(wacc_rate+(0.02)))^5.0 | D37: ='FCFForecast'!G16/(1+(wacc_rate+(0.02)))^1.0+'FCFForecast'!H16/(1+(wacc_rate+(0.02)))^2.0+'FCFForecast'!I16/(1+(wacc_rate+(0.02)))^3.0+'FCFForecast'!J16/(1+(wacc_rate+(0.02)))^4.0+'FCFForecast'!K16/(1+(wacc_rate+(0.02)))^5.0+'FCFForecast'!K8*(exit_ev_ebitda_x+(-1.0))/(1+(wacc_rate+(0.02)))^5.0 | E37: ='FCFForecast'!G16/(1+(wacc_rate+(0.02)))^1.0+'FCFForecast'!H16/(1+(wacc_rate+(0.02)))^2.0+'FCFForecast'!I16/(1+(wacc_rate+(0.02)))^3.0+'FCFForecast'!J16/(1+(wacc_rate+(0.02)))^4.0+'FCFForecast'!K16/(1+(wacc_rate+(0.02)))^5.0+'FCFForecast'!K8*(exit_ev_ebitda_x+(0.0))/(1+(wacc_rate+(0.02)))^5.0 | F37: ='FCFForecast'!G16/(1+(wacc_rate+(0.02)))^1.0+'FCFForecast'!H16/(1+(wacc_rate+(0.02)))^2.0+'FCFForecast'!I16/(1+(wacc_rate+(0.02)))^3.0+'FCFForecast'!J16/(1+(wacc_rate+(0.02)))^4.0+'FCFForecast'!K16/(1+(wacc_rate+(0.02)))^5.0+'FCFForecast'!K8*(exit_ev_ebitda_x+(1.0))/(1+(wacc_rate+(0.02)))^5.0 | G37: ='FCFForecast'!G16/(1+(wacc_rate+(0.02)))^1.0+'FCFForecast'!H16/(1+(wacc_rate+(0.02)))^2.0+'FCFForecast'!I16/(1+(wacc_rate+(0.02)))^3.0+'FCFForecast'!J16/(1+(wacc_rate+(0.02)))^4.0+'FCFForecast'!K16/(1+(wacc_rate+(0.02)))^5.0+'FCFForecast'!K8*(exit_ev_ebitda_x+(2.0))/(1+(wacc_rate+(0.02)))^5.0

Sheet MonteCarlo
A1: Monte Carlo Simulation
A2: Simulazione Monte Carlo
A3: ACTIVE SCENARIO → | B3: SCENARIO ATTIVO → | C3: =CHOOSE(scenario_index,"WORST","BASE","BEST")
A4: STATIC SNAPSHOT — computed at build time (seed/scenario fixed). Does NOT recompute when you change scenario_index or drivers. To refresh: rebuild from the spec. | ISTANTANEA STATICA — calcolata in fase di build (seed/scenario fissi). NON si ricalcola se modifichi scenario_index o i driver. Per aggiornare: ricostruisci dalla specifica.
A5: Base output | B5: Implied EV | C5: =primary_output
A6: 1,000-run triangular simulation on Implied EV. Method: exact shadow-engine recompute per draw. Δ mode: fractional (× base = absolute). Seed=20260417.
A8: PARAMETRIC (LIVE — normal approx) — P5/P50/P95/mean as live Excel formulas off primary_output and the mc_vol input. RECOMPUTES when you flip scenario_index or edit mc_vol. Distinct from the sampled histogram below, which is a build-time snapshot (exact resim via `modelforge monte-carlo`). | PARAMETRICO (LIVE — approssimazione normale) — P5/P50/P95/media come formule Excel live su primary_output e l'input mc_vol. Si RICALCOLA quando cambi scenario_index o modifichi mc_vol. Distinto dall'istogramma campionato sotto, che è un'istantanea di build (ri-simulazione esatta con `modelforge monte-carlo`).
A9: Volatility (σ, editable) | B9: 0.062770467
A10: Statistic | B10: Parametric (LIVE)
A11: Mean (LIVE) | B11: =primary_output
A12: P5 (LIVE) | B12: =primary_output*(1+NORM.S.INV(0.05)*mc_vol)
A13: P50 (LIVE) | B13: =primary_output*(1+NORM.S.INV(0.5)*mc_vol)
A14: P95 (LIVE) | B14: =primary_output*(1+NORM.S.INV(0.95)*mc_vol)
A16: SAMPLED (snapshot) — full 1,000-draw triangular distribution; frozen at build time, does NOT recompute on scenario flip (refresh: `modelforge monte-carlo`).
A17: Statistic | B17: Δ output (frac) | C17: Absolute output
A18: Mean | B18: 0.0064683095 | C18: =primary_output*(1+B18)
A19: Std | B19: 0.062770467 | C19: =primary_output*(1+B19)
A20: P5 | B20: -0.093609076 | C20: =primary_output*(1+B20)
A21: P25 | B21: -0.039296887 | C21: =primary_output*(1+B21)
A22: P50 (median) | B22: 0.0056570272 | C22: =primary_output*(1+B22)
A23: P75 | B23: 0.048215231 | C23: =primary_output*(1+B23)
A24: P95 | B24: 0.11135765 | C24: =primary_output*(1+B24)
A25: Min | B25: -0.16381253 | C25: =primary_output*(1+B25)
A26: Max | B26: 0.22160703 | C26: =primary_output*(1+B26)
A29: Histogram bins
A30: Bin low (Δ) | B30: Bin high (Δ) | C30: Count
A31: -0.16381253 | B31: -0.15096521 | C31: 2
A32: -0.15096521 | B32: -0.13811789 | C32: 3
A33: -0.13811789 | B33: -0.12527057 | C33: 6
A34: -0.12527057 | B34: -0.11242326 | C34: 15
A35: -0.11242326 | B35: -0.099575937 | C35: 16
A36: -0.099575937 | B36: -0.086728618 | C36: 30
A37: -0.086728618 | B37: -0.073881299 | C37: 40
A38: -0.073881299 | B38: -0.06103398 | C38: 31
A39: -0.06103398 | B39: -0.048186662 | C39: 57
A40: -0.048186662 | B40: -0.035339343 | C40: 68
A41: -0.035339343 | B41: -0.022492024 | C41: 56
A42: -0.022492024 | B42: -0.0096447049 | C42: 67
... A60: 0.20875972 | B60: 0.22160703 | C60: 1

Sheet Reproducibility
A1: Reproducibility
A2: Riproducibilità
A3: ACTIVE SCENARIO → | B3: SCENARIO ATTIVO → | C3: =CHOOSE(scenario_index,"WORST","BASE","BEST")
A4: Every workbook emitted by `modelforge build` carries this metadata. The spec SHA-256 is deterministic: two workbooks built from identical spec bytes will match. Use `modelforge verify <xlsx> --spec <yaml>` to confirm a workbook was built from a given spec.
A5: Spec SHA-256 | B5: 91d7bb87355830816341c62233fd156864bbac84931706e23f4ba8052bd88b47
A6: ModelForge version | B6: 0.1.0
A7: Python version | B7: 3.14.0
A8: Build timestamp (UTC) | B8: 2026-01-01T00:00:00+00:00
A9: Spec source | B9: C:\Users\lukep\Desktop\Projects AI\ModelForge\benchmarks\specs\dcf_industrial.yaml
A10: Host | B10: Windows 11
A11: Python impl | B11: CPython 3.14
