Workbook
Name FY0Rev: Assumptions!$C$5
Name NetDebt: Assumptions!$C$8
Name Shares: Assumptions!$C$9
Name RefPrice: Assumptions!$C$10
Name DA_Pct: Assumptions!$C$16
Name CapexPct: Assumptions!$C$17
Name NWCPct: Assumptions!$C$18
Name TaxRate: Assumptions!$C$19
Name TermGrowth: Assumptions!$C$27
Name WACC_Rate: WACC!$C$15

Sheet Summary
A1: IndustrialCo — DCF Valuation Summary (BM-DCF-001, USD m)
A2: Navigate: | B2: Summary | C2: DCF | D2: WACC | E2: Assumptions | F2: Sensitivity
A4: Headline Outputs
A5: Output | B5: Machine label | C5: Value | D5: Display
A6: Discount rate (WACC, decimal) | B6: wacc | C6: =WACC_Rate -> 0.0811875 | D6: =C6 -> 0.0811875
A7: Enterprise value ($m) | B7: enterprise_value | C7: =DCF!C37 -> 1509.9692
A8: Equity value ($m) | B8: equity_value | C8: =DCF!C40 -> 1259.9692
A9: Implied price per share ($) | B9: implied_price_per_share | C9: =DCF!C42 -> 8.3997944 | D9: =C9/RefPrice-1 -> 0.049974298
D10: vs $8.00 reference
A12: EV → Equity Bridge ($m)
A13: PV of explicit FCFF (Y1–Y5) | C13: =DCF!C35 -> 359.03626
A14: PV of terminal value | C14: =DCF!C36 -> 1150.9329 | D14: =DCF!C38 -> 0.76222279 | E14: of EV
A15: Enterprise value | C15: =C13+C14 -> 1509.9692
A16: Less: net debt | C16: =-NetDebt -> -250
A17: Equity value | C17: =C15+C16 -> 1259.9692
A18: Shares outstanding (m) | C18: =Shares -> 150
A19: Implied price per share | C19: =C17/C18 -> 8.3997944
A20: Reference share price | C20: =RefPrice -> 8
A21: Premium / (discount) | C21: =C19/C20-1 -> 0.049974298
A23: Key Assumptions
A24: WACC | C24: =WACC_Rate -> 0.0811875
A25: Terminal growth (g) | C25: =TermGrowth -> 0.02
A26: Tax rate | C26: =TaxRate -> 0.25
A27: FY0 revenue ($m) | C27: =FY0Rev -> 1000
A28: FY0 EBITDA margin | C28: =Assumptions!C6 -> 0.18
A30: Checks
A31: Check: Summary bridge = DCF equity value (= 0) | C31: =C17-DCF!C40 -> 0 | D31: =IF(ABS(C31)<0.000001,"OK","ERROR") -> OK
A32: Check: implied price ties Summary vs DCF (= 0) | C32: =C19-DCF!C42 -> 0 | D32: =IF(ABS(C32)<0.000001,"OK","ERROR") -> OK

Sheet DCF
A1: IndustrialCo — Enterprise DCF (USD m; end-of-year discounting)
A2: Navigate: | B2: Summary | C2: DCF | D2: WACC | E2: Assumptions | F2: Sensitivity
A4: USD millions | C4: FY0A | D4: FY1E | E4: FY2E | F4: FY3E | G4: FY4E | H4: FY5E
A5: Free Cash Flow to the Firm
A6: Revenue growth (% YoY) | D6: =Assumptions!C14 -> 0.04 | E6: =Assumptions!D14 -> 0.035 | F6: =Assumptions!E14 -> 0.03 | G6: =Assumptions!F14 -> 0.025 | H6: =Assumptions!G14 -> 0.02
A7: Revenue | C7: =FY0Rev -> 1000 | D7: =C7*(1+D6) -> 1040 | E7: =D7*(1+E6) -> 1076.4 | F7: =E7*(1+F6) -> 1108.692 | G7: =F7*(1+G6) -> 1136.4093 | H7: =G7*(1+H6) -> 1159.1375
A8: EBITDA margin | C8: =Assumptions!C6 -> 0.18 | D8: =Assumptions!C15 -> 0.18 | E8: =Assumptions!D15 -> 0.18 | F8: =Assumptions!E15 -> 0.18 | G8: =Assumptions!F15 -> 0.18 | H8: =Assumptions!G15 -> 0.18
A9: EBITDA | C9: =C7*C8 -> 180 | D9: =D7*D8 -> 187.2 | E9: =E7*E8 -> 193.752 | F9: =F7*F8 -> 199.56456 | G9: =G7*G8 -> 204.55367 | H9: =H7*H8 -> 208.64475
A10: Less: D&A (6.0% of revenue) | D10: =-D7*DA_Pct -> -62.4 | E10: =-E7*DA_Pct -> -64.584 | F10: =-F7*DA_Pct -> -66.52152 | G10: =-G7*DA_Pct -> -68.184558 | H10: =-H7*DA_Pct -> -69.548249
A11: EBIT | D11: =D9+D10 -> 124.8 | E11: =E9+E10 -> 129.168 | F11: =F9+F10 -> 133.04304 | G11: =G9+G10 -> 136.36912 | H11: =H9+H10 -> 139.0965
A12: EBIT margin | D12: =D11/D7 -> 0.12 | E12: =E11/E7 -> 0.12 | F12: =F11/F7 -> 0.12 | G12: =G11/G7 -> 0.12 | H12: =H11/H7 -> 0.12
A13: Less: cash taxes (25% × EBIT) | D13: =-D11*TaxRate -> -31.2 | E13: =-E11*TaxRate -> -32.292 | F13: =-F11*TaxRate -> -33.26076 | G13: =-G11*TaxRate -> -34.092279 | H13: =-H11*TaxRate -> -34.774125
A14: NOPAT | D14: =D11+D13 -> 93.6 | E14: =E11+E13 -> 96.876 | F14: =F11+F13 -> 99.78228 | G14: =G11+G13 -> 102.27684 | H14: =H11+H13 -> 104.32237
A15: Plus: D&A | D15: =-D10 -> 62.4 | E15: =-E10 -> 64.584 | F15: =-F10 -> 66.52152 | G15: =-G10 -> 68.184558 | H15: =-H10 -> 69.548249
A16: Less: capex (6.5% of revenue) | D16: =-D7*CapexPct -> -67.6 | E16: =-E7*CapexPct -> -69.966 | F16: =-F7*CapexPct -> -72.06498 | G16: =-G7*CapexPct -> -73.866604 | H16: =-H7*CapexPct -> -75.343937
A17: Less: increase in net working capital | D17: =-NWCPct*(D7-C7) -> -4 | E17: =-NWCPct*(E7-D7) -> -3.64 | F17: =-NWCPct*(F7-E7) -> -3.2292 | G17: =-NWCPct*(G7-F7) -> -2.77173 | H17: =-NWCPct*(H7-G7) -> -2.2728186
A18: Free cash flow to the firm (FCFF) | D18: =SUM(D14:D17) -> 84.4 | E18: =SUM(E14:E17) -> 87.854 | F18: =SUM(F14:F17) -> 91.00962 | G18: =SUM(G14:G17) -> 93.82306 | H18: =SUM(H14:H17) -> 96.253868
A20: Discount period (end-of-year) | D20: 1 | E20: =D20+1 -> 2 | F20: =E20+1 -> 3 | G20: =F20+1 -> 4 | H20: =G20+1 -> 5
A21: Discount factor @ WACC | D21: =1/(1+WACC_Rate)^D20 -> 0.92490895 | E21: =1/(1+WACC_Rate)^E20 -> 0.85545657 | F21: =1/(1+WACC_Rate)^F20 -> 0.79121945 | G21: =1/(1+WACC_Rate)^G20 -> 0.73180595 | H21: =1/(1+WACC_Rate)^H20 -> 0.67685388
A22: PV of FCFF | D22: =D18*D21 -> 78.062316 | E22: =E18*E21 -> 75.155282 | F22: =F18*F21 -> 72.008581 | G22: =G18*G21 -> 68.660274 | H22: =H18*H21 -> 65.149803
A24: Terminal Value — Gordon Growth on Normalized FCF
A25: NOPAT — Year 5 | C25: =H14 -> 104.32237
A26: ΔNWC — Year 5 | C26: =-H17 -> 2.2728186
A27: Terminal growth (g) | C27: =TermGrowth -> 0.02
A28: Normalized terminal FCF = NOPAT₅ − ΔNWC₅ × (1+g) | C28: =C25-C26*(1+C27) -> 102.0041
A29: Terminal value @ end of Year 5 = norm FCF × (1+g) / (WACC − g) | C29: =C28*(1+C27)/(WACC_Rate-C27) -> 1700.4156
A30: Discount factor — Year 5 | C30: =H21 -> 0.67685388
A31: PV of terminal value | C31: =C29*C30 -> 1150.9329
A32: Capex = D&A in perpetuity, so normalized FCF carries no capex/D&A wedge.
A34: Enterprise → Equity Value Bridge
A35: PV of explicit FCFF (Years 1–5) | C35: =SUM(D22:H22) -> 359.03626
A36: PV of terminal value | C36: =C31 -> 1150.9329
A37: Enterprise value | C37: =C35+C36 -> 1509.9692
A38: Terminal value as % of EV | C38: =C36/C37 -> 0.76222279
A39: Less: net debt | C39: =-NetDebt -> -250
A40: Equity value | C40: =C37+C39 -> 1259.9692
A41: Shares outstanding (m) | C41: =Shares -> 150
A42: Implied price per share | C42: =C40/C41 -> 8.3997944
A43: Reference share price | C43: =RefPrice -> 8
A44: Implied premium / (discount) to reference | C44: =C42/C43-1 -> 0.049974298
...

Sheet WACC
A1: IndustrialCo — WACC Build (CAPM)
A2: Navigate: | B2: Summary | C2: DCF | D2: WACC | E2: Assumptions | F2: Sensitivity
A4: WACC Build — component by component
A5: Risk-free rate (10Y UST) | C5: =Assumptions!C22 -> 0.0425
A6: Equity risk premium | C6: =Assumptions!C23 -> 0.05
A7: Beta (levered) | C7: =Assumptions!C24 -> 1.1
A8: Cost of equity (Ke = rf + β × ERP) | C8: =C5+C7*C6 -> 0.0975
A10: Pre-tax cost of debt | C10: =Assumptions!C25 -> 0.0575
A11: Tax rate | C11: =TaxRate -> 0.25
A12: After-tax cost of debt (Kd × (1 − t)) | C12: =C10*(1-C11) -> 0.043125
A13: Target D/(D+E) | C13: =Assumptions!C26 -> 0.3
A14: Implied E/(D+E) | C14: =1-C13 -> 0.7
A15: WACC = E/V × Ke + D/V × after-tax Kd | C15: =C14*C8+C13*C12 -> 0.0811875
A16: Check: WACC − stated 8.11875% (= 0) | C16: =C15-0.0811875 -> 0 | D16: =IF(ABS(C16)<0.0000001,"OK","ERROR") -> OK
A17: Plain CAPM per brief — no country/size premium, no alpha, no beta relevering.

Sheet Assumptions
A1: IndustrialCo — BM-DCF-001 — Assumptions & Drivers (USD m)
A2: Navigate: | B2: Summary | C2: DCF | D2: WACC | E2: Assumptions | F2: Sensitivity
A4: Target & Capitalization
A5: FY0 (last FY) revenue ($m) | C5: 1000
A6: FY0 EBITDA margin | C6: 0.18
A7: FY0 EBITDA ($m) | C7: =C5*C6 -> 180
A8: Net debt ($m) | C8: 250
A9: Shares outstanding (m) | C9: 150
A10: Reference share price ($) | C10: 8
A12: Operating Forecast Drivers (constant where single value)
A13: Per-year drivers | C13: Year 1 | D13: Year 2 | E13: Year 3 | F13: Year 4 | G13: Year 5
A14: Revenue growth (% YoY) | C14: 0.04 | D14: 0.035 | E14: 0.03 | F14: 0.025 | G14: 0.02
A15: EBITDA margin | C15: 0.18 | D15: 0.18 | E15: 0.18 | F15: 0.18 | G15: 0.18
A16: D&A (% of revenue) | C16: 0.06
A17: Capex (% of revenue) | C17: 0.065
A18: Change in NWC (% of YoY Δrevenue) | C18: 0.1
A19: Cash tax rate (on EBIT) | C19: 0.25
A20: All drivers apply identically to every projection year (per brief).
A21: WACC & Terminal Value Inputs (plain CAPM — final, no extra premia)
A22: Risk-free rate (10Y UST) | C22: 0.0425
A23: Equity risk premium | C23: 0.05
A24: Beta (levered) | C24: 1.1
A25: Pre-tax cost of debt | C25: 0.0575
A26: Target D/(D+E) | C26: 0.3
A27: Terminal growth (g) | C27: 0.02
A28: Note: g (2.0%) < risk-free (4.25%) < WACC — Gordon condition satisfied.

Sheet Sensitivity
A1: IndustrialCo — Sensitivity: WACC × Terminal Growth
A2: Navigate: | B2: Summary | C2: DCF | D2: WACC | E2: Assumptions | F2: Sensitivity
A4: Enterprise value ($m) — rows: WACC, columns: terminal growth g
B5: WACC \ g | C5: =E5-0.01 -> 0.01 | D5: =E5-0.005 -> 0.015 | E5: =TermGrowth -> 0.02 | F5: =E5+0.005 -> 0.025 | G5: =E5+0.01 -> 0.03
B6: =B8-0.01 -> 0.0711875 | C6: =DCF!$D$18/(1+$B6)^1+DCF!$E$18/(1+$B6)^2+DCF!$F$18/(1+$B6)^3+DCF!$G$18/(1+$B6)^4+DCF!$H$18/(1+$B6)^5+(DCF!$C$25-DCF!$C$26*(1+C$5))*(1+C$5)/(($B6-C$5)*(1+$B6)^5) -> 1563.0221 | D6: =DCF!$D$18/(1+$B6)^1+DCF!$E$18/(1+$B6)^2+DCF!$F$18/(1+$B6)^3+DCF!$G$18/(1+$B6)^4+DCF!$H$18/(1+$B6)^5+(DCF!$C$25-DCF!$C$26*(1+D$5))*(1+D$5)/(($B6-D$5)*(1+$B6)^5) -> 1675.5755 | E6: =DCF!$D$18/(1+$B6)^1+DCF!$E$18/(1+$B6)^2+DCF!$F$18/(1+$B6)^3+DCF!$G$18/(1+$B6)^4+DCF!$H$18/(1+$B6)^5+(DCF!$C$25-DCF!$C$26*(1+E$5))*(1+E$5)/(($B6-E$5)*(1+$B6)^5) -> 1810.1158 | F6: =DCF!$D$18/(1+$B6)^1+DCF!$E$18/(1+$B6)^2+DCF!$F$18/(1+$B6)^3+DCF!$G$18/(1+$B6)^4+DCF!$H$18/(1+$B6)^5+(DCF!$C$25-DCF!$C$26*(1+F$5))*(1+F$5)/(($B6-F$5)*(1+$B6)^5) -> 1973.7835 | G6: =DCF!$D$18/(1+$B6)^1+DCF!$E$18/(1+$B6)^2+DCF!$F$18/(1+$B6)^3+DCF!$G$18/(1+$B6)^4+DCF!$H$18/(1+$B6)^5+(DCF!$C$25-DCF!$C$26*(1+G$5))*(1+G$5)/(($B6-G$5)*(1+$B6)^5) -> 2177.1865
B7: =B8-0.005 -> 0.0761875 | C7: =DCF!$D$18/(1+$B7)^1+DCF!$E$18/(1+$B7)^2+DCF!$F$18/(1+$B7)^3+DCF!$G$18/(1+$B7)^4+DCF!$H$18/(1+$B7)^5+(DCF!$C$25-DCF!$C$26*(1+C$5))*(1+C$5)/(($B7-C$5)*(1+$B7)^5) -> 1442.4195 | D7: =DCF!$D$18/(1+$B7)^1+DCF!$E$18/(1+$B7)^2+DCF!$F$18/(1+$B7)^3+DCF!$G$18/(1+$B7)^4+DCF!$H$18/(1+$B7)^5+(DCF!$C$25-DCF!$C$26*(1+D$5))*(1+D$5)/(($B7-D$5)*(1+$B7)^5) -> 1536.195 | E7: =DCF!$D$18/(1+$B7)^1+DCF!$E$18/(1+$B7)^2+DCF!$F$18/(1+$B7)^3+DCF!$G$18/(1+$B7)^4+DCF!$H$18/(1+$B7)^5+(DCF!$C$25-DCF!$C$26*(1+E$5))*(1+E$5)/(($B7-E$5)*(1+$B7)^5) -> 1646.6589 | F7: =DCF!$D$18/(1+$B7)^1+DCF!$E$18/(1+$B7)^2+DCF!$F$18/(1+$B7)^3+DCF!$G$18/(1+$B7)^4+DCF!$H$18/(1+$B7)^5+(DCF!$C$25-DCF!$C$26*(1+F$5))*(1+F$5)/(($B7-F$5)*(1+$B7)^5) -> 1778.7015 | G7: =DCF!$D$18/(1+$B7)^1+DCF!$E$18/(1+$B7)^2+DCF!$F$18/(1+$B7)^3+DCF!$G$18/(1+$B7)^4+DCF!$H$18/(1+$B7)^5+(DCF!$C$25-DCF!$C$26*(1+G$5))*(1+G$5)/(($B7-G$5)*(1+$B7)^5) -> 1939.3308
B8: =WACC_Rate -> 0.0811875 | C8: =DCF!$D$18/(1+$B8)^1+DCF!$E$18/(1+$B8)^2+DCF!$F$18/(1+$B8)^3+DCF!$G$18/(1+$B8)^4+DCF!$H$18/(1+$B8)^5+(DCF!$C$25-DCF!$C$26*(1+C$5))*(1+C$5)/(($B8-C$5)*(1+$B8)^5) -> 1338.8126 | D8: =DCF!$D$18/(1+$B8)^1+DCF!$E$18/(1+$B8)^2+DCF!$F$18/(1+$B8)^3+DCF!$G$18/(1+$B8)^4+DCF!$H$18/(1+$B8)^5+(DCF!$C$25-DCF!$C$26*(1+D$5))*(1+D$5)/(($B8-D$5)*(1+$B8)^5) -> 1417.9266 | E8: =DCF!$D$18/(1+$B8)^1+DCF!$E$18/(1+$B8)^2+DCF!$F$18/(1+$B8)^3+DCF!$G$18/(1+$B8)^4+DCF!$H$18/(1+$B8)^5+(DCF!$C$25-DCF!$C$26*(1+E$5))*(1+E$5)/(($B8-E$5)*(1+$B8)^5) -> 1509.9692 | F8: =DCF!$D$18/(1+$B8)^1+DCF!$E$18/(1+$B8)^2+DCF!$F$18/(1+$B8)^3+DCF!$G$18/(1+$B8)^4+DCF!$H$18/(1+$B8)^5+(DCF!$C$25-DCF!$C$26*(1+F$5))*(1+F$5)/(($B8-F$5)*(1+$B8)^5) -> 1618.3917 | G8: =DCF!$D$18/(1+$B8)^1+DCF!$E$18/(1+$B8)^2+DCF!$F$18/(1+$B8)^3+DCF!$G$18/(1+$B8)^4+DCF!$H$18/(1+$B8)^5+(DCF!$C$25-DCF!$C$26*(1+G$5))*(1+G$5)/(($B8-G$5)*(1+$B8)^5) -> 1747.9941
B9: =B8+0.005 -> 0.0861875 | C9: =DCF!$D$18/(1+$B9)^1+DCF!$E$18/(1+$B9)^2+DCF!$F$18/(1+$B9)^3+DCF!$G$18/(1+$B9)^4+DCF!$H$18/(1+$B9)^5+(DCF!$C$25-DCF!$C$26*(1+C$5))*(1+C$5)/(($B9-C$5)*(1+$B9)^5) -> 1248.8536 | D9: =DCF!$D$18/(1+$B9)^1+DCF!$E$18/(1+$B9)^2+DCF!$F$18/(1+$B9)^3+DCF!$G$18/(1+$B9)^4+DCF!$H$18/(1+$B9)^5+(DCF!$C$25-DCF!$C$26*(1+D$5))*(1+D$5)/(($B9-D$5)*(1+$B9)^5) -> 1316.3202 | E9: =DCF!$D$18/(1+$B9)^1+DCF!$E$18/(1+$B9)^2+DCF!$F$18/(1+$B9)^3+DCF!$G$18/(1+$B9)^4+DCF!$H$18/(1+$B9)^5+(DCF!$C$25-DCF!$C$26*(1+E$5))*(1+E$5)/(($B9-E$5)*(1+$B9)^5) -> 1393.9788 | F9: =DCF!$D$18/(1+$B9)^1+DCF!$E$18/(1+$B9)^2+DCF!$F$18/(1+$B9)^3+DCF!$G$18/(1+$B9)^4+DCF!$H$18/(1+$B9)^5+(DCF!$C$25-DCF!$C$26*(1+F$5))*(1+F$5)/(($B9-F$5)*(1+$B9)^5) -> 1484.3281 | G9: =DCF!$D$18/(1+$B9)^1+DCF!$E$18/(1+$B9)^2+DCF!$F$18/(1+$B9)^3+DCF!$G$18/(1+$B9)^4+DCF!$H$18/(1+$B9)^5+(DCF!$C$25-DCF!$C$26*(1+G$5))*(1+G$5)/(($B9-G$5)*(1+$B9)^5) -> 1590.7561
B10: =B8+0.01 -> 0.0911875 | C10: =DCF!$D$18/(1+$B10)^1+DCF!$E$18/(1+$B10)^2+DCF!$F$18/(1+$B10)^3+DCF!$G$18/(1+$B10)^4+DCF!$H$18/(1+$B10)^5+(DCF!$C$25-DCF!$C$26*(1+C$5))*(1+C$5)/(($B10-C$5)*(1+$B10)^5) -> 1170.0199 | D10: =DCF!$D$18/(1+$B10)^1+DCF!$E$18/(1+$B10)^2+DCF!$F$18/(1+$B10)^3+DCF!$G$18/(1+$B10)^4+DCF!$H$18/(1+$B10)^5+(DCF!$C$25-DCF!$C$26*(1+D$5))*(1+D$5)/(($B10-D$5)*(1+$B10)^5) -> 1228.094 | E10: =DCF!$D$18/(1+$B10)^1+DCF!$E$18/(1+$B10)^2+DCF!$F$18/(1+$B10)^3+DCF!$G$18/(1+$B10)^4+DCF!$H$18/(1+$B10)^5+(DCF!$C$25-DCF!$C$26*(1+E$5))*(1+E$5)/(($B10-E$5)*(1+$B10)^5) -> 1294.325 | F10: =DCF!$D$18/(1+$B10)^1+DCF!$E$18/(1+$B10)^2+DCF!$F$18/(1+$B10)^3+DCF!$G$18/(1+$B10)^4+DCF!$H$18/(1+$B10)^5+(DCF!$C$25-DCF!$C$26*(1+F$5))*(1+F$5)/(($B10-F$5)*(1+$B10)^5) -> 1370.5615 | G10: =DCF!$D$18/(1+$B10)^1+DCF!$E$18/(1+$B10)^2+DCF!$F$18/(1+$B10)^3+DCF!$G$18/(1+$B10)^4+DCF!$H$18/(1+$B10)^5+(DCF!$C$25-DCF!$C$26*(1+G$5))*(1+G$5)/(($B10-G$5)*(1+$B10)^5) -> 1459.2562
A13: Implied price per share ($) — rows: WACC, columns: terminal growth g
B14: WACC \ g | C14: =C5 -> 0.01 | D14: =D5 -> 0.015 | E14: =E5 -> 0.02 | F14: =F5 -> 0.025 | G14: =G5 -> 0.03
B15: =B6 -> 0.0711875 | C15: =(C6-NetDebt)/Shares -> 8.7534804 | D15: =(D6-NetDebt)/Shares -> 9.5038366 | E15: =(E6-NetDebt)/Shares -> 10.400772 | F15: =(F6-NetDebt)/Shares -> 11.49189 | G15: =(G6-NetDebt)/Shares -> 12.84791
B16: =B7 -> 0.0761875 | C16: =(C7-NetDebt)/Shares -> 7.9494633 | D16: =(D7-NetDebt)/Shares -> 8.5746336 | E16: =(E7-NetDebt)/Shares -> 9.3110595 | F16: =(F7-NetDebt)/Shares -> 10.191343 | G16: =(G7-NetDebt)/Shares -> 11.262205
B17: =B8 -> 0.0811875 | C17: =(C8-NetDebt)/Shares -> 7.2587504 | D17: =(D8-NetDebt)/Shares -> 7.7861773 | E17: =(E8-NetDebt)/Shares -> 8.3997944 | F17: =(F8-NetDebt)/Shares -> 9.1226111 | G17: =(G8-NetDebt)/Shares -> 9.9866274
B18: =B9 -> 0.0861875 | C18: =(C9-NetDebt)/Shares -> 6.6590243 | D18: =(D9-NetDebt)/Shares -> 7.1088012 | E18: =(E9-NetDebt)/Shares -> 7.6265255 | F18: =(F9-NetDebt)/Shares -> 8.2288543 | G18: =(G9-NetDebt)/Shares -> 8.938374
B19: =B10 -> 0.0911875 | C19: =(C10-NetDebt)/Shares -> 6.1334657 | D19: =(D10-NetDebt)/Shares -> 6.5206266 | E19: =(E10-NetDebt)/Shares -> 6.9621667 | F19: =(F10-NetDebt)/Shares -> 7.4704098 | G19: =(G10-NetDebt)/Shares -> 8.0617082
A21: Checks
A22: Check: base-case cell = DCF enterprise value (= 0) | C22: =E8-DCF!C37 -> -2.2737368e-13 | D22: =IF(ABS(C22)<0.000001,"OK","ERROR") -> OK
A23: Check: base-case cell = DCF implied price (= 0) | C23: =E17-DCF!C42 -> -1.7763568e-15 | D23: =IF(ABS(C23)<0.000001,"OK","ERROR") -> OK
