Workbook

Sheet Summary
A1: IndustrialCo — DCF Valuation Summary (USD millions)
A2: Synthetic benchmark BM-DCF-001. Every figure below is a live link — no hardcoded outputs.
A4: HEADLINE OUTPUTS
A5: WACC (weighted average cost of capital) | B5: =WACC!$B$15 | C5: CAPM build — see the rate-build sheet
A6: Enterprise value | B6: =DCF!$D$33 | C6: PV of explicit FCFF + PV of terminal amount ($m)
A7: Equity value | B7: =DCF!$D$35 | C7: firm PV less net debt, the only bridge item ($m)
A8: Implied price per share | B8: =DCF!$D$37 | C8: vs reference of $8.00 — premium/(discount) below
A9: Premium / (discount) to reference price | B9: =DCF!$D$39
A11: MACHINE-READABLE HEADLINES (BRIEF §5 LABELS)
A12: wacc | B12: =WACC!$B$15 | C12: decimal
A13: enterprise_value | B13: =DCF!$D$33 | C13: $m
A14: equity_value | B14: =DCF!$D$35 | C14: $m
A15: implied_price_per_share | B15: =DCF!$D$37 | C15: $
A17: VALUE COMPOSITION
A18: PV of explicit FCFF (Years 1-5) | B18: =DCF!$D$31
A19: PV of terminal amount | B19: =DCF!$D$32
A20: Terminal share of total PV | B20: =DCF!$D$40
A21: Net debt | B21: =Assumptions!$B$8
A22: Shares outstanding (m) | B22: =Assumptions!$B$9
A24: Model checks status (from DCF sheet) | B24: =DCF!$D$46

Sheet Assumptions
A1: Assumptions & Sources — IndustrialCo DCF (benchmark BM-DCF-001)
A2: Every hardcoded input in the workbook lives on this sheet. USD millions unless noted. Source for all inputs: deal brief benchmarks/briefs/dcf_industrial.md (synthetic, frozen).
A4: TARGET & CAPITALIZATION (BRIEF §1)
A5: Last FY (FY0) revenue ($m) | B5: 1000 | H5: Brief §1
A6: Last FY (FY0) EBITDA ($m) | B6: 180 | H6: Brief §1 (18.0% margin)
A7: FY0 EBITDA margin — cross-check | B7: =B6/B5 | H7: Derived: FY0 EBITDA / FY0 revenue (brief states 18.0%)
A8: Net debt ($m) | B8: 250 | H8: Brief §1; §5 — the firm-to-shareholder bridge is net debt only
A9: Shares outstanding (m) | B9: 150 | H9: Brief §1
A10: Reference price ($ per sh.) | B10: 8 | H10: Brief §1 — premium/(discount) display only
A12: OPERATING DRIVERS — PROJECTION YEARS 1-5 (BRIEF §2)
C13: Year 1 | D13: Year 2 | E13: Year 3 | F13: Year 4 | G13: Year 5
A14: Revenue growth (%) | C14: 0.04 | D14: 0.035 | E14: 0.03 | F14: 0.025 | G14: 0.02 | H14: Brief §2 — revenue fade
A15: EBITDA margin (%) | C15: 0.18 | D15: 0.18 | E15: 0.18 | F15: 0.18 | G15: 0.18 | H15: Brief §2 — flat 18.0% throughout
A16: D&A (% of revenue) | B16: 0.06 | H16: Brief §2 — so EBIT margin = 12.0%
A17: Capex (% of revenue) | B17: 0.065 | H17: Brief §2
A18: Increase in NWC (% of Δ revenue) | B18: 0.1 | H18: Brief §2 — Year 1 Δ measured vs FY0 revenue of 1,000.0
A19: Cash tax rate (on EBIT) | B19: 0.25 | H19: Brief §2 — EBIT is positive every year
A21: DISCOUNT RATE & TERMINAL INPUTS (BRIEF §3-§4)
A22: Risk-free rate — 10Y UST | B22: 0.0425 | H22: Brief §3
A23: Equity risk premium | B23: 0.05 | H23: Brief §3
A24: Beta (levered) | B24: 1.1 | H24: Brief §3 — no relevering, no extra premia
A25: Pre-tax cost of debt | B25: 0.0575 | H25: Brief §3
A26: Target D/(D+E) | B26: 0.3 | H26: Brief §3
A27: Terminal growth (g) | B27: 0.02 | H27: Brief §4 — Gordon growth; g < risk-free < discount rate
A29: Conventions (Brief §4-§5): end-of-year discounting, t = 1..5, full first year, no mid-year convention, no stub. Terminal year normalization assumes capex = D&A in perpetuity. No minority interest, pension deficit, preferred, leases or cross-holdings.
A30: Downstream sheets contain no hardcoded numbers — they reference this sheet only.

Sheet WACC
A1: Discount Rate Build — CAPM (plain, per brief §3: no extra premia)
A2: Inputs link live from the Assumptions sheet; the output rate feeds the DCF and Sensitivity sheets.
A3: Risk-free rate (10Y UST) | B3: =Assumptions!$B$22
A4: Equity risk premium | B4: =Assumptions!$B$23
A5: Beta (levered) | B5: =Assumptions!$B$24
A6: Cost of equity (Ke = rf + β × ERP) | B6: =B3+B5*B4 | C6: i.e. 4.25% + 1.10 × 5.00%
A8: Pre-tax cost of debt | B8: =Assumptions!$B$25
A9: Cash tax rate | B9: =Assumptions!$B$19
A10: After-tax cost of debt (= Kd × (1 − t)) | B10: =B8*(1-B9)
A12: Target debt weight D/(D+E) | B12: =Assumptions!$B$26
A13: Implied equity weight E/(D+E) (= 1 − D/(D+E)) | B13: =1-B12
A15: WACC (weighted average cost of capital) | B15: =B13*B6+B12*B10 | C15: i.e. E/(D+E) × Ke + D/(D+E) × after-tax Kd
A17: Check: spread of discount rate over terminal g (> 0) | B17: =B15-Assumptions!$B$27
A18: Check: spread of risk-free over terminal g (> 0, brief §4) | B18: =Assumptions!$B$22-Assumptions!$B$27

Sheet DCF
A1: IndustrialCo — Unlevered DCF (FCFF method, USD millions)
A2: End-of-year discounting (t = 1..5, full first year); discount rate links live from the rate-build sheet.
C4: FY0 | D4: FY1 | E4: FY2 | F4: FY3 | G4: FY4 | H4: FY5
A5: Revenue growth | D5: =Assumptions!C14 | E5: =Assumptions!D14 | F5: =Assumptions!E14 | G5: =Assumptions!F14 | H5: =Assumptions!G14
A6: Revenue | C6: =Assumptions!$B$5 | D6: =C6*(1+D5) | E6: =D6*(1+E5) | F6: =E6*(1+F5) | G6: =F6*(1+G5) | H6: =G6*(1+H5)
A7: EBITDA margin | D7: =Assumptions!C15 | E7: =Assumptions!D15 | F7: =Assumptions!E15 | G7: =Assumptions!F15 | H7: =Assumptions!G15
A8: EBITDA | C8: =Assumptions!$B$6 | D8: =D6*D7 | E8: =E6*E7 | F8: =F6*F7 | G8: =G6*G7 | H8: =H6*H7
A9: Less: D&A (6.0% of revenue) | D9: =-D6*Assumptions!$B$16 | E9: =-E6*Assumptions!$B$16 | F9: =-F6*Assumptions!$B$16 | G9: =-G6*Assumptions!$B$16 | H9: =-H6*Assumptions!$B$16
A10: EBIT | D10: =D8+D9 | E10: =E8+E9 | F10: =F8+F9 | G10: =G8+G9 | H10: =H8+H9
A11: Less: cash taxes (25% of EBIT) | D11: =-D10*Assumptions!$B$19 | E11: =-E10*Assumptions!$B$19 | F11: =-F10*Assumptions!$B$19 | G11: =-G10*Assumptions!$B$19 | H11: =-H10*Assumptions!$B$19
A12: NOPAT | D12: =D10+D11 | E12: =E10+E11 | F12: =F10+F11 | G12: =G10+G11 | H12: =H10+H11
A13: Add: D&A | D13: =-D9 | E13: =-E9 | F13: =-F9 | G13: =-G9 | H13: =-H9
A14: Less: capex (6.5% of revenue) | D14: =-D6*Assumptions!$B$17 | E14: =-E6*Assumptions!$B$17 | F14: =-F6*Assumptions!$B$17 | G14: =-G6*Assumptions!$B$17 | H14: =-H6*Assumptions!$B$17
A15: Less: increase in NWC (10% of Δ revenue) | D15: =-(D6-C6)*Assumptions!$B$18 | E15: =-(E6-D6)*Assumptions!$B$18 | F15: =-(F6-E6)*Assumptions!$B$18 | G15: =-(G6-F6)*Assumptions!$B$18 | H15: =-(H6-G6)*Assumptions!$B$18
A16: FCFF — free cash flow to the firm | D16: =D12+D13+D14+D15 | E16: =E12+E13+E14+E15 | F16: =F12+F13+F14+F15 | G16: =G12+G13+G14+G15 | H16: =H12+H13+H14+H15
A18: Discount period t (end-of-year) | C18: =C6-C6 | D18: =C18+1 | E18: =D18+1 | F18: =E18+1 | G18: =F18+1 | H18: =G18+1
A19: Discount factor @ Kw | D19: =1/(1+WACC!$B$15)^D18 | E19: =1/(1+WACC!$B$15)^E18 | F19: =1/(1+WACC!$B$15)^F18 | G19: =1/(1+WACC!$B$15)^G18 | H19: =1/(1+WACC!$B$15)^H18
A20: PV of FCFF | D20: =D16*D19 | E20: =E16*E19 | F20: =F16*F19 | G20: =G16*G19 | H20: =H16*H19
A22: TERMINAL VALUE (GORDON GROWTH ON NORMALIZED FCF — BRIEF §4)
A23: Terminal growth (g) | D23: =Assumptions!$B$27
A24: NOPAT — Year 5 | D24: =H12
A25: Less: Year-5 increase in NWC, grown at (1 + g) | D25: =H15*(1+D23)
A26: Normalized terminal FCF (capex = D&A in perpetuity) | D26: =D24+D25
A27: Terminal value (Gordon: FCF × (1+g) ÷ (Kw − g)) | D27: =D26*(1+D23)/(WACC!$B$15-D23)
A28: PV of terminal value (× Year-5 discount factor) | D28: =D27*H19
A30: VALUATION BRIDGE (FIRM → SHAREHOLDERS)
A31: PV of explicit FCFF (Years 1-5) | D31: =SUM(D20:H20)
A32: PV of terminal value | D32: =D28
A33: Enterprise value | D33: =D31+D32
A34: Less: net debt | D34: =-Assumptions!$B$8
A35: Equity value | D35: =D33+D34
A36: Shares outstanding (m) | D36: =Assumptions!$B$9
A37: Implied price per share | D37: =D35/D36
A38: Reference price ($ per sh.) | D38: =Assumptions!$B$10
A39: Premium / (discount) to reference | D39: =D37/D38-1
A40: Terminal share of total PV | D40: =D32/D33
A42: CHECKS
A43: Check 1: sum of PV(FCFF) minus NPV(Kw, Y1-Y5) = 0 | D43: =D31-NPV(WACC!$B$15,D16:H16)
A44: Check 2: valuation bridge foots to zero | D44: =D33+D34-D35
A45: Check 3: spread of Kw over g (must be > 0) | D45: =WACC!$B$15-D23
...

Sheet Sensitivity
A1: Sensitivity Analysis — discount rate (rows) × terminal growth (columns)
A2: Each cell re-derives the full DCF: NPV of Years 1-5 FCFF plus Gordon terminal amount — all live formulas.
A3: Enterprise value ($m) — sensitivity; base case → | B3: =DCF!$D$33
B5: Kw \ g | C5: =DCF!$D$23-0.01 | D5: =DCF!$D$23-0.005 | E5: =DCF!$D$23 | F5: =DCF!$D$23+0.005 | G5: =DCF!$D$23+0.01
B6: =WACC!$B$15-0.01 | C6: =NPV($B6,DCF!$D$16:$H$16)+(DCF!$H$12+DCF!$H$15*(1+C$5))*(1+C$5)/($B6-C$5)/(1+$B6)^5 | D6: =NPV($B6,DCF!$D$16:$H$16)+(DCF!$H$12+DCF!$H$15*(1+D$5))*(1+D$5)/($B6-D$5)/(1+$B6)^5 | E6: =NPV($B6,DCF!$D$16:$H$16)+(DCF!$H$12+DCF!$H$15*(1+E$5))*(1+E$5)/($B6-E$5)/(1+$B6)^5 | F6: =NPV($B6,DCF!$D$16:$H$16)+(DCF!$H$12+DCF!$H$15*(1+F$5))*(1+F$5)/($B6-F$5)/(1+$B6)^5 | G6: =NPV($B6,DCF!$D$16:$H$16)+(DCF!$H$12+DCF!$H$15*(1+G$5))*(1+G$5)/($B6-G$5)/(1+$B6)^5
B7: =WACC!$B$15-0.005 | C7: =NPV($B7,DCF!$D$16:$H$16)+(DCF!$H$12+DCF!$H$15*(1+C$5))*(1+C$5)/($B7-C$5)/(1+$B7)^5 | D7: =NPV($B7,DCF!$D$16:$H$16)+(DCF!$H$12+DCF!$H$15*(1+D$5))*(1+D$5)/($B7-D$5)/(1+$B7)^5 | E7: =NPV($B7,DCF!$D$16:$H$16)+(DCF!$H$12+DCF!$H$15*(1+E$5))*(1+E$5)/($B7-E$5)/(1+$B7)^5 | F7: =NPV($B7,DCF!$D$16:$H$16)+(DCF!$H$12+DCF!$H$15*(1+F$5))*(1+F$5)/($B7-F$5)/(1+$B7)^5 | G7: =NPV($B7,DCF!$D$16:$H$16)+(DCF!$H$12+DCF!$H$15*(1+G$5))*(1+G$5)/($B7-G$5)/(1+$B7)^5
B8: =WACC!$B$15 | C8: =NPV($B8,DCF!$D$16:$H$16)+(DCF!$H$12+DCF!$H$15*(1+C$5))*(1+C$5)/($B8-C$5)/(1+$B8)^5 | D8: =NPV($B8,DCF!$D$16:$H$16)+(DCF!$H$12+DCF!$H$15*(1+D$5))*(1+D$5)/($B8-D$5)/(1+$B8)^5 | E8: =NPV($B8,DCF!$D$16:$H$16)+(DCF!$H$12+DCF!$H$15*(1+E$5))*(1+E$5)/($B8-E$5)/(1+$B8)^5 | F8: =NPV($B8,DCF!$D$16:$H$16)+(DCF!$H$12+DCF!$H$15*(1+F$5))*(1+F$5)/($B8-F$5)/(1+$B8)^5 | G8: =NPV($B8,DCF!$D$16:$H$16)+(DCF!$H$12+DCF!$H$15*(1+G$5))*(1+G$5)/($B8-G$5)/(1+$B8)^5
B9: =WACC!$B$15+0.005 | C9: =NPV($B9,DCF!$D$16:$H$16)+(DCF!$H$12+DCF!$H$15*(1+C$5))*(1+C$5)/($B9-C$5)/(1+$B9)^5 | D9: =NPV($B9,DCF!$D$16:$H$16)+(DCF!$H$12+DCF!$H$15*(1+D$5))*(1+D$5)/($B9-D$5)/(1+$B9)^5 | E9: =NPV($B9,DCF!$D$16:$H$16)+(DCF!$H$12+DCF!$H$15*(1+E$5))*(1+E$5)/($B9-E$5)/(1+$B9)^5 | F9: =NPV($B9,DCF!$D$16:$H$16)+(DCF!$H$12+DCF!$H$15*(1+F$5))*(1+F$5)/($B9-F$5)/(1+$B9)^5 | G9: =NPV($B9,DCF!$D$16:$H$16)+(DCF!$H$12+DCF!$H$15*(1+G$5))*(1+G$5)/($B9-G$5)/(1+$B9)^5
B10: =WACC!$B$15+0.01 | C10: =NPV($B10,DCF!$D$16:$H$16)+(DCF!$H$12+DCF!$H$15*(1+C$5))*(1+C$5)/($B10-C$5)/(1+$B10)^5 | D10: =NPV($B10,DCF!$D$16:$H$16)+(DCF!$H$12+DCF!$H$15*(1+D$5))*(1+D$5)/($B10-D$5)/(1+$B10)^5 | E10: =NPV($B10,DCF!$D$16:$H$16)+(DCF!$H$12+DCF!$H$15*(1+E$5))*(1+E$5)/($B10-E$5)/(1+$B10)^5 | F10: =NPV($B10,DCF!$D$16:$H$16)+(DCF!$H$12+DCF!$H$15*(1+F$5))*(1+F$5)/($B10-F$5)/(1+$B10)^5 | G10: =NPV($B10,DCF!$D$16:$H$16)+(DCF!$H$12+DCF!$H$15*(1+G$5))*(1+G$5)/($B10-G$5)/(1+$B10)^5
A12: Check: grid center equals base case (difference) | C12: =E8-DCF!$D$33
A14: Implied price per share ($) — sensitivity; base case → | B14: =DCF!$D$37
B16: Kw \ g | C16: =C5 | D16: =D5 | E16: =E5 | F16: =F5 | G16: =G5
B17: =B6 | C17: =(C6-Assumptions!$B$8)/Assumptions!$B$9 | D17: =(D6-Assumptions!$B$8)/Assumptions!$B$9 | E17: =(E6-Assumptions!$B$8)/Assumptions!$B$9 | F17: =(F6-Assumptions!$B$8)/Assumptions!$B$9 | G17: =(G6-Assumptions!$B$8)/Assumptions!$B$9
B18: =B7 | C18: =(C7-Assumptions!$B$8)/Assumptions!$B$9 | D18: =(D7-Assumptions!$B$8)/Assumptions!$B$9 | E18: =(E7-Assumptions!$B$8)/Assumptions!$B$9 | F18: =(F7-Assumptions!$B$8)/Assumptions!$B$9 | G18: =(G7-Assumptions!$B$8)/Assumptions!$B$9
B19: =B8 | C19: =(C8-Assumptions!$B$8)/Assumptions!$B$9 | D19: =(D8-Assumptions!$B$8)/Assumptions!$B$9 | E19: =(E8-Assumptions!$B$8)/Assumptions!$B$9 | F19: =(F8-Assumptions!$B$8)/Assumptions!$B$9 | G19: =(G8-Assumptions!$B$8)/Assumptions!$B$9
B20: =B9 | C20: =(C9-Assumptions!$B$8)/Assumptions!$B$9 | D20: =(D9-Assumptions!$B$8)/Assumptions!$B$9 | E20: =(E9-Assumptions!$B$8)/Assumptions!$B$9 | F20: =(F9-Assumptions!$B$8)/Assumptions!$B$9 | G20: =(G9-Assumptions!$B$8)/Assumptions!$B$9
B21: =B10 | C21: =(C10-Assumptions!$B$8)/Assumptions!$B$9 | D21: =(D10-Assumptions!$B$8)/Assumptions!$B$9 | E21: =(E10-Assumptions!$B$8)/Assumptions!$B$9 | F21: =(F10-Assumptions!$B$8)/Assumptions!$B$9 | G21: =(G10-Assumptions!$B$8)/Assumptions!$B$9
A23: Check: grid center equals base case (difference) | C23: =E19-DCF!$D$37
