Workbook
Name scenario_index: 'Cover'!$C$17
Name revenue_growth_y1: 'Assumptions'!$I$6
Name revenue_growth_y2: 'Assumptions'!$I$7
Name revenue_growth_y3: 'Assumptions'!$I$8
Name revenue_growth_y4: 'Assumptions'!$I$9
Name revenue_growth_y5: 'Assumptions'!$I$10
Name revenue_growth_y6: 'Assumptions'!$I$11
Name revenue_growth_y7: 'Assumptions'!$I$12
Name ebitda_margin_y1: 'Assumptions'!$I$13
Name ebitda_margin_y2: 'Assumptions'!$I$14
Name ebitda_margin_y3: 'Assumptions'!$I$15
Name ebitda_margin_y4: 'Assumptions'!$I$16
Name ebitda_margin_y5: 'Assumptions'!$I$17
Name ebitda_margin_y6: 'Assumptions'!$I$18
Name ebitda_margin_y7: 'Assumptions'!$I$19
Name da_pct_revenue: 'Assumptions'!$I$20
Name maintenance_capex_pct_revenue: 'Assumptions'!$I$21
Name growth_capex_pct_revenue: 'Assumptions'!$I$22
Name nwc_pct_revenue_delta: 'Assumptions'!$I$23
Name effective_tax_rate: 'Assumptions'!$I$24
Name senior_tl_amount: 'Assumptions'!$I$25
Name senior_tl_margin_bps: 'Assumptions'!$I$26
Name senior_tl_floor: 'Assumptions'!$I$27
Name senior_tl_arrangement_fee: 'Assumptions'!$I$28
Name senior_tl_commitment_fee: 'Assumptions'!$I$29
Name senior_tl_oid: 'Assumptions'!$I$30
Name sofr_rate: 'Assumptions'!$I$31
Name mezz_amount: 'Assumptions'!$I$32
Name mezz_margin_bps: 'Assumptions'!$I$33
Name mezz_floor: 'Assumptions'!$I$34
Name mezz_arrangement_fee: 'Assumptions'!$I$35
Name mezz_commitment_fee: 'Assumptions'!$I$36
Name mezz_oid: 'Assumptions'!$I$37
Name sofr_rate_mezz: 'Assumptions'!$I$38
Name leverage_threshold_y1: 'Assumptions'!$I$39
Name leverage_threshold_y2: 'Assumptions'!$I$40
Name leverage_threshold_y3: 'Assumptions'!$I$41
Name leverage_threshold_y4: 'Assumptions'!$I$42
Name leverage_threshold_y5: 'Assumptions'!$I$43
Name leverage_threshold_y6: 'Assumptions'!$I$44
Name leverage_threshold_y7: 'Assumptions'!$I$45
Name icr_threshold_y1: 'Assumptions'!$I$46
Name icr_threshold_y2: 'Assumptions'!$I$47
Name icr_threshold_y3: 'Assumptions'!$I$48
Name icr_threshold_y4: 'Assumptions'!$I$49
Name icr_threshold_y5: 'Assumptions'!$I$50
Name icr_threshold_y6: 'Assumptions'!$I$51
Name icr_threshold_y7: 'Assumptions'!$I$52
Name legal_fees_eur_m: 'Assumptions'!$I$53
Name advisory_fees_eur_m: 'Assumptions'!$I$54
Name other_fees_eur_m: 'Assumptions'!$I$55
Name expected_hold_years: 'Assumptions'!$I$56
Name make_whole_pct: 'Assumptions'!$I$57
Name purchase_price_eur_m: 'SourcesUses'!$D$31
Name earnout_discount_pct: 'SourcesUses'!$D$64
Name recap_target_leverage: 'SourcesUses'!$D$70
Name recap_sponsor_share_pct: 'SourcesUses'!$D$71
Name exit_year_input: 'SourcesUses'!$D$74
Name pik_coupon_pct: 'SourcesUses'!$D$114
Name historical_ebitda_lfy: 'SourcesUses'!$Z$1

Sheet RedFlags
A1: ModelForge Trust Layer — Red Flags
A2: Workbook: lbo_us_saas.xlsx
A3: Template: sponsor_lbo
A4: Rules run: 3 • FAIL: 0 WARN: 0 INFO: 0
A7: # | B7: Severity | C7: Rule | D7: Cell / Anchor | E7: Actual | F7: Expected | G7: Message | H7: Recommendation
B8: ALL CLEAR | C8: No plausibility violations triggered

Sheet Cover
A1: SaaSCo (synthetic benchmark) — Benchmark Sponsor LBO — Generic US Enterprise SaaS (synthetic) | B1: LBO sponsor benchmark — SaaS enterprise USA generico (sintetico)
A2: Strictly Private & Confidential · FINAL · v1.0
A4: Project code | B4: Codice progetto | C4: BM-LBO-001
A5: Analyst | B5: Analista | C5: Benchmark
A6: Valuation date | B6: Data valutazione | C6: 2026-01-01
A7: Version | B7: Versione | C7: v1.0
A8: Status | B8: Stato | C8: final
A9: Currency | B9: Valuta | C9: USD
A10: Units | B10: Unità | C10: millions
A11: Sign convention | B11: Convenzione di segno | C11: costs_negative
A12: Target | B12: Target | C12: SaaSCo (synthetic benchmark)
A13: Sector | B13: Settore | C13: Enterprise SaaS
A14: Country | B14: Paese | C14: US
A16: Scenario control | B16: Controllo scenari
A17: Active scenario | B17: Scenario attivo | C17: 2
A18: Scenario (resolved) | B18: Scenario (attivo) | C18: =CHOOSE(scenario_index,"Worst","Base","Best")
A20: Revision log | B20: Registro revisioni
A21: Version | B21: Date | C21: Analyst | D21: Note
A22: v1.0 | B22: 2026-01-01 | C22: Benchmark | D22: Frozen benchmark input — must match briefs/lbo_us_saas.md exactly.
A25: Sheet index | B25: Indice fogli
A26: Sources
A27: Assumptions
A28: OperatingModel
A29: DebtSchedule
A30: Covenants
A31: Returns
A32: QC

Sheet Sources
A1: Sources
A2: Fonti
A3: Every hardcoded number in this model traces back to a row below. Comment on the cell shows the ID; look it up here.
A4: ID fonte | B4: Documento | C4: Pagina | D4: Editore | E4: Data | F4: URL | G4: Verificato | H4: Note
A5: Source ID | B5: Document | C5: Page | D5: Publisher | E5: Date | F5: URL | G5: Verified | H5: Note
A6: S-001 | B6: benchmarks/briefs/lbo_us_saas.md | C6: 1 | D6: ModelForge public benchmark (synthetic deal brief) | E6: 2026-01-01 | G6: ✔ | H6: All purchase-price, debt, operating and exit inputs are defined in the frozen benchmark brief.

Sheet Assumptions
A1: Assumptions
A2: Ipotesi e driver
A3: Single source of truth. Every formula in the workbook reads the 'Active' column via named range. Change numbers here — nowhere else.
A5: ID | B5: Driver | C5: Description | D5: Descrizione | E5: Unit | F5: Worst | G5: Base | H5: Best | I5: Active | J5: Rationale | K5: Conf. | L5: Source
A6: A-001 | B6: revenue_growth_y1 | C6: Revenue growth Y1 | D6: Crescita ricavi A1 | E6: pct | F6: 0.12 | G6: 0.12 | H6: 0.12 | I6: =CHOOSE(scenario_index,F6,G6,H6) | J6: Frozen benchmark input per brief BM-LBO-001. | K6: H | L6: S-001
A7: A-002 | B7: revenue_growth_y2 | C7: Revenue growth Y2 | D7: Crescita ricavi A2 | E7: pct | F7: 0.11 | G7: 0.11 | H7: 0.11 | I7: =CHOOSE(scenario_index,F7,G7,H7) | J7: Frozen benchmark input per brief BM-LBO-001. | K7: H | L7: S-001
A8: A-003 | B8: revenue_growth_y3 | C8: Revenue growth Y3 | D8: Crescita ricavi A3 | E8: pct | F8: 0.1 | G8: 0.1 | H8: 0.1 | I8: =CHOOSE(scenario_index,F8,G8,H8) | J8: Frozen benchmark input per brief BM-LBO-001. | K8: H | L8: S-001
A9: A-004 | B9: revenue_growth_y4 | C9: Revenue growth Y4 | D9: Crescita ricavi A4 | E9: pct | F9: 0.09 | G9: 0.09 | H9: 0.09 | I9: =CHOOSE(scenario_index,F9,G9,H9) | J9: Frozen benchmark input per brief BM-LBO-001. | K9: H | L9: S-001
A10: A-005 | B10: revenue_growth_y5 | C10: Revenue growth Y5 | D10: Crescita ricavi A5 | E10: pct | F10: 0.08 | G10: 0.08 | H10: 0.08 | I10: =CHOOSE(scenario_index,F10,G10,H10) | J10: Frozen benchmark input per brief BM-LBO-001. | K10: H | L10: S-001
A11: A-006 | B11: revenue_growth_y6 | C11: Revenue growth Y6 | D11: Crescita ricavi A6 | E11: pct | F11: 0.07 | G11: 0.07 | H11: 0.07 | I11: =CHOOSE(scenario_index,F11,G11,H11) | J11: Post-hold convergence (display only — exit at year 5). | K11: M | L11: S-001
A12: A-007 | B12: revenue_growth_y7 | C12: Revenue growth Y7 | D12: Crescita ricavi A7 | E12: pct | F12: 0.06 | G12: 0.06 | H12: 0.06 | I12: =CHOOSE(scenario_index,F12,G12,H12) | J12: Post-hold convergence (display only — exit at year 5). | K12: M | L12: S-001
A13: A-011 | B13: ebitda_margin_y1 | C13: EBITDA margin Y1 | D13: Margine EBITDA A1 | E13: pct | F13: 0.35 | G13: 0.35 | H13: 0.35 | I13: =CHOOSE(scenario_index,F13,G13,H13) | J13: Frozen benchmark input per brief BM-LBO-001. | K13: H | L13: S-001
A14: A-012 | B14: ebitda_margin_y2 | C14: EBITDA margin Y2 | D14: Margine EBITDA A2 | E14: pct | F14: 0.36 | G14: 0.36 | H14: 0.36 | I14: =CHOOSE(scenario_index,F14,G14,H14) | J14: Frozen benchmark input per brief BM-LBO-001. | K14: H | L14: S-001
A15: A-013 | B15: ebitda_margin_y3 | C15: EBITDA margin Y3 | D15: Margine EBITDA A3 | E15: pct | F15: 0.36 | G15: 0.36 | H15: 0.36 | I15: =CHOOSE(scenario_index,F15,G15,H15) | J15: Frozen benchmark input per brief BM-LBO-001. | K15: H | L15: S-001
A16: A-014 | B16: ebitda_margin_y4 | C16: EBITDA margin Y4 | D16: Margine EBITDA A4 | E16: pct | F16: 0.37 | G16: 0.37 | H16: 0.37 | I16: =CHOOSE(scenario_index,F16,G16,H16) | J16: Frozen benchmark input per brief BM-LBO-001. | K16: H | L16: S-001
A17: A-015 | B17: ebitda_margin_y5 | C17: EBITDA margin Y5 | D17: Margine EBITDA A5 | E17: pct | F17: 0.38 | G17: 0.38 | H17: 0.38 | I17: =CHOOSE(scenario_index,F17,G17,H17) | J17: Frozen benchmark input per brief BM-LBO-001. | K17: H | L17: S-001
... A57: A-081 | B57: make_whole_pct | C57: Make-whole premium % | D57: Make-whole % | E57: pct | F57: 0 | G57: 0 | H57: 0 | I57: =CHOOSE(scenario_index,F57,G57,H57) | J57: Not exercised — sponsor exits at year 5 per brief BM-LBO-001. | K57: H | L57: S-001

Sheet OperatingModel
A1: Operating Model | B1: Modello operativo
A2: USD millions · sign: costs_negative
A3: ACTIVE SCENARIO → | B3: SCENARIO ATTIVO → | C3: =CHOOSE(scenario_index,"WORST","BASE","BEST")
C5: Unit | D5: A 2023 | E5: A 2024 | F5: A 2025 | G5: E 2026 | H5: E 2027 | I5: E 2028 | J5: E 2029 | K5: E 2030 | L5: E 2031 | M5: E 2032
A7: Revenue build | B7: Costruzione ricavi
A8: Revenue growth % | B8: Crescita ricavi % | C8: % | E8: =IFERROR($E$9/$D$9-1,0) | F8: =IFERROR($F$9/$E$9-1,0) | G8: =revenue_growth_y1 | H8: =revenue_growth_y2 | I8: =revenue_growth_y3 | J8: =revenue_growth_y4 | K8: =revenue_growth_y5 | L8: =revenue_growth_y6 | M8: =revenue_growth_y7
A9: Revenue | B9: Ricavi | C9: USD | D9: 81 | E9: 90 | F9: 100 | G9: =$F$9*(1+$G$8) | H9: =$G$9*(1+$H$8) | I9: =$H$9*(1+$I$8) | J9: =$I$9*(1+$J$8) | K9: =$J$9*(1+$K$8) | L9: =$K$9*(1+$L$8) | M9: =$L$9*(1+$M$8)
A11: Margin & opex | B11: Margini e opex
A12: EBITDA margin % | B12: Margine EBITDA % | C12: % | D12: 0.32962963 | E12: 0.34 | F12: 0.35 | G12: =ebitda_margin_y1 | H12: =ebitda_margin_y2 | I12: =ebitda_margin_y3 | J12: =ebitda_margin_y4 | K12: =ebitda_margin_y5 | L12: =ebitda_margin_y6 | M12: =ebitda_margin_y7
A13: EBITDA | B13: EBITDA | C13: USD | D13: 26.7 | E13: 30.6 | F13: 35 | G13: =$G$9*$G$12 | H13: =$H$9*$H$12 | I13: =$I$9*$I$12 | J13: =$J$9*$J$12 | K13: =$K$9*$K$12 | L13: =$L$9*$L$12 | M13: =$M$9*$M$12
A15: D&A | B15: Ammortamenti | C15: USD | D15: =-$D$9*da_pct_revenue | E15: =-$E$9*da_pct_revenue | F15: =-$F$9*da_pct_revenue | G15: =-$G$9*da_pct_revenue | H15: =-$H$9*da_pct_revenue | I15: =-$I$9*da_pct_revenue | J15: =-$J$9*da_pct_revenue | K15: =-$K$9*da_pct_revenue | L15: =-$L$9*da_pct_revenue | M15: =-$M$9*da_pct_revenue
A16: EBIT | B16: EBIT | C16: USD | D16: =$D$13+$D$15 | E16: =$E$13+$E$15 | F16: =$F$13+$F$15 | G16: =$G$13+$G$15 | H16: =$H$13+$H$15 | I16: =$I$13+$I$15 | J16: =$J$13+$J$15 | K16: =$K$13+$K$15 | L16: =$L$13+$L$15 | M16: =$M$13+$M$15
A18: Interest expense | B18: Oneri finanziari | C18: USD | D18: ='DebtSchedule'!D60 | E18: ='DebtSchedule'!E60 | F18: ='DebtSchedule'!F60 | G18: ='DebtSchedule'!G60 | H18: ='DebtSchedule'!H60 | I18: ='DebtSchedule'!I60 | J18: ='DebtSchedule'!J60 | K18: ='DebtSchedule'!K60 | ... M18: ='DebtSchedule'!M60
A19: Profit before tax | B19: Utile ante imposte | C19: USD | D19: =$D$16+$D$18 | E19: =$E$16+$E$18 | F19: =$F$16+$F$18 | G19: =$G$16+$G$18 | H19: =$H$16+$H$18 | I19: =$I$16+$I$18 | J19: =$J$16+$J$18 | K19: =$K$16+$K$18 | L19: =$L$16+$L$18 | M19: =$M$16+$M$18
A20: Taxes | B20: Imposte | C20: USD | D20: =-MAX($D$19,0)*effective_tax_rate | E20: =-MAX($E$19,0)*effective_tax_rate | F20: =-MAX($F$19,0)*effective_tax_rate | G20: =-MAX($G$19,0)*effective_tax_rate | H20: =-MAX($H$19,0)*effective_tax_rate | I20: =-MAX($I$19,0)*effective_tax_rate | J20: =-MAX($J$19,0)*effective_tax_rate | K20: =-MAX($K$19,0)*effective_tax_rate | L20: =-MAX($L$19,0)*effective_tax_rate | M20: =-MAX($M$19,0)*effective_tax_rate
A21: Net income | B21: Utile netto | C21: USD | D21: =$D$19+$D$20 | E21: =$E$19+$E$20 | F21: =$F$19+$F$20 | G21: =$G$19+$G$20 | H21: =$H$19+$H$20 | I21: =$I$19+$I$20 | J21: =$J$19+$J$20 | K21: =$K$19+$K$20 | L21: =$L$19+$L$20 | M21: =$M$19+$M$20
A23: Cash flow to debt | B23: Flusso di cassa al debito
A24: Maintenance capex | B24: Capex manutenzione | C24: USD | D24: =-$D$9*maintenance_capex_pct_revenue | E24: =-$E$9*maintenance_capex_pct_revenue | F24: =-$F$9*maintenance_capex_pct_revenue | G24: =-$G$9*maintenance_capex_pct_revenue | H24: =-$H$9*maintenance_capex_pct_revenue | I24: =-$I$9*maintenance_capex_pct_revenue | J24: =-$J$9*maintenance_capex_pct_revenue | K24: =-$K$9*maintenance_capex_pct_revenue | L24: =-$L$9*maintenance_capex_pct_revenue | M24: =-$M$9*maintenance_capex_pct_revenue
A25: Growth capex | B25: Capex crescita | C25: USD | D25: =-$D$9*growth_capex_pct_revenue | E25: =-$E$9*growth_capex_pct_revenue | F25: =-$F$9*growth_capex_pct_revenue | G25: =-$G$9*growth_capex_pct_revenue | H25: =-$H$9*growth_capex_pct_revenue | I25: =-$I$9*growth_capex_pct_revenue | J25: =-$J$9*growth_capex_pct_revenue | K25: =-$K$9*growth_capex_pct_revenue | L25: =-$L$9*growth_capex_pct_revenue | M25: =-$M$9*growth_capex_pct_revenue
A26: Total capex | B26: Capex totale | C26: USD | D26: =$D$24+$D$25 | E26: =$E$24+$E$25 | F26: =$F$24+$F$25 | G26: =$G$24+$G$25 | H26: =$H$24+$H$25 | I26: =$I$24+$I$25 | J26: =$J$24+$J$25 | K26: =$K$24+$K$25 | L26: =$L$24+$L$25 | M26: =$M$24+$M$25
A27: Δ Net working capital | B27: Δ Capitale circolante | C27: USD | D27: 0 | E27: =-($E$9-$D$9)*nwc_pct_revenue_delta | F27: =-($F$9-$E$9)*nwc_pct_revenue_delta | G27: =-($G$9-$F$9)*nwc_pct_revenue_delta | H27: =-($H$9-$G$9)*nwc_pct_revenue_delta | I27: =-($I$9-$H$9)*nwc_pct_revenue_delta | J27: =-($J$9-$I$9)*nwc_pct_revenue_delta | K27: =-($K$9-$J$9)*nwc_pct_revenue_delta | L27: =-($L$9-$K$9)*nwc_pct_revenue_delta | M27: =-($M$9-$L$9)*nwc_pct_revenue_delta
A28: Free cash flow to debt | B28: FCF al debito | C28: USD | D28: =$D$13+$D$20+$D$26+$D$27+$D$18 | E28: =$E$13+$E$20+$E$26+$E$27+$E$18 | F28: =$F$13+$F$20+$F$26+$F$27+$F$18 | G28: =$G$13+$G$20+$G$26+$G$27+$G$18 | H28: =$H$13+$H$20+$H$26+$H$27+$H$18 | I28: =$I$13+$I$20+$I$26+$I$27+$I$18 | J28: =$J$13+$J$20+$J$26+$J$27+$J$18 | K28: =$K$13+$K$20+$K$26+$K$27+$K$18 | L28: =$L$13+$L$20+$L$26+$L$27+$L$18 | M28: =$M$13+$M$20+$M$26+$M$27+$M$18

Sheet DebtSchedule
A1: Debt Schedule | B1: Piano del debito
A2: USD millions · average-balance interest convention
A3: ACTIVE SCENARIO → | B3: SCENARIO ATTIVO → | C3: =CHOOSE(scenario_index,"WORST","BASE","BEST")
D5: A 2023 | E5: A 2024 | F5: A 2025 | G5: E 2026 | H5: E 2027 | I5: E 2028 | J5: E 2029 | K5: E 2030 | L5: E 2031 | M5: E 2032
A7: Tranche — Senior Term Loan | B7: Term Loan Senior
A8: Opening debt | B8: Debito iniziale | C8: USD | D8: =0 | E8: =$D$11 | F8: =$E$11 | G8: =$F$11 | H8: =$G$11 | I8: =$H$11 | J8: =$I$11 | K8: =$J$11 | L8: =$K$11 | M8: =$L$11
A9: Drawdown | B9: Erogazione | C9: USD | D9: =0 | E9: =0 | F9: =0 | G9: =senior_tl_amount | H9: =0 | I9: =0 | J9: =0 | K9: =0 | L9: =0 | M9: =0
A10: Scheduled amortization | B10: Ammortamento | C10: USD | D10: =0 | E10: =0 | F10: =0 | G10: =0 | H10: =0 | I10: =0 | J10: =0 | K10: =0 | L10: =0 | M10: =-$M$8
A11: Closing debt | B11: Debito finale | C11: USD | D11: =$D$8+$D$9+$D$10 | E11: =$E$8+$E$9+$E$10 | F11: =$F$8+$F$9+$F$10 | G11: =$G$8+$G$9+$G$10 | H11: =$H$8+$H$9+$H$10 | I11: =$I$8+$I$9+$I$10 | J11: =$J$8+$J$9+$J$10 | K11: =$K$8+$K$9+$K$10 | L11: =$L$8+$L$9+$L$10 | M11: =$M$8+$M$9+$M$10
A12: Average debt | B12: Debito medio | C12: USD | D12: =($D$8+$D$11)/2 | E12: =($E$8+$E$11)/2 | F12: =($F$8+$F$11)/2 | G12: =($G$8+$G$11)/2 | H12: =($H$8+$H$11)/2 | I12: =($I$8+$I$11)/2 | J12: =($J$8+$J$11)/2 | K12: =($K$8+$K$11)/2 | L12: =($L$8+$L$11)/2 | M12: =($M$8+$M$11)/2
A13: All-in rate | B13: Tasso all-in | C13: % | D13: =MAX(sofr_rate,senior_tl_floor)+(senior_tl_margin_bps/10000) | E13: =MAX(sofr_rate,senior_tl_floor)+(senior_tl_margin_bps/10000) | F13: =MAX(sofr_rate,senior_tl_floor)+(senior_tl_margin_bps/10000) | G13: =MAX(sofr_rate,senior_tl_floor)+(senior_tl_margin_bps/10000) | H13: =MAX(sofr_rate,senior_tl_floor)+(senior_tl_margin_bps/10000) | I13: =MAX(sofr_rate,senior_tl_floor)+(senior_tl_margin_bps/10000) | J13: =MAX(sofr_rate,senior_tl_floor)+(senior_tl_margin_bps/10000) | K13: =MAX(sofr_rate,senior_tl_floor)+(senior_tl_margin_bps/10000) | ... M13: =MAX(sofr_rate,senior_tl_floor)+(senior_tl_margin_bps/10000)
A14: Cash interest | B14: Interessi cassa | C14: USD | D14: =-$D$8*$D$13 | E14: =-$E$8*$E$13 | F14: =-$F$8*$F$13 | G14: =-$G$8*$G$13 | H14: =-$H$8*$H$13 | I14: =-$I$8*$I$13 | J14: =-$J$8*$J$13 | K14: =-$K$8*$K$13 | L14: =-$L$8*$L$13 | M14: =-$M$8*$M$13
A15: Arrangement fee | B15: Commissione di strutturazione | C15: USD | D15: =0 | E15: =0 | F15: =0 | G15: =senior_tl_amount*senior_tl_arrangement_fee | H15: =0 | I15: =0 | J15: =0 | K15: =0 | L15: =0 | M15: =0
A17: Tranche — Mezzanine Notes | B17: Note Mezzanine
A18: Opening debt | B18: Debito iniziale | C18: USD | D18: =0 | E18: =$D$21 | F18: =$E$21 | G18: =$F$21 | H18: =$G$21 | I18: =$H$21 | J18: =$I$21 | K18: =$J$21 | L18: =$K$21 | M18: =$L$21
A19: Drawdown | B19: Erogazione | C19: USD | D19: =0 | E19: =0 | F19: =0 | G19: =mezz_amount | H19: =0 | I19: =0 | J19: =0 | K19: =0 | L19: =0 | M19: =0
A20: Scheduled amortization | B20: Ammortamento | C20: USD | D20: =0 | E20: =0 | F20: =0 | G20: =0 | H20: =0 | I20: =0 | J20: =0 | K20: =0 | ... M20: =0
A21: Closing debt | B21: Debito finale | C21: USD | D21: =$D$18+$D$19+$D$20 | E21: =$E$18+$E$19+$E$20 | F21: =$F$18+$F$19+$F$20 | G21: =$G$18+$G$19+$G$20 | H21: =$H$18+$H$19+$H$20 | I21: =$I$18+$I$19+$I$20 | J21: =$J$18+$J$19+$J$20 | K21: =$K$18+$K$19+$K$20 | L21: =$L$18+$L$19+$L$20 | M21: =$M$18+$M$19+$M$20
A22: Average debt | B22: Debito medio | C22: USD | D22: =($D$18+$D$21)/2 | E22: =($E$18+$E$21)/2 | F22: =($F$18+$F$21)/2 | G22: =($G$18+$G$21)/2 | H22: =($H$18+$H$21)/2 | I22: =($I$18+$I$21)/2 | J22: =($J$18+$J$21)/2 | K22: =($K$18+$K$21)/2 | L22: =($L$18+$L$21)/2 | M22: =($M$18+$M$21)/2
A23: All-in rate | B23: Tasso all-in | C23: % | D23: =MAX(sofr_rate_mezz,mezz_floor)+(mezz_margin_bps/10000) | E23: =MAX(sofr_rate_mezz,mezz_floor)+(mezz_margin_bps/10000) | F23: =MAX(sofr_rate_mezz,mezz_floor)+(mezz_margin_bps/10000) | G23: =MAX(sofr_rate_mezz,mezz_floor)+(mezz_margin_bps/10000) | H23: =MAX(sofr_rate_mezz,mezz_floor)+(mezz_margin_bps/10000) | I23: =MAX(sofr_rate_mezz,mezz_floor)+(mezz_margin_bps/10000) | J23: =MAX(sofr_rate_mezz,mezz_floor)+(mezz_margin_bps/10000) | K23: =MAX(sofr_rate_mezz,mezz_floor)+(mezz_margin_bps/10000) | ... M23: =MAX(sofr_rate_mezz,mezz_floor)+(mezz_margin_bps/10000)
A24: Cash interest | B24: Interessi cassa | C24: USD | D24: =-$D$18*$D$23 | E24: =-$E$18*$E$23 | F24: =-$F$18*$F$23 | G24: =-$G$18*$G$23 | H24: =-$H$18*$H$23 | I24: =-$I$18*$I$23 | J24: =-$J$18*$J$23 | K24: =-$K$18*$K$23 | L24: =-$L$18*$L$23 | M24: =-$M$18*$M$23
A25: Arrangement fee | B25: Commissione di strutturazione | C25: USD | D25: =0 | E25: =0 | F25: =0 | G25: =mezz_amount*mezz_arrangement_fee | H25: =0 | I25: =0 | J25: =0 | K25: =0 | L25: =0 | M25: =0
A27: Sources & Uses of Funds | B27: Fonti e impieghi
A28: USES
A29: Purchase equity (offer × shares) | D29: (See DealStructure if available)
A30: Refinance existing debt | D30: =0
A31: M&A advisory fees (expensed at close) | D31: =0
A32: Financing fees (capitalized) | D32: =0
A33: OID discount | D33: =0
A34: Minimum cash to BS | D34: =0
A36: SOURCES
A37: New debt raised (all tranches) | D37: =$G$11+$G$21
A38: Sponsor equity | D38: (Balance plug)
A39: Management rollover | D39: =0
A41: Check: Sources = Uses | D41: (Sponsor equity plugs the balance — full S&U in v0.8 SponsorLBO)
A43: — Additional bulge-tier stubs —
A44: • Purchase price build | D44: Offer premium × FD shares + existing net debt + fees
A45: • Goodwill created (PPA) | D45: Equity price − BV equity − write-ups + DTL
A46: • OID amortization schedule | D46: Straight-line over tenor, CFS addback
A47: • PIK toggle (payment-in-kind) | D47: Accrues to principal if cash insufficient
...

Sheet Covenants
A1: Covenants | B1: Covenant
A2: Period-by-period headroom & breach monitor
A3: ACTIVE SCENARIO → | B3: SCENARIO ATTIVO → | C3: =CHOOSE(scenario_index,"WORST","BASE","BEST")
D5: A 2023 | E5: A 2024 | F5: A 2025 | G5: E 2026 | H5: E 2027 | I5: E 2028 | J5: E 2029 | K5: E 2030 | L5: E 2031 | M5: E 2032
A7: Total Net Leverage | B7: Leva finanziaria netta totale
A8: Leverage (Debt / EBITDA) | B8: Leva (Debito / EBITDA) | C8: x | D8: =IFERROR('DebtSchedule'!D59/'OperatingModel'!D13,0) | E8: =IFERROR('DebtSchedule'!E59/'OperatingModel'!E13,0) | F8: =IFERROR('DebtSchedule'!F59/'OperatingModel'!F13,0) | G8: =IFERROR('DebtSchedule'!G59/'OperatingModel'!F13,0) | H8: =IFERROR('DebtSchedule'!H59/'OperatingModel'!H13,0) | I8: =IFERROR('DebtSchedule'!I59/'OperatingModel'!I13,0) | J8: =IFERROR('DebtSchedule'!J59/'OperatingModel'!J13,0) | K8: =IFERROR('DebtSchedule'!K59/'OperatingModel'!K13,0) | L8: =IFERROR('DebtSchedule'!L59/'OperatingModel'!L13,0) | M8: =IFERROR('DebtSchedule'!M59/'OperatingModel'!M13,0)
A9: Total Net Leverage — threshold | B9: Leva finanziaria netta totale — soglia | C9: x | G9: =leverage_threshold_y1 | H9: =leverage_threshold_y2 | I9: =leverage_threshold_y3 | J9: =leverage_threshold_y4 | K9: =leverage_threshold_y5 | L9: =leverage_threshold_y6 | M9: =leverage_threshold_y7
A10: Total Net Leverage — headroom | B10: Leva finanziaria netta totale — headroom | C10: % | G10: =IFERROR(($G$9-$G$8)/$G$9,0) | H10: =IFERROR(($H$9-$H$8)/$H$9,0) | I10: =IFERROR(($I$9-$I$8)/$I$9,0) | J10: =IFERROR(($J$9-$J$8)/$J$9,0) | K10: =IFERROR(($K$9-$K$8)/$K$9,0) | L10: =IFERROR(($L$9-$L$8)/$L$9,0) | M10: =IFERROR(($M$9-$M$8)/$M$9,0)
A11: Total Net Leverage — breach | B11: Leva finanziaria netta totale — violazione | G11: =IF(AND($G$8>$G$9,'DebtSchedule'!G60<-0.01),1,0) | H11: =IF(AND($H$8>$H$9,'DebtSchedule'!H60<-0.01),1,0) | I11: =IF(AND($I$8>$I$9,'DebtSchedule'!I60<-0.01),1,0) | J11: =IF(AND($J$8>$J$9,'DebtSchedule'!J60<-0.01),1,0) | K11: =IF(AND($K$8>$K$9,'DebtSchedule'!K60<-0.01),1,0) | L11: =IF(AND($L$8>$L$9,'DebtSchedule'!L60<-0.01),1,0) | M11: =IF(AND($M$8>$M$9,'DebtSchedule'!M60<-0.01),1,0)
A13: Interest Coverage Ratio | B13: Rapporto di copertura interessi
A14: Interest coverage (EBITDA / Interest) | B14: ICR (EBITDA / Oneri) | C14: x | D14: =IFERROR('OperatingModel'!D13/ABS('DebtSchedule'!D60),0) | E14: =IFERROR('OperatingModel'!E13/ABS('DebtSchedule'!E60),0) | F14: =IFERROR('OperatingModel'!F13/ABS('DebtSchedule'!F60),0) | G14: =IFERROR('OperatingModel'!G13/ABS('DebtSchedule'!G60),0) | H14: =IFERROR('OperatingModel'!H13/ABS('DebtSchedule'!H60),0) | I14: =IFERROR('OperatingModel'!I13/ABS('DebtSchedule'!I60),0) | J14: =IFERROR('OperatingModel'!J13/ABS('DebtSchedule'!J60),0) | K14: =IFERROR('OperatingModel'!K13/ABS('DebtSchedule'!K60),0) | ... M14: =IFERROR('OperatingModel'!M13/ABS('DebtSchedule'!M60),0)
A15: Interest Coverage Ratio — threshold | B15: Rapporto di copertura interessi — soglia | C15: x | G15: =icr_threshold_y1 | H15: =icr_threshold_y2 | I15: =icr_threshold_y3 | J15: =icr_threshold_y4 | K15: =icr_threshold_y5 | L15: =icr_threshold_y6 | M15: =icr_threshold_y7
A16: Interest Coverage Ratio — headroom | B16: Rapporto di copertura interessi — headroom | C16: % | G16: =IFERROR(($G$14-$G$15)/$G$15,0) | H16: =IFERROR(($H$14-$H$15)/$H$15,0) | I16: =IFERROR(($I$14-$I$15)/$I$15,0) | J16: =IFERROR(($J$14-$J$15)/$J$15,0) | K16: =IFERROR(($K$14-$K$15)/$K$15,0) | L16: =IFERROR(($L$14-$L$15)/$L$15,0) | M16: =IFERROR(($M$14-$M$15)/$M$15,0)
A17: Interest Coverage Ratio — breach | B17: Rapporto di copertura interessi — violazione | G17: =IF(AND($G$14<$G$15,'DebtSchedule'!G60<-0.01),1,0) | H17: =IF(AND($H$14<$H$15,'DebtSchedule'!H60<-0.01),1,0) | I17: =IF(AND($I$14<$I$15,'DebtSchedule'!I60<-0.01),1,0) | J17: =IF(AND($J$14<$J$15,'DebtSchedule'!J60<-0.01),1,0) | K17: =IF(AND($K$14<$K$15,'DebtSchedule'!K60<-0.01),1,0) | L17: =IF(AND($L$14<$L$15,'DebtSchedule'!L60<-0.01),1,0) | M17: =IF(AND($M$14<$M$15,'DebtSchedule'!M60<-0.01),1,0)
A19: Aggregate breach counter | B19: Contatore violazioni
A20: Total breaches (projection window) | B20: Violazioni totali (proiezione) | C20: =SUM($G$11:$M$11)+SUM($G$17:$M$17)
A22: FCCR covenant (sponsor LBO) | B22: Fixed Charge Coverage Ratio
A23: FCCR threshold (fixed charge coverage) | B23: Soglia FCCR | C23: 1.2

Sheet Returns
A1: Returns | B1: Rendimenti
A2: Lender IRR, MoIC, EIR (IFRS 9) — projection window only
A3: ACTIVE SCENARIO → | B3: SCENARIO ATTIVO → | C3: =CHOOSE(scenario_index,"WORST","BASE","BEST")
C5: Period | D5: t=0 | E5: t=1 | F5: t=2 | G5: t=3 | H5: t=4 | I5: t=5 | J5: t=6 | K5: t=7
A7: Transaction costs (at close) | B7: Costi della transazione (al closing)
A8: Legal fees | B8: Spese legali | C8: USD | D8: =legal_fees_eur_m
A9: Advisory fees | B9: Spese di consulenza | C9: USD | D9: =advisory_fees_eur_m
A10: Other transaction fees | B10: Altre spese di transazione | C10: USD | D10: =other_fees_eur_m
A11: Total transaction costs | B11: Costi totali | D11: =legal_fees_eur_m+advisory_fees_eur_m+other_fees_eur_m
A13: Exit assumptions | B13: Ipotesi di uscita
A14: Expected hold (years) | B14: Holding atteso (anni) | D14: =expected_hold_years
A15: Make-whole call rate | B15: Tasso make-whole | D15: =make_whole_pct
A17: Senior Term Loan — lender CF | B17: Senior Term Loan — CF finanziatore
A18: Lender cash flow | B18: Flusso al finanziatore | C18: USD | D18: =-'DebtSchedule'!G9+'DebtSchedule'!G15 | E18: =-'DebtSchedule'!G14-'DebtSchedule'!G10 | F18: =-'DebtSchedule'!H14-'DebtSchedule'!H10 | G18: =-'DebtSchedule'!I14-'DebtSchedule'!I10 | H18: =-'DebtSchedule'!J14-'DebtSchedule'!J10 | I18: =-'DebtSchedule'!K14-'DebtSchedule'!K10 | J18: =-'DebtSchedule'!L14-'DebtSchedule'!L10 | K18: =-'DebtSchedule'!M14-'DebtSchedule'!M10
A19: Lender IRR | B19: IRR finanziatore | D19: =IRR($D$18:$K$18)
A20: EIR (IFRS 9, incl. fees) | B20: EIR (IFRS 9, incl. commissioni) | D20: =IRR($D$18:$K$18,0.08)
A21: Lender MoIC | B21: MoIC finanziatore | D21: =IFERROR(SUMIF($D$18:$K$18,">0")/ABS(SUMIF($D$18:$K$18,"<0")),0)
A23: Mezzanine Notes — lender CF | B23: Mezzanine Notes — CF finanziatore
A24: Lender cash flow | B24: Flusso al finanziatore | C24: USD | D24: =-'DebtSchedule'!G19+'DebtSchedule'!G25 | E24: =-'DebtSchedule'!G24-'DebtSchedule'!G20 | F24: =-'DebtSchedule'!H24-'DebtSchedule'!H20 | G24: =-'DebtSchedule'!I24-'DebtSchedule'!I20 | H24: =-'DebtSchedule'!J24-'DebtSchedule'!J20 | I24: =-'DebtSchedule'!K24-'DebtSchedule'!K20 | J24: =-'DebtSchedule'!L24-'DebtSchedule'!L20 | K24: =-'DebtSchedule'!M24-'DebtSchedule'!M20
A25: Lender IRR | B25: IRR finanziatore | D25: =IRR($D$24:$K$24)
A26: EIR (IFRS 9, incl. fees) | B26: EIR (IFRS 9, incl. commissioni) | D26: =IRR($D$24:$K$24,0.08)
A27: Lender MoIC | B27: MoIC finanziatore | D27: =IFERROR(SUMIF($D$24:$K$24,">0")/ABS(SUMIF($D$24:$K$24,"<0")),0)
A29: Blended lender returns | B29: Rendimenti blended
A30: Blended cash flow | B30: CF totale | D30: =$D$18+$D$24 | E30: =$E$18+$E$24 | F30: =$F$18+$F$24 | G30: =$G$18+$G$24 | H30: =$H$18+$H$24 | I30: =$I$18+$I$24 | J30: =$J$18+$J$24 | K30: =$K$18+$K$24
A31: Blended IRR | B31: IRR blended | D31: =IRR($D$30:$K$30)
A32: Blended MoIC | B32: MoIC blended | D32: =IFERROR(SUMIF($D$30:$K$30,">0")/ABS(SUMIF($D$30:$K$30,"<0")),0)

Sheet SourcesUses
A1: Sources & Uses + LBO Structuring | B1: Sources & Uses + Struttura LBO | Z1: 35
A2: Balanced S&U, PPA, sponsor capital, exits, hurdle, promote
A5: Sources & Uses | B5: Fonti e impieghi (S&U)
A6: SOURCES | B6: FONTI
A7: Senior debt (Term Loan B / unitranche) | B7: Debito senior (TLB / unitranche) | D7: 157.5
A8: Mezzanine / subordinated debt | B8: Debito mezzanino | D8: 35
A9: Revolver facility (drawn at close) | B9: Revolver (tirato alla chiusura) | D9: 0
A10: Sponsor equity (new money) | B10: Equity dello sponsor (denaro nuovo) | D10: =D21-(D7+D8+D9)-D11
A11: Management rollover equity | B11: Rollover equity del management | D11: 0
A12: Total sources | B12: Totale fonti | D12: =D7+D8+D9+D10+D11
A14: USES | B14: IMPIEGHI
A15: Purchase equity (target shares × offer px) | B15: Equity da acquisire | D15: =D28
A16: Refinance target net debt | B16: Rifinanziamento debito target | D16: 20
A17: M&A advisory fees (expensed) | B17: Spese M&A (spesate) | D17: 7
A18: Financing fees (capitalized + amortized) | B18: Commissioni di finanziamento (capitalizzate) | D18: 5
A19: OID discount (original issue) | B19: Sconto OID | D19: 0
A20: Minimum cash to balance sheet | B20: Cassa minima al bilancio | D20: 5
A21: Total uses | B21: Totale impieghi | D21: =D15+D16+D17+D18+D19+D20
A22: S&U check (sources − uses) | B22: S&U check (fonti − impieghi) | D22: =D12-D21
A24: Purchase price build | B24: Costruzione prezzo di acquisto
A25: Offer price per share | B25: Prezzo di offerta per azione | D25: 5.5
A26: Fully-diluted shares outstanding (m) | B26: Azioni fully-diluted (m) | D26: 60
A27: Option buyout (treasury / in-the-money) | B27: Acquisto opzioni (metodo tesoriera / ITM) | D27: 0
A28: Equity purchase price | B28: Prezzo di acquisto equity | D28: =D25*D26+D27
A29: (+) Target net debt assumed | B29: (+) PFN target assunto | D29: 20
A30: (+) Transaction fees (aggregate) | B30: (+) Spese totali | D30: =D17+D18
A31: purchase_price — Enterprise Value | B31: Prezzo acquisto — Enterprise Value | D31: =D28+D29+D30
A33: Purchase Price Allocation (PPA) | B33: Allocazione prezzo di acquisto (PPA)
A34: Target book value of equity at close | B34: PN target alla chiusura | D34: 50
A35: PP&E fair-value write-up | B35: Rivalutazione immobilizzazioni | D35: 0
A36: Intangibles — customer list | B36: Intangibili — lista clienti | D36: 30
A37: Intangibles — technology | B37: Intangibili — tecnologia | D37: 15
A38: Intangibles — trade name | B38: Intangibili — marchio | D38: 10
A39: DTL rate on asset step-ups | B39: Aliquota DTL su rivalutazioni | D39: 0.24
A40: DTL on asset write-ups | B40: DTL su rivalutazioni | D40: =(D35+D36+D37+D38)*D39
A41: Goodwill created at close | B41: Avviamento creato | D41: =D28-D34-D35-D36-D37-D38+D40
A42: Customer-list amortization (SL, 10y) | B42: Ammortamento lista clienti (SL, 10 anni) | D42: =-D36/10
A43: Technology amortization (SL, 7y) | B43: Ammortamento tecnologia (SL, 7 anni) | D43: =-D37/7
A44: Trade-name amortization (SL, 15y) | B44: Ammortamento marchio (SL, 15 anni) | D44: =-D38/15
A45: Total PPA amortization (annual) | B45: Ammortamento PPA totale (annuale) | D45: =D42+D43+D44
...

Sheet QC
A1: Quality Checks | B1: Controlli qualità
A2: All checks must equal 1 before this model leaves the building.
A4: ALL CHECKS PASS | B4: Tutti i controlli OK | C4: =IF(SUM($C$7,$C$8,$C$9,$C$10,$C$11,$C$12,$C$13,$C$14,$C$15,$C$16,$C$17,$C$18)=12,1,0)
A6: Check | B6: Check (IT) | C6: Pass
A7: Sign: D&A negative all periods | B7: Segno: Ammortamenti negativi | C7: =IF(SUM($D$7:$M$7)=10,1,0) | D7: =IF('OperatingModel'!D15<=0,1,0) | E7: =IF('OperatingModel'!E15<=0,1,0) | F7: =IF('OperatingModel'!F15<=0,1,0) | G7: =IF('OperatingModel'!G15<=0,1,0) | H7: =IF('OperatingModel'!H15<=0,1,0) | I7: =IF('OperatingModel'!I15<=0,1,0) | J7: =IF('OperatingModel'!J15<=0,1,0) | K7: =IF('OperatingModel'!K15<=0,1,0) | ... M7: =IF('OperatingModel'!M15<=0,1,0)
A8: Sign: Tax ≤ 0 all periods | B8: Segno: Imposte ≤ 0 | C8: =IF(SUM($D$8:$M$8)=10,1,0) | D8: =IF('OperatingModel'!D20<=0,1,0) | E8: =IF('OperatingModel'!E20<=0,1,0) | F8: =IF('OperatingModel'!F20<=0,1,0) | G8: =IF('OperatingModel'!G20<=0,1,0) | H8: =IF('OperatingModel'!H20<=0,1,0) | I8: =IF('OperatingModel'!I20<=0,1,0) | J8: =IF('OperatingModel'!J20<=0,1,0) | K8: =IF('OperatingModel'!K20<=0,1,0) | ... M8: =IF('OperatingModel'!M20<=0,1,0)
A9: Sign: Capex negative all periods | B9: Segno: Capex negativo | C9: =IF(SUM($D$9:$M$9)=10,1,0) | D9: =IF('OperatingModel'!D26<=0,1,0) | E9: =IF('OperatingModel'!E26<=0,1,0) | F9: =IF('OperatingModel'!F26<=0,1,0) | G9: =IF('OperatingModel'!G26<=0,1,0) | H9: =IF('OperatingModel'!H26<=0,1,0) | I9: =IF('OperatingModel'!I26<=0,1,0) | J9: =IF('OperatingModel'!J26<=0,1,0) | K9: =IF('OperatingModel'!K26<=0,1,0) | ... M9: =IF('OperatingModel'!M26<=0,1,0)
A10: Sign: Interest expense ≤ 0 | B10: Segno: Oneri finanziari ≤ 0 | C10: =IF(SUM($D$10:$M$10)=10,1,0) | D10: =IF('OperatingModel'!D18<=0,1,0) | E10: =IF('OperatingModel'!E18<=0,1,0) | F10: =IF('OperatingModel'!F18<=0,1,0) | G10: =IF('OperatingModel'!G18<=0,1,0) | H10: =IF('OperatingModel'!H18<=0,1,0) | I10: =IF('OperatingModel'!I18<=0,1,0) | J10: =IF('OperatingModel'!J18<=0,1,0) | K10: =IF('OperatingModel'!K18<=0,1,0) | ... M10: =IF('OperatingModel'!M18<=0,1,0)
A11: Debt closing non-negative | B11: Debito finale ≥ 0 | C11: =IF(SUM($D$11:$M$11)=10,1,0) | D11: =IF('DebtSchedule'!D59>=-0.01,1,0) | E11: =IF('DebtSchedule'!E59>=-0.01,1,0) | F11: =IF('DebtSchedule'!F59>=-0.01,1,0) | G11: =IF('DebtSchedule'!G59>=-0.01,1,0) | H11: =IF('DebtSchedule'!H59>=-0.01,1,0) | I11: =IF('DebtSchedule'!I59>=-0.01,1,0) | J11: =IF('DebtSchedule'!J59>=-0.01,1,0) | K11: =IF('DebtSchedule'!K59>=-0.01,1,0) | ... M11: =IF('DebtSchedule'!M59>=-0.01,1,0)
A12: Covenant breach counter = 0 (active scenario) | B12: Contatore violazioni covenant = 0 (scenario attivo) | C12: =IF('Covenants'!$C$20=0,1,0)
A13: Revenue ≥ 0 all periods | B13: Ricavi ≥ 0 | C13: =IF(SUM($D$13:$M$13)=10,1,0) | D13: =IF('OperatingModel'!D9>=0,1,0) | E13: =IF('OperatingModel'!E9>=0,1,0) | F13: =IF('OperatingModel'!F9>=0,1,0) | G13: =IF('OperatingModel'!G9>=0,1,0) | H13: =IF('OperatingModel'!H9>=0,1,0) | I13: =IF('OperatingModel'!I9>=0,1,0) | J13: =IF('OperatingModel'!J9>=0,1,0) | K13: =IF('OperatingModel'!K9>=0,1,0) | ... M13: =IF('OperatingModel'!M9>=0,1,0)
A14: EBITDA margin in [0%, 60%] | B14: Margine EBITDA in [0%, 60%] | C14: =IF(SUM($D$14:$M$14)=10,1,0) | D14: =IF(AND('OperatingModel'!D12>=0,'OperatingModel'!D12<=0.6),1,0) | E14: =IF(AND('OperatingModel'!E12>=0,'OperatingModel'!E12<=0.6),1,0) | F14: =IF(AND('OperatingModel'!F12>=0,'OperatingModel'!F12<=0.6),1,0) | G14: =IF(AND('OperatingModel'!G12>=0,'OperatingModel'!G12<=0.6),1,0) | H14: =IF(AND('OperatingModel'!H12>=0,'OperatingModel'!H12<=0.6),1,0) | I14: =IF(AND('OperatingModel'!I12>=0,'OperatingModel'!I12<=0.6),1,0) | J14: =IF(AND('OperatingModel'!J12>=0,'OperatingModel'!J12<=0.6),1,0) | K14: =IF(AND('OperatingModel'!K12>=0,'OperatingModel'!K12<=0.6),1,0) | ... M14: =IF(AND('OperatingModel'!M12>=0,'OperatingModel'!M12<=0.6),1,0)
A15: No errors on Net income | B15: Nessun errore su Utile netto | C15: =IF(SUM($D$15:$M$15)=10,1,0) | D15: =IF(ISERROR('OperatingModel'!D21),0,1) | E15: =IF(ISERROR('OperatingModel'!E21),0,1) | F15: =IF(ISERROR('OperatingModel'!F21),0,1) | G15: =IF(ISERROR('OperatingModel'!G21),0,1) | H15: =IF(ISERROR('OperatingModel'!H21),0,1) | I15: =IF(ISERROR('OperatingModel'!I21),0,1) | J15: =IF(ISERROR('OperatingModel'!J21),0,1) | K15: =IF(ISERROR('OperatingModel'!K21),0,1) | ... M15: =IF(ISERROR('OperatingModel'!M21),0,1)
A16: Arrangement fee paid at close year only | B16: Commissione di strutturazione al closing | C16: =IF(AND('DebtSchedule'!G15>=0,'DebtSchedule'!G25>=0),1,0)
A17: Total debt → 0 by final period | B17: Debito totale → 0 a fine piano | C17: =IF('DebtSchedule'!M59<=0.1,1,0)
A18: Net income = EBT + tax (tie) | B18: Utile netto = EBT + imposte | C18: =IF(SUM($D$18:$M$18)=10,1,0) | D18: =IF(ABS('OperatingModel'!D21-('OperatingModel'!D19+'OperatingModel'!D20))<=0.01,1,0) | E18: =IF(ABS('OperatingModel'!E21-('OperatingModel'!E19+'OperatingModel'!E20))<=0.01,1,0) | F18: =IF(ABS('OperatingModel'!F21-('OperatingModel'!F19+'OperatingModel'!F20))<=0.01,1,0) | G18: =IF(ABS('OperatingModel'!G21-('OperatingModel'!G19+'OperatingModel'!G20))<=0.01,1,0) | H18: =IF(ABS('OperatingModel'!H21-('OperatingModel'!H19+'OperatingModel'!H20))<=0.01,1,0) | I18: =IF(ABS('OperatingModel'!I21-('OperatingModel'!I19+'OperatingModel'!I20))<=0.01,1,0) | J18: =IF(ABS('OperatingModel'!J21-('OperatingModel'!J19+'OperatingModel'!J20))<=0.01,1,0) | K18: =IF(ABS('OperatingModel'!K21-('OperatingModel'!K19+'OperatingModel'!K20))<=0.01,1,0) | ... M18: =IF(ABS('OperatingModel'!M21-('OperatingModel'!M19+'OperatingModel'!M20))<=0.01,1,0)

Sheet MOAT
A1: ModelForge MOAT — Live-Formula Verification
A2: Workbook: lbo_us_saas.xlsx
A3: Core-output formula density: 97.5%
A4: Overall: FAIL (3/4 gates)
A6: Gate | B6: Verdict | C6: Metric | D6: Threshold | E6: Detail
A7: formula_density | B7: PASS | C7: 0.9751 | D7: 0.9000 | E7: All core output sheets meet density threshold
A8: reference_graph | B8: PASS | C8: 0.00 | D8: 0.00 | E8: No magic-number literals in output formulas
A9: no_orphan_inputs | B9: FAIL | C9: 7.00 | D9: 5.00 | E9: 7 orphan named range(s): exit_year_input, historical_ebitda_lfy, mezz_commitment_fee, mezz_oid, purchase_price_eur_m
A10: recalculation | B10: PASS | C10: 0.00 | D10: 0 | E10: All formula values reconcile (tol=1e-04)
A12: Per-sheet formula density
A13: Sheet | B13: Class | C13: Numeric cells | D13: Formula cells | E13: Formula % | F13: Magic-number cells
A14: RedFlags | B14: audit | C14: 0 | D14: 0 | E14: n/a | F14: 0
A15: Cover | B15: input | C15: 2 | D15: 1 | E15: 50.0% | F15: 0
A16: Sources | B16: input | C16: 1 | D16: 0 | E16: 0.0% | F16: 0
A17: Assumptions | B17: input | C17: 208 | D17: 52 | E17: 25.0% | F17: 0
A18: OperatingModel | B18: core_output | C18: 150 | D18: 140 | E18: 93.3% | F18: 0
A19: DebtSchedule | B19: core_output | C19: 188 | D19: 188 | E19: 100.0% | F19: 0
A20: Covenants | B20: core_output | C20: 65 | D20: 64 | E20: 98.5% | F20: 0
A21: Returns | B21: core_output | C21: 39 | D21: 39 | E21: 100.0% | F21: 0
A22: SourcesUses | B22: unknown | C22: 112 | D22: 60 | E22: 53.6% | F22: 0
A23: QC | B23: audit | C23: 103 | D23: 103 | E23: 100.0% | F23: 0
A24: ComplianceCheck | B24: audit | C24: 13 | D24: 5 | E24: 38.5% | F24: 0
A25: SensitivityAnalysis | B25: audit | C25: 78 | D25: 57 | E25: 73.1% | F25: 0
... A27: Reproducibility | B27: audit | C27: 1 | D27: 1 | E27: 100.0% | F27: 0
A30: Orphan named ranges (7):
A31: exit_year_input, historical_ebitda_lfy, mezz_commitment_fee, mezz_oid, purchase_price_eur_m, senior_tl_commitment_fee, senior_tl_oid

Sheet ComplianceCheck
A1: Compliance Check | B1: Controllo di conformità
A2: AIFMD II / IFRS 9 / Basel III-IV / GACS — Italian & EU regulatory plumbing
A5: AIFMD II leverage & concentration | B5: AIFMD II leva & concentrazione
A6: AIF type (open/closed) | B6: Tipo AIF | D6: closed
A7: AIFMD II leverage cap — open-ended | B7: Limite leva AIFMD II — aperto | D7: 1.75
A8: AIFMD II leverage cap — closed-ended | B8: Limite leva AIFMD II — chiuso | D8: 3
A9: AIFMD II leverage cap (applied) | B9: Limite AIFMD II (applicato) | D9: =IF($D$6="open",aif_leverage_cap_open,aif_leverage_cap_closed)
A10: Actual portfolio leverage | B10: Leva effettiva | D10: 1.5
A11: AIFMD II leverage compliance | D11: =IF(aif_actual_leverage<=$D$9,"PASS","FAIL")
A13: Largest single borrower % NAV | B13: Maggior debitore % NAV | D13: 0.15
A14: AIFMD II single-borrower cap | B14: Limite singolo debitore | D14: 0.2
A15: Single-borrower compliance | D15: =IF(aif_largest_single_borrower_pct_nav<=aif_single_borrower_cap,"PASS","FAIL")
A17: Loan-originating AIF status | B17: Classificazione AIF con origination
A18: Originated loans % NAV | B18: Prestiti originati % NAV | D18: 0.55
A19: Loan-originating AIF flag | D19: =IF($D$18>=0.50,"YES — closed-ended required if >60%","NO")
A21: IFRS 9 three-stage ECL | B21: IFRS 9 modello a tre stadi
A22: ECL formula (canonical): ECL = PD × LGD × EAD × DF | B22: Formula ECL: PD × LGD × EAD × Fattore sconto
A23: where PD = probability of default, LGD = loss given default, EAD = exposure at default, DF = discount factor
A25: Stage 1 (12-month ECL — no SICR) | B25: Stadio 1 (ECL 12m — no SICR) | D25: 12m PD × LGD × EAD × DF
A26: Stage 2 (Lifetime ECL — SICR triggered) | B26: Stadio 2 (ECL lifetime — SICR) | D26: Lifetime PD × LGD × EAD × DF | 30+DPD backstop
A27: Stage 3 (Lifetime ECL — credit-impaired) | B27: Stadio 3 (ECL lifetime — impaired) | D27: PD 100% × LGD × EAD × DF | interest on NET
A29: SICR triggers (document bank policy)
A30: • Absolute PD threshold breach
A31: • Relative PD doubling vs origination
A32: • Rating downgrade by ≥2 notches
A33: • Watchlist flag
A34: • Forbearance granted
A35: • 30+ days past due (DPD) presumption
A37: Basel NPL calendar provisioning | B37: Calendar provisioning NPL
A38: Regulation (EU) 2019/630 — NPL minimum coverage
A39: • Unsecured NPEs | B39: NPE non garantite | D39: 0% / 35% / 100% (Y1-2 / Y3 / Y3+)
A40: • NPEs secured by real estate | B40: NPE garantite da immobili | D40: 0% / 25% / 70% / 100% (Y1-4 / Y5 / Y7 / Y9+)
A41: • NPEs secured by other collateral | B41: NPE garantite altro | D41: 0% / 35% / 70% / 100% (Y1-2 / Y3 / Y4 / Y7+)
A44: GACS (Garanzia Cartolarizzazione Sofferenze) | B44: GACS — Garanzia stato su senior NPL
A45: • Senior tranche rating ≥ BBB- | B45: Rating senior ≥ investment grade | D45: BBB
A46: • Legge 130/1999 SPV (bankruptcy-remote) | B46: SPV legge 130/1999 | D46: YES (required)
A47: • Guarantee fee priced on IT financial CDS | B47: Fee garanzia su CDS finanziari italiani | D47: IT Italian financial-sector CDS basket (5Y)
A48: • Servicer fit-and-proper (Banca d'Italia) | B48: Servicer requisiti | D48: Required
A50: Italian tax — IRES + IRAP split | B50: Tassazione italiana — IRES + IRAP
A51: IRES rate | B51: Aliquota IRES | D51: 0.24
...

Sheet SensitivityAnalysis
A1: Sensitivity Analysis
A2: Analisi di sensibilità
A3: ACTIVE SCENARIO → | B3: SCENARIO ATTIVO → | C3: =CHOOSE(scenario_index,"WORST","BASE","BEST")
A4: LIVE — linear-elasticity approximation off primary_output. Recomputes when you change scenario_index or edit a driver/shock. Exact non-linear recompute via the `modelforge` CLI / dossier. | LIVE — approssimazione a elasticità lineare su primary_output. Si ricalcola quando cambi scenario_index o modifichi un driver/shock. Ricalcolo esatto non lineare tramite la CLI `modelforge` / dossier.
A5: Primary output | B5: Blended Lender IRR | D5: =primary_output
A6: Factors analyzed | D6: 5
J8: Method: LIVE elasticity formula
A9: ID | B9: Factor | C9: Driver | D9: Base | E9: Low shk | F9: High shk | G9: Elast. | H9: Low value | I9: High value | J9: Low Δ | K9: High Δ
A10: F-001 | B10: Revenue growth Y1 ±20% | C10: revenue_growth_y1 | D10: =revenue_growth_y1 | E10: -0.2 | F10: 0.2 | G10: 0.8 | H10: =D10*(1+E10) | I10: =D10*(1+F10) | J10: =primary_output*E10*G10 | K10: =primary_output*F10*G10
A11: F-002 | B11: EBITDA margin Y1 ±25% | C11: ebitda_margin_y1 | D11: =ebitda_margin_y1 | E11: -0.25 | F11: 0.25 | G11: 0.9 | H11: =D11*(1+E11) | I11: =D11*(1+F11) | J11: =primary_output*E11*G11 | K11: =primary_output*F11*G11
A12: F-003 | B12: Maintenance capex % rev ±20% | C12: maintenance_capex_pct_revenue | D12: =maintenance_capex_pct_revenue | E12: -0.2 | F12: 0.2 | G12: -0.3 | H12: =D12*(1+E12) | I12: =D12*(1+F12) | J12: =primary_output*E12*G12 | K12: =primary_output*F12*G12
A13: F-004 | B13: Growth capex % rev ±25% | C13: growth_capex_pct_revenue | D13: =growth_capex_pct_revenue | E13: -0.25 | F13: 0.25 | G13: -0.25 | H13: =D13*(1+E13) | I13: =D13*(1+F13) | J13: =primary_output*E13*G13 | K13: =primary_output*F13*G13
A14: F-005 | B14: Effective tax rate ±10% | C14: effective_tax_rate | D14: =effective_tax_rate | E14: -0.1 | F14: 0.1 | G14: -0.3 | H14: =D14*(1+E14) | I14: =D14*(1+F14) | J14: =primary_output*E14*G14 | K14: =primary_output*F14*G14
A17: 2D Data Table: EBITDA margin Y1 ±25% × Revenue growth Y1 ±20% =TABLE(ebitda_margin_y1, revenue_growth_y1) (linear elasticity: rows=+0.90, cols=+0.80)
A18: LIVE — linear-elasticity approximation off primary_output. Recomputes when you change scenario_index or edit a driver/shock. Exact non-linear recompute via the `modelforge` CLI / dossier. | LIVE — approssimazione a elasticità lineare su primary_output. Si ricalcola quando cambi scenario_index o modifichi un driver/shock. Ricalcolo esatto non lineare tramite la CLI `modelforge` / dossier.
A19: Each cell = primary_output × (1 + row_shock × row_elasticity + col_shock × col_elasticity), a live Excel formula. Shocks live via named ranges sensitivity_shock_1..5 (editable inputs); flip scenario_index or edit a shock and the body recomputes.
B20: ebitda_margin_y1 ↓ / revenue_growth_y1 → | C20: -0.2 | D20: -0.1 | E20: 0 | F20: 0.1 | G20: 0.2
B21: =sensitivity_shock_1 | C21: =primary_output*(1+sensitivity_shock_1*(0.9)+sensitivity_shock_1*(0.8)) | D21: =primary_output*(1+sensitivity_shock_1*(0.9)+sensitivity_shock_2*(0.8)) | E21: =primary_output*(1+sensitivity_shock_1*(0.9)+sensitivity_shock_3*(0.8)) | F21: =primary_output*(1+sensitivity_shock_1*(0.9)+sensitivity_shock_4*(0.8)) | G21: =primary_output*(1+sensitivity_shock_1*(0.9)+sensitivity_shock_5*(0.8))
B22: =sensitivity_shock_2 | C22: =primary_output*(1+sensitivity_shock_2*(0.9)+sensitivity_shock_1*(0.8)) | D22: =primary_output*(1+sensitivity_shock_2*(0.9)+sensitivity_shock_2*(0.8)) | E22: =primary_output*(1+sensitivity_shock_2*(0.9)+sensitivity_shock_3*(0.8)) | F22: =primary_output*(1+sensitivity_shock_2*(0.9)+sensitivity_shock_4*(0.8)) | G22: =primary_output*(1+sensitivity_shock_2*(0.9)+sensitivity_shock_5*(0.8))
B23: =sensitivity_shock_3 | C23: =primary_output*(1+sensitivity_shock_3*(0.9)+sensitivity_shock_1*(0.8)) | D23: =primary_output*(1+sensitivity_shock_3*(0.9)+sensitivity_shock_2*(0.8)) | E23: =primary_output*(1+sensitivity_shock_3*(0.9)+sensitivity_shock_3*(0.8)) | F23: =primary_output*(1+sensitivity_shock_3*(0.9)+sensitivity_shock_4*(0.8)) | G23: =primary_output*(1+sensitivity_shock_3*(0.9)+sensitivity_shock_5*(0.8))
B24: =sensitivity_shock_4 | C24: =primary_output*(1+sensitivity_shock_4*(0.9)+sensitivity_shock_1*(0.8)) | D24: =primary_output*(1+sensitivity_shock_4*(0.9)+sensitivity_shock_2*(0.8)) | E24: =primary_output*(1+sensitivity_shock_4*(0.9)+sensitivity_shock_3*(0.8)) | F24: =primary_output*(1+sensitivity_shock_4*(0.9)+sensitivity_shock_4*(0.8)) | G24: =primary_output*(1+sensitivity_shock_4*(0.9)+sensitivity_shock_5*(0.8))
B25: =sensitivity_shock_5 | C25: =primary_output*(1+sensitivity_shock_5*(0.9)+sensitivity_shock_1*(0.8)) | D25: =primary_output*(1+sensitivity_shock_5*(0.9)+sensitivity_shock_2*(0.8)) | E25: =primary_output*(1+sensitivity_shock_5*(0.9)+sensitivity_shock_3*(0.8)) | F25: =primary_output*(1+sensitivity_shock_5*(0.9)+sensitivity_shock_4*(0.8)) | G25: =primary_output*(1+sensitivity_shock_5*(0.9)+sensitivity_shock_5*(0.8))

Sheet MonteCarlo
A1: Monte Carlo Simulation
A2: Simulazione Monte Carlo
A3: ACTIVE SCENARIO → | B3: SCENARIO ATTIVO → | C3: =CHOOSE(scenario_index,"WORST","BASE","BEST")
A4: STATIC SNAPSHOT — computed at build time (seed/scenario fixed). Does NOT recompute when you change scenario_index or drivers. To refresh: rebuild from the spec. | ISTANTANEA STATICA — calcolata in fase di build (seed/scenario fissi). NON si ricalcola se modifichi scenario_index o i driver. Per aggiornare: ricostruisci dalla specifica.
A5: Base output | B5: Blended Lender IRR | C5: =primary_output
A6: 1,000-run triangular simulation on Blended Lender IRR. Method: linearized per-factor elasticity. Δ mode: fractional (× base = absolute). Seed=20260417.
A8: PARAMETRIC (LIVE — normal approx) — P5/P50/P95/mean as live Excel formulas off primary_output and the mc_vol input. RECOMPUTES when you flip scenario_index or edit mc_vol. Distinct from the sampled histogram below, which is a build-time snapshot (exact resim via `modelforge monte-carlo`). | PARAMETRICO (LIVE — approssimazione normale) — P5/P50/P95/media come formule Excel live su primary_output e l'input mc_vol. Si RICALCOLA quando cambi scenario_index o modifichi mc_vol. Distinto dall'istogramma campionato sotto, che è un'istantanea di build (ri-simulazione esatta con `modelforge monte-carlo`).
A9: Volatility (σ, editable) | B9: 0.11846836
A10: Statistic | B10: Parametric (LIVE)
A11: Mean (LIVE) | B11: =primary_output
A12: P5 (LIVE) | B12: =primary_output*(1+NORM.S.INV(0.05)*mc_vol)
A13: P50 (LIVE) | B13: =primary_output*(1+NORM.S.INV(0.5)*mc_vol)
A14: P95 (LIVE) | B14: =primary_output*(1+NORM.S.INV(0.95)*mc_vol)
A16: SAMPLED (snapshot) — full 1,000-draw triangular distribution; frozen at build time, does NOT recompute on scenario flip (refresh: `modelforge monte-carlo`).
A17: Statistic | B17: Δ output (frac) | C17: Absolute output
A18: Mean | B18: 0.0021479997 | C18: =primary_output*(1+B18)
A19: Std | B19: 0.11846836 | C19: =primary_output*(1+B19)
A20: P5 | B20: -0.19376388 | C20: =primary_output*(1+B20)
A21: P25 | B21: -0.076004351 | C21: =primary_output*(1+B21)
A22: P50 (median) | B22: 0.0010594389 | C22: =primary_output*(1+B22)
A23: P75 | B23: 0.084478031 | C23: =primary_output*(1+B23)
A24: P95 | B24: 0.19348427 | C24: =primary_output*(1+B24)
A25: Min | B25: -0.35321006 | C25: =primary_output*(1+B25)
A26: Max | B26: 0.35398927 | C26: =primary_output*(1+B26)
A29: Histogram bins
A30: Bin low (Δ) | B30: Bin high (Δ) | C30: Count
A31: -0.35321006 | B31: -0.32963674 | C31: 1
A32: -0.32963674 | B32: -0.30606343 | C32: 2
A33: -0.30606343 | B33: -0.28249012 | C33: 3
A34: -0.28249012 | B34: -0.25891681 | C34: 6
A35: -0.25891681 | B35: -0.2353435 | C35: 9
A36: -0.2353435 | B36: -0.21177019 | C36: 16
A37: -0.21177019 | B37: -0.18819688 | C37: 23
A38: -0.18819688 | B38: -0.16462357 | C38: 29
A39: -0.16462357 | B39: -0.14105026 | C39: 30
A40: -0.14105026 | B40: -0.11747695 | C40: 38
A41: -0.11747695 | B41: -0.093903637 | C41: 53
A42: -0.093903637 | B42: -0.070330327 | C42: 61
... A60: 0.33041596 | B60: 0.35398927 | C60: 2

Sheet Reproducibility
A1: Reproducibility
A2: Riproducibilità
A3: ACTIVE SCENARIO → | B3: SCENARIO ATTIVO → | C3: =CHOOSE(scenario_index,"WORST","BASE","BEST")
A4: Every workbook emitted by `modelforge build` carries this metadata. The spec SHA-256 is deterministic: two workbooks built from identical spec bytes will match. Use `modelforge verify <xlsx> --spec <yaml>` to confirm a workbook was built from a given spec.
A5: Spec SHA-256 | B5: 02638f2408789f372d708531d5d25d88450a9cf8b549ef8466e4a06ac93cf300
A6: ModelForge version | B6: 0.1.0
A7: Python version | B7: 3.14.0
A8: Build timestamp (UTC) | B8: 2026-01-01T00:00:00+00:00
A9: Spec source | B9: C:\Users\lukep\Desktop\Projects AI\ModelForge\benchmarks\specs\lbo_us_saas.yaml
A10: Host | B10: Windows 11
A11: Python impl | B11: CPython 3.14
