Workbook

Sheet Model
A1: MfgCo — Integrated 3-Statement Model (Deal Brief BM-3S-001)
A2: USD millions unless stated · 365-day year · Synthetic benchmark — MfgCo is fictional · Blue = input, Black = formula, Green = cross-sheet link
A4: Fiscal year | B4: FY0 | C4: FY1 | D4: FY2 | E4: FY3 | F4: FY4 | G4: FY5 | H4: FY6 | I4: FY7
A5: Phase (t = 0..7) | B5: Historical | C5: Historical | D5: Historical | E5: Projection | F5: Projection | G5: Projection | H5: Projection | I5: Projection
A7: ASSUMPTIONS & DRIVERS
A8: Revenue growth (% YoY) | C8: =C23/B23-1 | D8: =D23/C23-1 | E8: 0.05 | F8: 0.045 | G8: 0.04 | H8: 0.035 | I8: 0.03
A9: EBITDA margin (%) | B9: =B24/B23 | C9: =C24/C23 | D9: =D24/D23 | E9: 0.14 | F9: 0.145 | G9: 0.15 | H9: 0.15 | I9: 0.15
A11: D&A (% of revenue) | B11: 0.055 | C11: All years t = 0..7
A12: Capex (% of revenue) | B12: 0.06 | C12: All years t = 0..7
A13: Interest rate on debt | B13: 0.06 | C13: On opening debt balance; t=0 charged on the t=0 balance
A14: Tax rate | B14: 0.25 | C14: On positive EBT only
A15: Receivable days (DSO) | B15: 55 | C15: AR = Revenue x DSO/365, from t=1 onward
A16: Inventory days (DIO, on revenue) | B16: 60 | C16: Inventory = Revenue x DIO/365, from t=1 (stated simplification)
A17: Payable days (DPO, on revenue) | B17: 40 | C17: AP = Revenue x DPO/365, from t=1 (stated simplification)
A18: Dividend payout (% of positive NI) | B18: 0.3 | C18: Financing outflow in CFS
A19: Scheduled debt amortization ($m / yr) | B19: 20 | C19: Floored at 0; financing outflow in CFS
A20: Days in year | B20: 365
A22: INCOME STATEMENT
A23: Revenue | B23: 540 | C23: 570 | D23: 600 | E23: =D23*(1+E8) | F23: =E23*(1+F8) | G23: =F23*(1+G8) | H23: =G23*(1+H8) | I23: =H23*(1+I8)
A24: EBITDA | B24: 70.2 | C24: 76.95 | D24: 84 | E24: =E23*E9 | F24: =F23*F9 | G24: =G23*G9 | H24: =H23*H9 | I24: =I23*I9
A25: Less: D&A (5.5% of revenue) | B25: =B23*$B$11 | C25: =C23*$B$11 | D25: =D23*$B$11 | E25: =E23*$B$11 | F25: =F23*$B$11 | G25: =G23*$B$11 | H25: =H23*$B$11 | I25: =I23*$B$11
A26: EBIT | B26: =B24-B25 | C26: =C24-C25 | D26: =D24-D25 | E26: =E24-E25 | F26: =F24-F25 | G26: =G24-G25 | H26: =H24-H25 | I26: =I24-I25
A27: Less: Interest expense (6.0% on opening debt) | B27: =$B$13*B51 | C27: =$B$13*B51 | D27: =$B$13*C51 | E27: =$B$13*D51 | F27: =$B$13*E51 | G27: =$B$13*F51 | H27: =$B$13*G51 | I27: =$B$13*H51
A28: EBT (pre-tax income) | B28: =B26-B27 | C28: =C26-C27 | D28: =D26-D27 | E28: =E26-E27 | F28: =F26-F27 | G28: =G26-G27 | H28: =H26-H27 | I28: =I26-I27
A29: Less: Taxes (25% of positive EBT) | B29: =MAX(0,B28)*$B$14 | C29: =MAX(0,C28)*$B$14 | D29: =MAX(0,D28)*$B$14 | E29: =MAX(0,E28)*$B$14 | F29: =MAX(0,F28)*$B$14 | G29: =MAX(0,G28)*$B$14 | H29: =MAX(0,H28)*$B$14 | I29: =MAX(0,I28)*$B$14
A30: Net income | B30: =B28-B29 | C30: =C28-C29 | D30: =D28-D29 | E30: =E28-E29 | F30: =F28-F29 | G30: =G28-G29 | H30: =H28-H29 | I30: =I28-I29
A31: memo: Net margin (%) | B31: =B30/B23 | C31: =C30/C23 | D31: =D30/D23 | E31: =E30/E23 | F31: =F30/F23 | G31: =G30/G23 | H31: =H30/H23 | I31: =I30/I23
A32: memo: Dividends declared (30% of positive NI) | B32: =$B$18*MAX(0,B30) | C32: =$B$18*MAX(0,C30) | D32: =$B$18*MAX(0,D30) | E32: =$B$18*MAX(0,E30) | F32: =$B$18*MAX(0,F30) | G32: =$B$18*MAX(0,G30) | H32: =$B$18*MAX(0,H30) | I32: =$B$18*MAX(0,I30)
A34: SUPPORTING SCHEDULES
A35: Working capital (days-driven from t = 1; t = 0 anchored to opening balance sheet)
A36: Accounts receivable (DSO 55) | B36: 90 | C36: =C23*$B$15/$B$20 | D36: =D23*$B$15/$B$20 | E36: =E23*$B$15/$B$20 | F36: =F23*$B$15/$B$20 | G36: =G23*$B$15/$B$20 | H36: =H23*$B$15/$B$20 | I36: =I23*$B$15/$B$20
A37: Inventory (DIO 60, on revenue) | B37: 75 | C37: =C23*$B$16/$B$20 | D37: =D23*$B$16/$B$20 | E37: =E23*$B$16/$B$20 | F37: =F23*$B$16/$B$20 | G37: =G23*$B$16/$B$20 | H37: =H23*$B$16/$B$20 | I37: =I23*$B$16/$B$20
A38: Accounts payable (DPO 40, on revenue) | B38: 55 | C38: =C23*$B$17/$B$20 | D38: =D23*$B$17/$B$20 | E38: =E23*$B$17/$B$20 | F38: =F23*$B$17/$B$20 | G38: =G23*$B$17/$B$20 | H38: =H23*$B$17/$B$20 | I38: =I23*$B$17/$B$20
A39: Net working capital (AR + Inv - AP) | B39: =B36+B37-B38 | C39: =C36+C37-C38 | D39: =D36+D37-D38 | E39: =E36+E37-E38 | F39: =F36+F37-F38 | G39: =G36+G37-G38 | H39: =H36+H37-H38 | I39: =I36+I37-I38
A40: Increase / (decrease) in NWC | C40: =C39-B39 | D40: =D39-C39 | E40: =E39-D39 | F40: =F39-E39 | G40: =G39-F39 | H40: =H39-G39 | I40: =I39-H39
A42: Net PP&E roll-forward (PPE_t = PPE_t-1 + capex_t - D&A_t, from t = 1)
A43: Opening net PP&E | C43: =B46 | D43: =C46 | E43: =D46 | F43: =E46 | G43: =F46 | H43: =G46 | I43: =H46
A44: Plus: Capex (6.0% of revenue) | B44: =B23*$B$12 | C44: =C23*$B$12 | D44: =D23*$B$12 | E44: =E23*$B$12 | F44: =F23*$B$12 | G44: =G23*$B$12 | H44: =H23*$B$12 | I44: =I23*$B$12
A45: Less: D&A | B45: =B25 | C45: =C25 | D45: =D25 | E45: =E25 | F45: =F25 | G45: =G25 | H45: =H25 | I45: =I25
A46: Closing net PP&E | B46: 250 | C46: =C43+C44-C45 | D46: =D43+D44-D45 | E46: =E43+E44-E45 | F46: =F43+F44-F45 | G46: =G43+G44-G45 | H46: =H43+H44-H45 | I46: =I43+I44-I45
...

Sheet Outputs
A1: BM-3S-001 — Headline Outputs (final projection year, t = 7)
A2: All values are live links to the Model sheet.
A4: Label | B4: Value | C4: Description
A5: final_net_income | B5: =Model!I30 | C5: Net income, final year ($m)
A6: final_total_assets | B6: =Model!I78 | C6: Total assets, final year ($m)
A7: final_total_liabilities_equity | B7: =Model!I83 | C7: Total liabilities + equity, final year ($m)
A8: final_balance_check | B8: =Model!I84 | C8: Assets - (liabilities + equity), final year (~0)
A9: final_cash | B9: =Model!I74 | C9: Ending cash, final year ($m)
A10: final_debt | B10: =Model!I80 | C10: Ending debt, final year ($m) = 180 - 7 x 20 = 40.0
